Workbook
Name All_Days: #REF!
Name ARGUS_DAYS_PRICED: #REF!
Name ARGUS_PRICING_DAYS: #REF!
Name BRENT_DAYS_PRICED: #REF!
Name Calendar: #REF!
Name CargoSize: #REF!
Name CMA_Argus_Trading_Days: #REF!
Name CMA_Brent_Trading_Days: #REF!
Name CMA_DAYS_PRICED: #REF!
Name CMA_NYMEX_Trading_Days: #REF!
Name CMA_Platts_Dubai: #REF!
Name CMA_Platts_Euro_Brent_Trading_Days: #REF!
Name CMA_Platts_US_Trading_Days: #REF!
Name CMA_PRICING_DAYS: #REF!
Name Cons_Date: #REF!
Name CostDemK: 'Cargo Data'!$AE$2:$AE$21
Name CostFlag: 'Cost Dashboard'!$C$6
Name CostFreightK: 'Cargo Data'!$AC$2:$AC$21
Name CostInclFlag: 'Cargo Data'!$AJ$2:$AJ$21
Name CostMonth: 'Cost Dashboard'!$C$4
Name CostOtherK: 'Cargo Data'!$AH$2:$AH$21
Name CostSTSK: 'Cargo Data'!$AF$2:$AF$21
Name CostTD7K: 'Cargo Data'!$AD$2:$AD$21
Name CostTotalK: 'Cargo Data'!$AI$2:$AI$21
Name CostTVMK: 'Cargo Data'!$AG$2:$AG$21
Name CostVessel: 'Cost Dashboard'!$C$5
Name Crude: #REF!
Name Crude: #REF!
Name CrudeBenchmarks: #REF!
Name CrudeBenchmarks: #REF!
Name Crudes: #REF!
Name Current_Day: #REF!
Name DateRange: OFFSET(#REF!,0,0,MATCH(TODAY(),#REF!,0),1)
Name DaysInMonth: #REF!
Name DischargePort: #REF!
Name Disports: #REF!
Name EV__LASTREFTIME__: 40738.6979398148
Name FilterFlag: Dashboard!$C$6
Name FilterMonth: Dashboard!$C$4
Name FilterVessel: Dashboard!$C$5
Name FregithTable: #REF!
Name Holidays: #REF!
Name IBrentCurve: '[1]Calendar Management'!#REF!
Name IBrentCurve: '[1]Calendar Management'!#REF!
Name Ledgerdd: Ledger[[#All],[Cargo Name]]
Name Ledgerdd: Ledger[[#All],[Cargo Name]]
Name Ledgerdd: Ledger[[#All],[Cargo Name]]
Name Ledgerdd: Ledger[[#All],[Cargo Name]]
Name Ledgerdd: Ledger[[#All],[Cargo Name]]
Name LIM_START_DATE: #REF!
Name LIM_START_DATE: #REF!
Name LoadPort: #REF!
Name LoadPorts: #REF!
Name MinTonnage: #REF!
Name Mo_Avg_Pricing: #REF!
Name Months: '[1]Calendar Management'!#REF!
Name Months: '[1]Calendar Management'!#REF!
Name MorningStar_As_Of_Date: #REF!
Name MTDRange: OFFSET(#REF!,0,0,MATCH(TODAY(),#REF!,0),1)
Name No_Holiday: #REF!

Sheet Dashboard
B2: CARGO ECONOMICS DASHBOARD — 2026
B3: FILTERS ▼ (use dropdowns)
B4: Load Month | C4: All | E4: Cargoes shown | F4: =SUM(CargoData[Incl]) -> 19
B5: Vessel Class | C5: All
B6: Exclude flagged | C6: Yes
B8: Total Volume (kbbl) | C8: Total Day-1 P&L ($k) | D8: Wtd Avg P&L ($/bbl) | E8: Total Costs ($k) | F8: Avg Cost ($/bbl) | G8: Win Rate
B9: =SUMPRODUCT(CargoData[Incl],CargoData[Volume (kbbl)]) -> 24996 | C9: =SUMPRODUCT(CargoData[Incl],CargoData[Day 1 P&L ($k)]) -> 10767.648 | D9: =IFERROR(C9/B9,0) -> 0.43077483 | E9: =SUMPRODUCT(CargoData[Incl],CargoData[Total Costs ($k)]) -> 164120.47 | F9: =IFERROR(SUMPRODUCT(CargoData[Incl],CargoData[Volume (kbbl)],CargoData[Total Cost ($/bbl)])/B9,0) -> 6.2509164 | G9: {=IFERROR(SUMPRODUCT(CargoData[Incl],--(CargoData[P&L ($/bbl)]>0))/F4,0)} -> 0.84210526
B12: P&L BY LOAD MONTH | H12: P&L BY VESSEL CLASS | AA12: Chart helper: Month | AD12: Chart helper: Vessel
B13: Load Month | C13: Cargoes | D13: Volume (kbbl) | E13: Day-1 P&L ($k) | F13: $/bbl | H13: Vessel Class | I13: Cargoes | J13: Volume (kbbl) | K13: Day-1 P&L ($k) | L13: $/bbl | AA13: Load Month | AB13: Day-1 P&L ($k) | AD13: Vessel Class | AE13: Volume (kbbl)
B14: {=IFERROR(TEXT(_xlfn._xlws.SORT(_xlfn.UNIQUE(_xlfn._xlws.FILTER(CargoData[Load Month],CargoData[Incl]=1))),"mmm-yy"),"")} -> Feb-26 | C14: {=IF($B14="","",SUMPRODUCT((CargoData[Load Mo]=$B14)*CargoData[Incl]))} -> 5 | D14: {=IF($B14="","",SUMPRODUCT((CargoData[Load Mo]=$B14)*CargoData[Incl]*CargoData[Volume (kbbl)]))} -> 4872 | E14: {=IF($B14="","",SUMPRODUCT((CargoData[Load Mo]=$B14)*CargoData[Incl]*CargoData[Day 1 P&L ($k)]))} -> 495.64474 | F14: =IF($B14="","",IFERROR(E14/D14,"")) -> 0.10173332 | H14: {=IFERROR(_xlfn._xlws.SORT(_xlfn.UNIQUE(_xlfn._xlws.FILTER(CargoData[Vessel Class],CargoData[Incl]=1))),"")} -> Aframax | I14: {=IF($H14="","",SUMPRODUCT((CargoData[Vessel Class]=$H14)*CargoData[Incl]))} -> 7 | J14: {=IF($H14="","",SUMPRODUCT((CargoData[Vessel Class]=$H14)*CargoData[Incl]*CargoData[Volume (kbbl)]))} -> 4900 | K14: {=IF($H14="","",SUMPRODUCT((CargoData[Vessel Class]=$H14)*CargoData[Incl]*CargoData[Day 1 P&L ($k)]))} -> 436.10499 | L14: =IF($H14="","",IFERROR(K14/J14,"")) -> 0.089001018 | AA14: =IF($B14="","",$B14) -> Feb-26 | AB14: =IF($B14="",NA(),$E14) -> 495.64474 | AD14: =IF($H14="","",$H14) -> Aframax | AE14: =IF($H14="",NA(),$J14) -> 4900
B15: Mar-26 | C15: {=IF($B15="","",SUMPRODUCT((CargoData[Load Mo]=$B15)*CargoData[Incl]))} -> 3 | D15: {=IF($B15="","",SUMPRODUCT((CargoData[Load Mo]=$B15)*CargoData[Incl]*CargoData[Volume (kbbl)]))} -> 3530 | E15: {=IF($B15="","",SUMPRODUCT((CargoData[Load Mo]=$B15)*CargoData[Incl]*CargoData[Day 1 P&L ($k)]))} -> 873.08655 | F15: =IF($B15="","",IFERROR(E15/D15,"")) -> 0.2473333 | H15: FOB | I15: {=IF($H15="","",SUMPRODUCT((CargoData[Vessel Class]=$H15)*CargoData[Incl]))} -> 4 | J15: {=IF($H15="","",SUMPRODUCT((CargoData[Vessel Class]=$H15)*CargoData[Incl]*CargoData[Volume (kbbl)]))} -> 4000 | K15: {=IF($H15="","",SUMPRODUCT((CargoData[Vessel Class]=$H15)*CargoData[Incl]*CargoData[Day 1 P&L ($k)]))} -> 1122.575 | L15: =IF($H15="","",IFERROR(K15/J15,"")) -> 0.28064375 | AA15: =IF($B15="","",$B15) -> Mar-26 | AB15: =IF($B15="",NA(),$E15) -> 873.08655 | AD15: =IF($H15="","",$H15) -> FOB | AE15: =IF($H15="",NA(),$J15) -> 4000
B16: Apr-26 | C16: {=IF($B16="","",SUMPRODUCT((CargoData[Load Mo]=$B16)*CargoData[Incl]))} -> 4 | D16: {=IF($B16="","",SUMPRODUCT((CargoData[Load Mo]=$B16)*CargoData[Incl]*CargoData[Volume (kbbl)]))} -> 6744 | E16: {=IF($B16="","",SUMPRODUCT((CargoData[Load Mo]=$B16)*CargoData[Incl]*CargoData[Day 1 P&L ($k)]))} -> 886.48 | F16: =IF($B16="","",IFERROR(E16/D16,"")) -> 0.13144721 | H16: VLCC | I16: {=IF($H16="","",SUMPRODUCT((CargoData[Vessel Class]=$H16)*CargoData[Incl]))} -> 8 | J16: {=IF($H16="","",SUMPRODUCT((CargoData[Vessel Class]=$H16)*CargoData[Incl]*CargoData[Volume (kbbl)]))} -> 16096 | K16: {=IF($H16="","",SUMPRODUCT((CargoData[Vessel Class]=$H16)*CargoData[Incl]*CargoData[Day 1 P&L ($k)]))} -> 9208.9677 | L16: =IF($H16="","",IFERROR(K16/J16,"")) -> 0.57212771 | AA16: =IF($B16="","",$B16) -> Apr-26 | AB16: =IF($B16="",NA(),$E16) -> 886.48 | AD16: =IF($H16="","",$H16) -> VLCC | AE16: =IF($H16="",NA(),$J16) -> 16096
B17: May-26 | C17: {=IF($B17="","",SUMPRODUCT((CargoData[Load Mo]=$B17)*CargoData[Incl]))} -> 2 | D17: {=IF($B17="","",SUMPRODUCT((CargoData[Load Mo]=$B17)*CargoData[Incl]*CargoData[Volume (kbbl)]))} -> 4204 | E17: {=IF($B17="","",SUMPRODUCT((CargoData[Load Mo]=$B17)*CargoData[Incl]*CargoData[Day 1 P&L ($k)]))} -> 6396.71 | F17: =IF($B17="","",IFERROR(E17/D17,"")) -> 1.5215771 | I17: {=IF($H17="","",SUMPRODUCT((CargoData[Vessel Class]=$H17)*CargoData[Incl]))} | J17: {=IF($H17="","",SUMPRODUCT((CargoData[Vessel Class]=$H17)*CargoData[Incl]*CargoData[Volume (kbbl)]))} | K17: {=IF($H17="","",SUMPRODUCT((CargoData[Vessel Class]=$H17)*CargoData[Incl]*CargoData[Day 1 P&L ($k)]))} | L17: =IF($H17="","",IFERROR(K17/J17,"")) | AA17: =IF($B17="","",$B17) -> May-26 | AB17: =IF($B17="",NA(),$E17) -> 6396.71 | AD17: =IF($H17="","",$H17) | AE17: =IF($H17="",NA(),$J17) -> #N/A
B18: Jun-26 | C18: {=IF($B18="","",SUMPRODUCT((CargoData[Load Mo]=$B18)*CargoData[Incl]))} -> 5 | D18: {=IF($B18="","",SUMPRODUCT((CargoData[Load Mo]=$B18)*CargoData[Incl]*CargoData[Volume (kbbl)]))} -> 5646 | E18: {=IF($B18="","",SUMPRODUCT((CargoData[Load Mo]=$B18)*CargoData[Incl]*CargoData[Day 1 P&L ($k)]))} -> 2115.7264 | F18: =IF($B18="","",IFERROR(E18/D18,"")) -> 0.37473014 | I18: {=IF($H18="","",SUMPRODUCT((CargoData[Vessel Class]=$H18)*CargoData[Incl]))} | J18: {=IF($H18="","",SUMPRODUCT((CargoData[Vessel Class]=$H18)*CargoData[Incl]*CargoData[Volume (kbbl)]))} | K18: {=IF($H18="","",SUMPRODUCT((CargoData[Vessel Class]=$H18)*CargoData[Incl]*CargoData[Day 1 P&L ($k)]))} | L18: =IF($H18="","",IFERROR(K18/J18,"")) | AA18: =IF($B18="","",$B18) -> Jun-26 | AB18: =IF($B18="",NA(),$E18) -> 2115.7264 | AD18: =IF($H18="","",$H18) | AE18: =IF($H18="",NA(),$J18) -> #N/A
C19: {=IF($B19="","",SUMPRODUCT((CargoData[Load Mo]=$B19)*CargoData[Incl]))} | D19: {=IF($B19="","",SUMPRODUCT((CargoData[Load Mo]=$B19)*CargoData[Incl]*CargoData[Volume (kbbl)]))} | E19: {=IF($B19="","",SUMPRODUCT((CargoData[Load Mo]=$B19)*CargoData[Incl]*CargoData[Day 1 P&L ($k)]))} | F19: =IF($B19="","",IFERROR(E19/D19,"")) | H19: Total | I19: =SUM(I14:I18) -> 19 | J19: =SUM(J14:J18) -> 24996 | K19: =SUM(K14:K18) -> 10767.648 | L19: =IFERROR(K19/J19,"") -> 0.43077483 | AA19: =IF($B19="","",$B19) | AB19: =IF($B19="",NA(),$E19) -> #N/A
B20: Total | C20: =SUM(C14:C19) -> 19 | D20: =SUM(D14:D19) -> 24996 | E20: =SUM(E14:E19) -> 10767.648 | F20: =IFERROR(E20/D20,"") -> 0.43077483
B23: COST BUILD-UP ($/bbl, volume-weighted)
B24: Component | C24: $/bbl
B25: Freight | C25: =IFERROR(SUMPRODUCT(CargoData[Incl],CargoData[Volume (kbbl)],CargoData[Freight])/$B$9,0) -> 5.8558489
B26: TD7 Freight | C26: =IFERROR(SUMPRODUCT(CargoData[Incl],CargoData[Volume (kbbl)],CargoData[TD7 Freight])/$B$9,0) -> -0.17505693
B27: Demurrage | C27: =IFERROR(SUMPRODUCT(CargoData[Incl],CargoData[Volume (kbbl)],CargoData[Demurrage])/$B$9,0) -> 0.090736478
B28: STS | C28: =IFERROR(SUMPRODUCT(CargoData[Incl],CargoData[Volume (kbbl)],CargoData[STS])/$B$9,0) -> 0.17503046
B29: TVM | C29: =IFERROR(SUMPRODUCT(CargoData[Incl],CargoData[Volume (kbbl)],CargoData[TVM])/$B$9,0) -> 0.062050476
B30: Other | C30: =IFERROR(SUMPRODUCT(CargoData[Incl],CargoData[Volume (kbbl)],CargoData[Other])/$B$9,0) -> 0.24230706
B31: Total | C31: =SUM(C25:C30) -> 6.2509164
B34: CARGO DETAIL (filtered)
B35: Load Month | C35: Cargo Name | D35: Deal Number | E35: Vessel | F35: Volume (kbbl) | G35: FOB Corpus (ICE Brent) | H35: Landed | I35: Sold | J35: P&L ($/bbl) | K35: Day-1 P&L ($k) | L35: Flag
B36: {=IFERROR(_xlfn._xlws.SORT(_xlfn._xlws.FILTER(_xlfn.CHOOSECOLS(CargoData[#Data],3,4,5,6,7,12,20,21,22,23,25),CargoData[Incl]=1),10,-1),"No cargoes match the current filters")} -> May-26 | C36: HDO July26 10-20 | D36: ARA26HS00053 | E36: VLCC | F36: 2065 | G36: 5.92 | H36: 22.373438 | I36: 23.98 | J36: 1.6065617 | K36: 3317.55 | L36: OK
B37: May-26 | C37: ENEOS July 20-30 | D37: ENE26HS00007 | E37: VLCC | F37: 2139 | G37: 17.89 | H37: 26.890468 | I37: 28.33 | J37: 1.4395325 | K37: 3079.16 | L37: OK
B38: Apr-26 | C38: HDO FOB APR 7-12 | D38: HDH26HS00001 | E38: FOB | F38: 1900 | G38: -3.6273684 | H38: -1.488 | I38: -0.94875 | J38: 0.53925 | K38: 1024.575 | L38: OK
B39: Jun-26 | C39: HDO Aug26 22-31 DAP | D39: ARA26HS00078 | E39: VLCC | F39: 1422 | G39: -0.34 | H39: 13.755495 | I39: 14.34 | J39: 0.58450518 | K39: 831.16637 | L39: OK
B40: Mar-26 | C40: HDO May 1-10 WTI+WTL | D40: ARA26HS00032 | E40: VLCC | F40: 2130 | G40: -1.85 | H40: 6.3077999 | I40: 6.68 | J40: 0.37220014 | K40: 792.7863 | L40: OK
B41: Jun-26 | C41: GS Caltex Korea Aug 16-22 | D41: ARA26HS00075 | E41: VLCC | F41: 2124 | G41: 0.17 | H41: 15.352335 | I41: 15.67 | J41: 0.31766478 | K41: 674.72 | L41: OK
B42: Feb-26 | C42: Dangote VLCC March 15-25 | D42: ARA26HS00023 | E42: VLCC | F42: 2072 | G42: -2.31 | H42: 0.83305019 | I42: 1.08 | J42: 0.24694981 | K42: 511.68 | L42: OK
B43: Jun-26 | C43: Jun26 EFP 1 | D43: ARA26HS00069-1 | E43: Aframax | F43: 700 | G43: -6.73 | H43: -0.2806 | I43: 0.03 | J43: 0.3106 | K43: 217.42 | L43: OK
B44: Jun-26 | C44: Jun26 EFP 2 | D44: ARA26HS00069-2 | E44: Aframax | F44: 700 | G44: -6.73 | H44: -0.2806 | I44: 0.03 | J44: 0.3106 | K44: 217.42 | L44: OK
B45: Jun-26 | C45: BP FOB June26 10-15 | D45: BPO26HS00009 | E45: Aframax | F45: 700 | G45: 1.3 | H45: 1.3 | I45: 1.55 | J45: 0.25 | K45: 175 | L45: OK
B46: Mar-26 | C46: April26 EFP 1 | D46: ARA26HS000036 | E46: Aframax | F46: 700 | G46: -4.5 | H46: -0.11471464 | I46: -0.02 | J46: 0.094714643 | K46: 66.30025 | L46: OK
B47: Feb-26 | C47: Gunvor FOB Feb28-01 | D47: GUN26HS00014 | E47: FOB | F47: 700 | G47: -2.61 | H47: -2.61 | I47: -2.55 | J47: 0.06 | K47: 42 | L47: OK
B48: Feb-26 | C48: Gunvor FOB Feb 27-28 STG | D48: GUN26HS00012 | E48: FOB | F48: 700 | G48: -2.96 | H48: -2.96 | I48: -2.9 | J48: 0.06 | K48: 42 | L48: OK
...

Sheet Cost Dashboard
B2: CARGO COST DASHBOARD — 2026
B3: FILTERS ▼
B4: Load Month | C4: All | E4: Cargoes shown | F4: =SUM(CostInclFlag) -> 19
B5: Vessel Class | C5: All
B6: Exclude flagged | C6: Yes
B8: Total Costs ($k) | C8: Total Volume (kbbl) | D8: Avg Cost ($/bbl) | E8: Freight ($k) | F8: Freight % of Costs | G8: TD7 Credit ($k)
B9: =SUMPRODUCT(CostInclFlag,CostTotalK) -> 164120.47 | C9: =SUMPRODUCT(CostInclFlag,CargoData[Volume (kbbl)]) -> 24996 | D9: =IFERROR(B9/C9,0) -> 6.5658694 | E9: =SUMPRODUCT(CostInclFlag,CostFreightK) -> 152244.62 | F9: =IFERROR(E9/B9,0) -> 0.92763941 | G9: =SUMPRODUCT(CostInclFlag,CostTD7K) -> -4375.723
B12: COSTS BY LOAD MONTH ($k)
B13: Load Month | C13: Cargoes | D13: Volume (kbbl) | E13: (+) Freight | F13: (-) TD7 Freight* | G13: (+) Demurrage | H13: (+) STS | I13: (+) TVM | J13: (+) Other | K13: Total Costs ($k) | L13: $/bbl | AA13: Load Month | AB13: Total Costs ($k) | AD13: Component | AE13: Total ($k) | AG13: Load Month | AH13: $/bbl
B14: {=IFERROR(TEXT(_xlfn._xlws.SORT(_xlfn.UNIQUE(_xlfn._xlws.FILTER(CargoData[Load Month],CostInclFlag=1))),"mmm-yy"),"")} -> Feb-26 | C14: {=IF($B14="","",SUMPRODUCT((CargoData[Load Mo]=$B14)*CostInclFlag))} -> 5 | D14: {=IF($B14="","",SUMPRODUCT((CargoData[Load Mo]=$B14)*CostInclFlag*CargoData[Volume (kbbl)]))} -> 4872 | E14: {=IF($B14="","",SUMPRODUCT((CargoData[Load Mo]=$B14)*CostInclFlag*CostFreightK))} -> 7675.452 | F14: {=IF($B14="","",SUMPRODUCT((CargoData[Load Mo]=$B14)*CostInclFlag*CostTD7K))} -> -761.41674 | G14: {=IF($B14="","",SUMPRODUCT((CargoData[Load Mo]=$B14)*CostInclFlag*CostDemK))} -> 160 | H14: {=IF($B14="","",SUMPRODUCT((CargoData[Load Mo]=$B14)*CostInclFlag*CostSTSK))} -> 915 | I14: {=IF($B14="","",SUMPRODUCT((CargoData[Load Mo]=$B14)*CostInclFlag*CostTVMK))} -> 0 | J14: {=IF($B14="","",SUMPRODUCT((CargoData[Load Mo]=$B14)*CostInclFlag*CostOtherK))} -> 1156 | K14: =IF($B14="","",SUM(E14:J14)) -> 9145.0353 | L14: =IF($B14="","",IFERROR(K14/D14,"")) -> 1.8770598 | AA14: =IF($B14="","",$B14) -> Feb-26 | AB14: =IF($B14="",NA(),$K14) -> 9145.0353 | AD14: =$B35 -> (+) Freight | AE14: =$C35 -> 152244.62 | AG14: =IF($B14="","",$B14) -> Feb-26 | AH14: =IF($B14="",NA(),$L14) -> 1.8770598
B15: Mar-26 | C15: {=IF($B15="","",SUMPRODUCT((CargoData[Load Mo]=$B15)*CostInclFlag))} -> 3 | D15: {=IF($B15="","",SUMPRODUCT((CargoData[Load Mo]=$B15)*CostInclFlag*CargoData[Volume (kbbl)]))} -> 3530 | E15: {=IF($B15="","",SUMPRODUCT((CargoData[Load Mo]=$B15)*CostInclFlag*CostFreightK))} -> 18459.991 | F15: {=IF($B15="","",SUMPRODUCT((CargoData[Load Mo]=$B15)*CostInclFlag*CostTD7K))} -> -974.29125 | G15: {=IF($B15="","",SUMPRODUCT((CargoData[Load Mo]=$B15)*CostInclFlag*CostDemK))} -> 160 | H15: {=IF($B15="","",SUMPRODUCT((CargoData[Load Mo]=$B15)*CostInclFlag*CostSTSK))} -> 450 | I15: {=IF($B15="","",SUMPRODUCT((CargoData[Load Mo]=$B15)*CostInclFlag*CostTVMK))} -> 716.0137 | J15: {=IF($B15="","",SUMPRODUCT((CargoData[Load Mo]=$B15)*CostInclFlag*CostOtherK))} -> 420 | K15: =IF($B15="","",SUM(E15:J15)) -> 19231.713 | L15: =IF($B15="","",IFERROR(K15/D15,"")) -> 5.4480775 | AA15: =IF($B15="","",$B15) -> Mar-26 | AB15: =IF($B15="",NA(),$K15) -> 19231.713 | AD15: =$B36 -> (-) TD7 Freight* | AE15: =$C36 -> -4375.723 | AG15: =IF($B15="","",$B15) -> Mar-26 | AH15: =IF($B15="",NA(),$L15) -> 5.4480775
B16: Apr-26 | C16: {=IF($B16="","",SUMPRODUCT((CargoData[Load Mo]=$B16)*CostInclFlag))} -> 4 | D16: {=IF($B16="","",SUMPRODUCT((CargoData[Load Mo]=$B16)*CostInclFlag*CargoData[Volume (kbbl)]))} -> 6744 | E16: {=IF($B16="","",SUMPRODUCT((CargoData[Load Mo]=$B16)*CostInclFlag*CostFreightK))} -> 37440 | F16: {=IF($B16="","",SUMPRODUCT((CargoData[Load Mo]=$B16)*CostInclFlag*CostTD7K))} -> 0 | G16: {=IF($B16="","",SUMPRODUCT((CargoData[Load Mo]=$B16)*CostInclFlag*CostDemK))} -> 480 | H16: {=IF($B16="","",SUMPRODUCT((CargoData[Load Mo]=$B16)*CostInclFlag*CostSTSK))} -> 1275 | I16: {=IF($B16="","",SUMPRODUCT((CargoData[Load Mo]=$B16)*CostInclFlag*CostTVMK))} -> 0 | J16: {=IF($B16="","",SUMPRODUCT((CargoData[Load Mo]=$B16)*CostInclFlag*CostOtherK))} -> 879.295 | K16: =IF($B16="","",SUM(E16:J16)) -> 40074.295 | L16: =IF($B16="","",IFERROR(K16/D16,"")) -> 5.9422146 | AA16: =IF($B16="","",$B16) -> Apr-26 | AB16: =IF($B16="",NA(),$K16) -> 40074.295 | AD16: =$B37 -> (+) Demurrage | AE16: =$C37 -> 2400 | AG16: =IF($B16="","",$B16) -> Apr-26 | AH16: =IF($B16="",NA(),$L16) -> 5.9422146
B17: May-26 | C17: {=IF($B17="","",SUMPRODUCT((CargoData[Load Mo]=$B17)*CostInclFlag))} -> 2 | D17: {=IF($B17="","",SUMPRODUCT((CargoData[Load Mo]=$B17)*CostInclFlag*CargoData[Volume (kbbl)]))} -> 4204 | E17: {=IF($B17="","",SUMPRODUCT((CargoData[Load Mo]=$B17)*CostInclFlag*CostFreightK))} -> 41700 | F17: {=IF($B17="","",SUMPRODUCT((CargoData[Load Mo]=$B17)*CostInclFlag*CostTD7K))} -> 0 | G17: {=IF($B17="","",SUMPRODUCT((CargoData[Load Mo]=$B17)*CostInclFlag*CostDemK))} -> 800 | H17: {=IF($B17="","",SUMPRODUCT((CargoData[Load Mo]=$B17)*CostInclFlag*CostSTSK))} -> 900 | I17: {=IF($B17="","",SUMPRODUCT((CargoData[Load Mo]=$B17)*CostInclFlag*CostTVMK))} -> 835 | J17: {=IF($B17="","",SUMPRODUCT((CargoData[Load Mo]=$B17)*CostInclFlag*CostOtherK))} -> 1311.55 | K17: =IF($B17="","",SUM(E17:J17)) -> 45546.55 | L17: =IF($B17="","",IFERROR(K17/D17,"")) -> 10.834098 | AA17: =IF($B17="","",$B17) -> May-26 | AB17: =IF($B17="",NA(),$K17) -> 45546.55 | AD17: =$B38 -> (+) STS | AE17: =$C38 -> 4540 | AG17: =IF($B17="","",$B17) -> May-26 | AH17: =IF($B17="",NA(),$L17) -> 10.834098
B18: Jun-26 | C18: {=IF($B18="","",SUMPRODUCT((CargoData[Load Mo]=$B18)*CostInclFlag))} -> 5 | D18: {=IF($B18="","",SUMPRODUCT((CargoData[Load Mo]=$B18)*CostInclFlag*CargoData[Volume (kbbl)]))} -> 5646 | E18: {=IF($B18="","",SUMPRODUCT((CargoData[Load Mo]=$B18)*CostInclFlag*CostFreightK))} -> 46969.175 | F18: {=IF($B18="","",SUMPRODUCT((CargoData[Load Mo]=$B18)*CostInclFlag*CostTD7K))} -> -2640.015 | G18: {=IF($B18="","",SUMPRODUCT((CargoData[Load Mo]=$B18)*CostInclFlag*CostDemK))} -> 800 | H18: {=IF($B18="","",SUMPRODUCT((CargoData[Load Mo]=$B18)*CostInclFlag*CostSTSK))} -> 1000 | I18: {=IF($B18="","",SUMPRODUCT((CargoData[Load Mo]=$B18)*CostInclFlag*CostTVMK))} -> 889.71822 | J18: {=IF($B18="","",SUMPRODUCT((CargoData[Load Mo]=$B18)*CostInclFlag*CostOtherK))} -> 3104 | K18: =IF($B18="","",SUM(E18:J18)) -> 50122.878 | L18: =IF($B18="","",IFERROR(K18/D18,"")) -> 8.8775909 | AA18: =IF($B18="","",$B18) -> Jun-26 | AB18: =IF($B18="",NA(),$K18) -> 50122.878 | AD18: =$B39 -> (+) TVM | AE18: =$C39 -> 2440.7319 | AG18: =IF($B18="","",$B18) -> Jun-26 | AH18: =IF($B18="",NA(),$L18) -> 8.8775909
C19: {=IF($B19="","",SUMPRODUCT((CargoData[Load Mo]=$B19)*CostInclFlag))} | D19: {=IF($B19="","",SUMPRODUCT((CargoData[Load Mo]=$B19)*CostInclFlag*CargoData[Volume (kbbl)]))} | E19: {=IF($B19="","",SUMPRODUCT((CargoData[Load Mo]=$B19)*CostInclFlag*CostFreightK))} | F19: {=IF($B19="","",SUMPRODUCT((CargoData[Load Mo]=$B19)*CostInclFlag*CostTD7K))} | G19: {=IF($B19="","",SUMPRODUCT((CargoData[Load Mo]=$B19)*CostInclFlag*CostDemK))} | H19: {=IF($B19="","",SUMPRODUCT((CargoData[Load Mo]=$B19)*CostInclFlag*CostSTSK))} | I19: {=IF($B19="","",SUMPRODUCT((CargoData[Load Mo]=$B19)*CostInclFlag*CostTVMK))} | J19: {=IF($B19="","",SUMPRODUCT((CargoData[Load Mo]=$B19)*CostInclFlag*CostOtherK))} | K19: =IF($B19="","",SUM(E19:J19)) | L19: =IF($B19="","",IFERROR(K19/D19,"")) | AA19: =IF($B19="","",$B19) | AB19: =IF($B19="",NA(),$K19) -> #N/A | AD19: =$B40 -> (+) Other | AE19: =$C40 -> 6870.845 | AG19: =IF($B19="","",$B19) | AH19: =IF($B19="",NA(),$L19) -> #N/A
B20: Total | C20: =SUM(C14:C19) -> 19 | D20: =SUM(D14:D19) -> 24996 | E20: =SUM(E14:E19) -> 152244.62 | F20: =SUM(F14:F19) -> -4375.723 | G20: =SUM(G14:G19) -> 2400 | H20: =SUM(H14:H19) -> 4540 | I20: =SUM(I14:I19) -> 2440.7319 | J20: =SUM(J14:J19) -> 6870.845 | K20: =SUM(K14:K19) -> 164120.47 | L20: =IFERROR(K20/D20,"") -> 6.5658694
B23: COSTS BY VESSEL CLASS ($k)
B24: Vessel Class | C24: Cargoes | D24: Volume (kbbl) | E24: (+) Freight | F24: (-) TD7 Freight* | G24: (+) Demurrage | H24: (+) STS | I24: (+) TVM | J24: (+) Other | K24: Total Costs ($k) | L24: $/bbl
B25: {=IFERROR(_xlfn._xlws.SORT(_xlfn.UNIQUE(_xlfn._xlws.FILTER(CargoData[Vessel Class],CostInclFlag=1))),"")} -> Aframax | C25: {=IF($B25="","",SUMPRODUCT((CargoData[Vessel Class]=$B25)*CostInclFlag))} -> 7 | D25: {=IF($B25="","",SUMPRODUCT((CargoData[Vessel Class]=$B25)*CostInclFlag*CargoData[Volume (kbbl)]))} -> 4900 | E25: {=IF($B25="","",SUMPRODUCT((CargoData[Vessel Class]=$B25)*CostInclFlag*CostFreightK))} -> 18594.618 | F25: {=IF($B25="","",SUMPRODUCT((CargoData[Vessel Class]=$B25)*CostInclFlag*CostTD7K))} -> -4375.723 | G25: {=IF($B25="","",SUMPRODUCT((CargoData[Vessel Class]=$B25)*CostInclFlag*CostDemK))} -> 0 | H25: {=IF($B25="","",SUMPRODUCT((CargoData[Vessel Class]=$B25)*CostInclFlag*CostSTSK))} -> 465 | I25: {=IF($B25="","",SUMPRODUCT((CargoData[Vessel Class]=$B25)*CostInclFlag*CostTVMK))} -> 84 | J25: {=IF($B25="","",SUMPRODUCT((CargoData[Vessel Class]=$B25)*CostInclFlag*CostOtherK))} -> 0 | K25: =IF($B25="","",SUM(E25:J25)) -> 14767.895 | L25: =IF($B25="","",IFERROR(K25/D25,"")) -> 3.0138561
B26: FOB | C26: {=IF($B26="","",SUMPRODUCT((CargoData[Vessel Class]=$B26)*CostInclFlag))} -> 4 | D26: {=IF($B26="","",SUMPRODUCT((CargoData[Vessel Class]=$B26)*CostInclFlag*CargoData[Volume (kbbl)]))} -> 4000 | E26: {=IF($B26="","",SUMPRODUCT((CargoData[Vessel Class]=$B26)*CostInclFlag*CostFreightK))} -> 0 | F26: {=IF($B26="","",SUMPRODUCT((CargoData[Vessel Class]=$B26)*CostInclFlag*CostTD7K))} -> 0 | G26: {=IF($B26="","",SUMPRODUCT((CargoData[Vessel Class]=$B26)*CostInclFlag*CostDemK))} -> 0 | H26: {=IF($B26="","",SUMPRODUCT((CargoData[Vessel Class]=$B26)*CostInclFlag*CostSTSK))} -> 375 | I26: {=IF($B26="","",SUMPRODUCT((CargoData[Vessel Class]=$B26)*CostInclFlag*CostTVMK))} -> 0 | J26: {=IF($B26="","",SUMPRODUCT((CargoData[Vessel Class]=$B26)*CostInclFlag*CostOtherK))} -> 0 | K26: =IF($B26="","",SUM(E26:J26)) -> 375 | L26: =IF($B26="","",IFERROR(K26/D26,"")) -> 0.09375
B27: VLCC | C27: {=IF($B27="","",SUMPRODUCT((CargoData[Vessel Class]=$B27)*CostInclFlag))} -> 8 | D27: {=IF($B27="","",SUMPRODUCT((CargoData[Vessel Class]=$B27)*CostInclFlag*CargoData[Volume (kbbl)]))} -> 16096 | E27: {=IF($B27="","",SUMPRODUCT((CargoData[Vessel Class]=$B27)*CostInclFlag*CostFreightK))} -> 133650 | F27: {=IF($B27="","",SUMPRODUCT((CargoData[Vessel Class]=$B27)*CostInclFlag*CostTD7K))} -> 0 | G27: {=IF($B27="","",SUMPRODUCT((CargoData[Vessel Class]=$B27)*CostInclFlag*CostDemK))} -> 2400 | H27: {=IF($B27="","",SUMPRODUCT((CargoData[Vessel Class]=$B27)*CostInclFlag*CostSTSK))} -> 3700 | I27: {=IF($B27="","",SUMPRODUCT((CargoData[Vessel Class]=$B27)*CostInclFlag*CostTVMK))} -> 2356.7319 | J27: {=IF($B27="","",SUMPRODUCT((CargoData[Vessel Class]=$B27)*CostInclFlag*CostOtherK))} -> 6870.845 | K27: =IF($B27="","",SUM(E27:J27)) -> 148977.58 | L27: =IF($B27="","",IFERROR(K27/D27,"")) -> 9.2555652
C28: {=IF($B28="","",SUMPRODUCT((CargoData[Vessel Class]=$B28)*CostInclFlag))} | D28: {=IF($B28="","",SUMPRODUCT((CargoData[Vessel Class]=$B28)*CostInclFlag*CargoData[Volume (kbbl)]))} | E28: {=IF($B28="","",SUMPRODUCT((CargoData[Vessel Class]=$B28)*CostInclFlag*CostFreightK))} | F28: {=IF($B28="","",SUMPRODUCT((CargoData[Vessel Class]=$B28)*CostInclFlag*CostTD7K))} | G28: {=IF($B28="","",SUMPRODUCT((CargoData[Vessel Class]=$B28)*CostInclFlag*CostDemK))} | H28: {=IF($B28="","",SUMPRODUCT((CargoData[Vessel Class]=$B28)*CostInclFlag*CostSTSK))} | I28: {=IF($B28="","",SUMPRODUCT((CargoData[Vessel Class]=$B28)*CostInclFlag*CostTVMK))} | J28: {=IF($B28="","",SUMPRODUCT((CargoData[Vessel Class]=$B28)*CostInclFlag*CostOtherK))} | K28: =IF($B28="","",SUM(E28:J28)) | L28: =IF($B28="","",IFERROR(K28/D28,""))
C29: {=IF($B29="","",SUMPRODUCT((CargoData[Vessel Class]=$B29)*CostInclFlag))} | D29: {=IF($B29="","",SUMPRODUCT((CargoData[Vessel Class]=$B29)*CostInclFlag*CargoData[Volume (kbbl)]))} | E29: {=IF($B29="","",SUMPRODUCT((CargoData[Vessel Class]=$B29)*CostInclFlag*CostFreightK))} | F29: {=IF($B29="","",SUMPRODUCT((CargoData[Vessel Class]=$B29)*CostInclFlag*CostTD7K))} | G29: {=IF($B29="","",SUMPRODUCT((CargoData[Vessel Class]=$B29)*CostInclFlag*CostDemK))} | H29: {=IF($B29="","",SUMPRODUCT((CargoData[Vessel Class]=$B29)*CostInclFlag*CostSTSK))} | I29: {=IF($B29="","",SUMPRODUCT((CargoData[Vessel Class]=$B29)*CostInclFlag*CostTVMK))} | J29: {=IF($B29="","",SUMPRODUCT((CargoData[Vessel Class]=$B29)*CostInclFlag*CostOtherK))} | K29: =IF($B29="","",SUM(E29:J29)) | L29: =IF($B29="","",IFERROR(K29/D29,""))
B30: Total | C30: =SUM(C25:C29) -> 19 | D30: =SUM(D25:D29) -> 24996 | E30: =SUM(E25:E29) -> 152244.62 | F30: =SUM(F25:F29) -> -4375.723 | G30: =SUM(G25:G29) -> 2400 | H30: =SUM(H25:H29) -> 4540 | I30: =SUM(I25:I29) -> 2440.7319 | J30: =SUM(J25:J29) -> 6870.845 | K30: =SUM(K25:K29) -> 164120.47 | L30: =IFERROR(K30/D30,"") -> 6.5658694
B33: COST MIX — ALL FILTERED CARGOES
B34: Component | C34: Total ($k) | D34: $/bbl | E34: % of Total
B35: (+) Freight | C35: =SUMPRODUCT(CostInclFlag,CostFreightK) -> 152244.62 | D35: =IFERROR(C35/$C$9,0) -> 6.0907592 | E35: =IFERROR(C35/$C$41,0) -> 0.92763941
B36: (-) TD7 Freight* | C36: =SUMPRODUCT(CostInclFlag,CostTD7K) -> -4375.723 | D36: =IFERROR(C36/$C$9,0) -> -0.17505693 | E36: =IFERROR(C36/$C$41,0) -> -0.026661652
B37: (+) Demurrage | C37: =SUMPRODUCT(CostInclFlag,CostDemK) -> 2400 | D37: =IFERROR(C37/$C$9,0) -> 0.096015362 | E37: =IFERROR(C37/$C$41,0) -> 0.014623404
B38: (+) STS | C38: =SUMPRODUCT(CostInclFlag,CostSTSK) -> 4540 | D38: =IFERROR(C38/$C$9,0) -> 0.18162906 | E38: =IFERROR(C38/$C$41,0) -> 0.027662606
B39: (+) TVM | C39: =SUMPRODUCT(CostInclFlag,CostTVMK) -> 2440.7319 | D39: =IFERROR(C39/$C$9,0) -> 0.0976449 | E39: =IFERROR(C39/$C$41,0) -> 0.014871587
B40: (+) Other | C40: =SUMPRODUCT(CostInclFlag,CostOtherK) -> 6870.845 | D40: =IFERROR(C40/$C$9,0) -> 0.27487778 | E40: =IFERROR(C40/$C$41,0) -> 0.041864643
B41: Total Costs | C41: =SUM(C35:C40) -> 164120.47 | D41: =IFERROR(C41/$C$9,0) -> 6.5658694 | E41: =IFERROR(C41/C41,0) -> 1
B42: * TD7 Freight applies only to Brent EFP cargoes
B45: COST DETAIL BY CARGO (filtered, sorted by Total Costs)
B46: Load Month | C46: Cargo Name | D46: Deal Number | E46: Vessel | F46: Volume (kbbl) | G46: (+) Freight | H46: (-) TD7 Freight* | I46: (+) Demurrage | J46: (+) STS | K46: (+) TVM | L46: (+) Other | M46: Total Costs ($k) | N46: $/bbl
B47: {=IFERROR(_xlfn.LET(_xlpm.d,_xlfn.HSTACK(_xlfn.CHOOSECOLS(CargoData[#Data],3,4,5,6,7),CostFreightK,CostTD7K,CostDemK,CostSTSK,CostTVMK,CostOtherK,CostTotalK),_xlpm.f,_xlfn._xlws.FILTER(_xlpm.d,CostInclFlag=1),_xlpm.s,_xlfn._xlws.SORT(_xlpm.f,12,-1),_xlfn.HSTACK(_xlpm.s,IFERROR(_xlfn.CHOOSECOLS(_xlpm.s,12)/_xlfn.CHOOSECOLS(_xlpm.s,5),0))),"No cargoes match the current filters")} -> May-26 | C47: HDO July26 10-20 | D47: ARA26HS00053 | E47: VLCC | F47: 2065 | G47: 25000 | H47: 0 | I47: 400 | J47: 450 | K47: 0 | L47: 444.55 | M47: 26294.55 | N47: 12.733438
B48: Apr-26 | C48: CPC Taiwan June 18-22 | D48: ARA26HS00045 | E48: VLCC | F48: 2065 | G48: 20650 | H48: 0 | I48: 240 | J48: 450 | K48: 0 | L48: 439.6475 | M48: 21779.647 | N48: 10.547045
B49: Jun-26 | C49: HDO Aug26 22-31 DAP | D49: ARA26HS00078 | E49: VLCC | F49: 1422 | G49: 17800 | H49: 0 | I49: 400 | J49: 500 | K49: 0 | L49: 2468 | M49: 21168 | N49: 14.886076
B50: Jun-26 | C50: GS Caltex Korea Aug 16-22 | D50: ARA26HS00075 | E50: VLCC | F50: 2124 | G50: 17500 | H50: 0 | I50: 400 | J50: 500 | K50: 889.71822 | L50: 636 | M50: 19925.718 | N50: 9.3812233
...

Sheet Report
F7: Crude Trading Cargoes P&L
F8: ='PnL26'!P1 -> 46265
F10: ='PnL26'!H8 -> 0 | G10: ='PnL26'!I8 -> 0 | I10: =[1]EXPO!AC58 -> 46081 | J10: =[1]EXPO!AD58 -> 46112 | K10: =[1]EXPO!AE58 -> 0 | L10: =[1]EXPO!AF58 -> 0 | M10: =[1]EXPO!AG58 -> 0 | N10: =[1]EXPO!AH58 -> xCrd-Trading Cargoes | O10: =[1]EXPO!AI58 -> 45382 | P10: =[1]EXPO!AJ58 -> 45412 | ... W10: =[1]EXPO!AQ58 -> 45869 | X10: =[1]EXPO!#REF! -> #REF!
F11: ='PnL26'!H9 -> 0 | G11: ='PnL26'!I9 -> 0 | I11: =[1]EXPO!AC59 -> 0 | J11: =[1]EXPO!AD59 -> 0 | K11: =[1]EXPO!AE59 -> 1145.3922 | L11: =[1]EXPO!AF59 -> 1145.3922 | M11: =[1]EXPO!AG59 -> 0 | N11: =[1]EXPO!AH59 -> Nymex WTI | O11: =[1]EXPO!AI59 -> 0 | P11: =[1]EXPO!AJ59 -> 0 | ... W11: =[1]EXPO!AQ59 -> 0 | X11: =[1]EXPO!#REF! -> #REF! | Y11: =[1]EXPO!#REF! -> #REF!
F12: ='PnL26'!H10 -> 0 | G12: ='PnL26'!I10 -> 0 | I12: =[1]EXPO!AC60 -> 0 | J12: =[1]EXPO!AD60 -> 0 | K12: =[1]EXPO!AE60 -> 0 | L12: =[1]EXPO!AF60 -> 0 | M12: =[1]EXPO!AG60 -> 0 | N12: =[1]EXPO!AH60 -> ICE Brent | O12: =[1]EXPO!AI60 -> 0 | P12: =[1]EXPO!AJ60 -> 0 | ... W12: =[1]EXPO!AQ60 -> 0 | X12: =[1]EXPO!#REF! -> #REF! | Y12: =[1]EXPO!#REF! -> #REF!
F13: ='PnL26'!H11 -> 0 | G13: ='PnL26'!I11 -> 0 | I13: =[1]EXPO!AC61 -> 0 | J13: =[1]EXPO!AD61 -> 0 | K13: =[1]EXPO!AE61 -> 0 | L13: =[1]EXPO!AF61 -> 0 | M13: =[1]EXPO!AG61 -> 0 | N13: =[1]EXPO!AH61 -> Platts Dubai | O13: =[1]EXPO!AI61 -> 0 | P13: =[1]EXPO!AJ61 -> 0 | ... W13: =[1]EXPO!AQ61 -> 0 | X13: =[1]EXPO!#REF! -> #REF! | Y13: =[1]EXPO!#REF! -> #REF!
F14: ='PnL26'!H12 -> 0 | G14: ='PnL26'!I12 -> 0 | I14: =[1]EXPO!AC62 -> 0 | J14: =[1]EXPO!AD62 -> 0 | K14: =[1]EXPO!AE62 -> 0 | L14: =[1]EXPO!AF62 -> 0 | M14: =[1]EXPO!AG62 -> 0 | N14: =[1]EXPO!AH62 -> Dated Brent (DFLs) | O14: =[1]EXPO!AI62 -> 0 | P14: =[1]EXPO!AJ62 -> 0 | ... W14: =[1]EXPO!AQ62 -> 0 | X14: =[1]EXPO!#REF! -> #REF! | Y14: =[1]EXPO!#REF! -> #REF!
F15: ='PnL26'!H13 -> 0 | G15: ='PnL26'!I13 -> 0 | I15: =[1]EXPO!AC63 -> 0 | J15: =[1]EXPO!AD63 -> 0 | K15: =[1]EXPO!AE63 -> 1145.3922 | L15: =[1]EXPO!AF63 -> 0 | M15: =[1]EXPO!AG63 -> 0 | N15: =[1]EXPO!AH63 -> Total | O15: =[1]EXPO!AI63 -> 0 | P15: =[1]EXPO!AJ63 -> 0 | ... W15: =[1]EXPO!AQ63 -> 0 | X15: =[1]EXPO!#REF! -> #REF! | Y15: =[1]EXPO!#REF! -> #REF!
F16: ='PnL26'!H14 -> 0 | G16: ='PnL26'!I14 -> 0
F17: ='PnL26'!H15 -> 0 | G17: ='PnL26'!I15 -> 0
F18: ='PnL26'!H16 -> 0 | G18: ='PnL26'!I16 -> 0
F19: ='PnL26'!H17 -> 0 | G19: ='PnL26'!I17 -> 0
F20: ='PnL26'!H18 -> 0 | G20: ='PnL26'!I18 -> 0

Sheet Control
E1: M1 | F1: m2
B2: WTI Sprds | C2: Futures | D2: WTI Sprds | E2: WTI | F2: WTI | G2: Rdam Flat | H2: 21.86
B3: Brent Sprds | C3: Futures | D3: Brent Sprds | E3: Brent | F3: Brent | G3: Min | H3: 70000
B4: WTI-Brent | C4: Swaps | D4: WTI-Brent | E4: WTI | F4: Brent | H4: 185 | N4: Month | S4: Nov/Dec 25 | T4: Expired
B5: DFL | C5: Swaps | D5: Dated | H5: 700000 | N5: 1 | O5: F | S5: Dec/Jan 25 | T5: Expired
B6: Physical | C6: Physical | D6: Physical | H6: =H3*H2*H4/100 -> 2830870 | N6: =+N5+1 -> 2 | O6: G | S6: Apr07-Apr11/Apr 25 | T6: Expired
B7: CFD | C7: Swaps | D7: Dated | H7: =H6/H5 -> 4.0441 | N7: =+N6+1 -> 3 | O7: H | S7: Apr14-Apr18/Apr 25 | T7: Expired
B8: WTI Sprds-Fly | C8: Futures | D8: =D2 -> WTI Sprds | E8: WTI | F8: WTI | N8: =+N7+1 -> 4 | O8: J | S8: Dec 16-20/Dec 24 | T8: Expired
B9: Freight-TD22 | C9: Freight | D9: Freight | N9: =+N8+1 -> 5 | O9: K | S9: Dec 23-27/Dec 24 | T9: Expired
B10: WTI-Brent - EFP | C10: EFP Value | D10: WTI-Brent | N10: =+N9+1 -> 6 | O10: M | S10: Mar03-Mar07/Jan 25 | T10: Expired
B11: Freight-TD25 | C11: Freight | D11: Freight | N11: =+N10+1 -> 7 | O11: N | S11: Mar17-Mar21/Jan 25 | T11: Expired
B12: Freight-TD7 | C12: Freight | D12: Freight | N12: =+N11+1 -> 8 | O12: Q | S12: May19-May23/Jun 25 | T12: Expired
B13: CFD | C13: Swaps | D13: CFD | N13: =+N12+1 -> 9 | O13: U | S13: May19-May23/May 25 | T13: Expired
B14: MEH | C14: Swaps | D14: MEH | N14: =+N13+1 -> 10 | O14: V | S14: Nov/Dec 24 | T14: Expired
B15: Demurrage | C15: Physical | D15: Physical | N15: =+N14+1 -> 11 | O15: X | S15: Dec/Jan 24 | T15: Expired
B16: WTI CMA Diff | C16: Physical | D16: =D8 -> WTI Sprds | N16: =+N15+1 -> 12 | O16: Z | S16: Jan/Feb 25 | T16: Expired
B17: Legacy 2025 | C17: Legacy 2025 | D17: Legacy 2025 | S17: Feb/Mar 25 | T17: Expired
B18: Legacy 2024 | C18: Legacy 2024 | D18: Legacy 2024 | S18: Mar/Apr 25 | T18: Expired
B19: Legacy 2024 | C19: Legacy 2024 | D19: Legacy 2024 | S19: Apr/May 25 | T19: Expired
S20: May/Jun 25 | T20: Expired
S21: Dec 24 | T21: Expired
B22: Expiry Tables | S22: Jan 25 | T22: Expired
B23: WTI Sprds | S23: Feb 25 | T23: Expired
B24: Brent Sprds | S24: Mar 25 | T24: Expired
B25: WTI-Brent | S25: Apr 25 | T25: Expired
B26: Dated | S26: May 25 | T26: Expired
S27: Oct 24 | T27: Expired
B28: Dated | S28: Nov 24 | T28: Expired
B29: WTI Sprds | S29: Jan 23 | T29: Expired
B30: Freight | S30: Sep/Oct 24 | T30: Expired
B31: WTI-Brent | S31: Jan 6-10/Jan 25 | T31: Expired
B32: Freight | S32: Jan 20-24/Jan 25 | T32: Expired
B33: Freight | S33: Jan27-Jan31/Jan 25 | T33: Expired
B34: CFD | S34: Jun 25 | T34: Expired
B35: MEH | S35: Jun/Jul 25 | T35: Expired
B36: Physical | S36: Jul 25 | T36: Expired
B37: WTI Sprds | S37: Jul/Aug 25 | T37: Expired
B38: Legacy 2024 | S38: Aug/Sep 25 | T38: Expired
S39: Sep/Oct 25 | T39: Expired
S40: Oct/Nov 25 | T40: Expired
...

Sheet Trades 2026 1.14
A1: Cargo Name | B1: Date | C1: Sub-Instrument | D1: Expo Type | E1: Quantity | F1: Month1 | G1: Month2 | H1: Price | I1: Mtm | J1: PnL | K1: Average | L1: Name | M1: Buy/Sell | N1: Average MtM | O1: Instrument Type | P1: Instrument | Q1: Year | R1: Side | S1: Accounting | T1: Trade ID | U1: Phys Active?
A2: Unallocated | B2: 45980 | C2: WTI Sprds | D2: Hedge | E2: -1122 | F2: 45991 | G2: 46022 | H2: 0.5 | I2: 0.5 | J2: 0 | K2: -561 | L2: Nov/Dec 25 | M2: Sell | N2: -561 | O2: Futures | P2: WTI Sprds | Q2: 2025 | R2: Sell | S2: Expired | T2: UnallocatedWTI SprdsHedge-11220.52 | U2: =IFERROR(_xlfn.XLOOKUP(A2,'2025 EOY'!A:A,'2025 EOY'!B:B),"No") -> No
A3: Unallocated | B3: 45980 | C3: WTI Sprds-Fly | D3: Hedge | E3: 1122 | F3: 45991 | G3: 46022 | H3: 0.5 | I3: 0.5 | K3: 213.18 | L3: Nov/Dec 25 | M3: Buy | N3: 561 | O3: Futures | P3: WTI Sprds | Q3: 2025 | R3: Buy | S3: Expired | T3: UnallocatedWTI Sprds-FlyHedge11220.53 | U3: =IFERROR(_xlfn.XLOOKUP(A3,'2025 EOY'!A:A,'2025 EOY'!B:B),"No") -> No
A4: Unallocated | B4: 45980 | C4: WTI Sprds | D4: Hedge | E4: 1122 | F4: 46022 | G4: 46053 | H4: 0.19 | I4: 0.19 | K4: 561 | L4: Dec/Jan 25 | M4: Buy | N4: 213.18 | O4: Futures | P4: WTI Sprds | Q4: 2025 | R4: Buy | S4: Expired | T4: UnallocatedWTI SprdsHedge11220.194 | U4: =IFERROR(_xlfn.XLOOKUP(A4,'2025 EOY'!A:A,'2025 EOY'!B:B),"No") -> No
A5: Unallocated | B5: 45980 | C5: WTI Sprds-Fly | D5: Hedge | E5: -1122 | F5: 46022 | G5: 46053 | H5: 0.19 | I5: 0.19 | J5: 0 | K5: -213.18 | L5: Dec/Jan 25 | M5: Sell | N5: -213.18 | O5: Futures | P5: WTI Sprds | Q5: 2025 | R5: Sell | S5: Expired | T5: UnallocatedWTI Sprds-FlyHedge-11220.195 | U5: =IFERROR(_xlfn.XLOOKUP(A5,'2025 EOY'!A:A,'2025 EOY'!B:B),"No") -> No
A6: Unallocated | B6: 45906 | C6: CFD | D6: Hedge | E6: -500 | F6: Apr07-Apr11 | G6: 45777 | H6: 2.26 | I6: 2.26 | J6: 0 | K6: -1130 | L6: Apr07-Apr11/Apr 25 | M6: Buy | N6: 397.6 | O6: Swaps | P6: Dated | Q6: 2025 | R6: Sell | S6: Expired | T6: UnallocatedCFDHedge-5002.266 | U6: =IFERROR(_xlfn.XLOOKUP(A6,'2025 EOY'!A:A,'2025 EOY'!B:B),"No") -> No
A7: Unallocated | B7: 45906 | C7: CFD | D7: Hedge | E7: 500 | F7: Apr14-Apr18 | G7: 45777 | H7: 1.86 | I7: 1.86 | J7: 0 | K7: 930 | L7: Apr14-Apr18/Apr 25 | M7: Buy | N7: 397.6 | O7: Swaps | P7: Dated | Q7: 2025 | R7: Buy | S7: Expired | T7: UnallocatedCFDHedge5001.867 | U7: =IFERROR(_xlfn.XLOOKUP(A7,'2025 EOY'!A:A,'2025 EOY'!B:B),"No") -> No
A8: Unallocated | B8: 45906 | C8: CFD | D8: Hedge | E8: 400 | F8: Dec 16-20 | G8: 45657 | H8: 0.847 | I8: 0.847 | J8: 0 | K8: 338.8 | L8: Dec 16-20/Dec 24 | M8: Buy | N8: 397.6 | O8: Swaps | P8: Dated | Q8: 2024 | R8: Buy | S8: Expired | T8: UnallocatedCFDHedge4000.8478 | U8: =IFERROR(_xlfn.XLOOKUP(A8,'2025 EOY'!A:A,'2025 EOY'!B:B),"No") -> No
A9: Unallocated | B9: 45906 | C9: CFD | D9: Hedge | E9: 200 | F9: Dec 23-27 | G9: 45657 | H9: -0.09 | I9: -0.09 | J9: 0 | K9: -18 | L9: Dec 23-27/Dec 24 | M9: Buy | N9: 397.6 | O9: Swaps | P9: Dated | Q9: 2024 | R9: Buy | S9: Expired | T9: UnallocatedCFDHedge200-0.099 | U9: =IFERROR(_xlfn.XLOOKUP(A9,'2025 EOY'!A:A,'2025 EOY'!B:B),"No") -> No
A10: Unallocated | B10: 45719 | C10: CFD | D10: Hedge | E10: -200 | F10: Mar03-Mar07 | G10: 45688 | H10: 1.32 | I10: 1.32 | J10: 0 | K10: -264 | L10: Mar03-Mar07/Jan 25 | M10: Sell | N10: -264 | O10: Swaps | P10: Dated | Q10: 2025 | R10: Sell | S10: Expired | T10: UnallocatedCFDHedge-2001.3210 | U10: =IFERROR(_xlfn.XLOOKUP(A10,'2025 EOY'!A:A,'2025 EOY'!B:B),"No") -> No
A11: Unallocated | B11: 45719 | C11: CFD | D11: Hedge | E11: 200 | F11: Mar17-Mar21 | G11: 45688 | H11: 0.54 | I11: 0.54 | J11: 0 | K11: 108 | L11: Mar17-Mar21/Jan 25 | M11: Buy | N11: 108 | O11: Swaps | P11: Dated | Q11: 2025 | R11: Buy | S11: Expired | T11: UnallocatedCFDHedge2000.5411 | U11: =IFERROR(_xlfn.XLOOKUP(A11,'2025 EOY'!A:A,'2025 EOY'!B:B),"No") -> No
A12: Trafi CIF Rdam June 13-17 | B12: 45804 | C12: CFD | D12: Hedge | E12: -1500 | F12: May19-May23 | G12: 45838 | H12: 0.472 | I12: 0.472 | J12: -1.6653345e-13 | K12: -708 | L12: May19-May23/Jun 25 | M12: Sell | N12: -708 | O12: Swaps | P12: Dated | Q12: 2025 | R12: Sell | S12: Expired | T12: Trafi CIF Rdam June 13-17CFDHedge-15000.47212 | U12: =IFERROR(_xlfn.XLOOKUP(A12,'2025 EOY'!A:A,'2025 EOY'!B:B),"No") -> No
A13: Unallocated | B13: 45793 | C13: CFD | D13: Hedge | E13: 1500 | F13: May19-May23 | G13: 45808 | H13: 0.472 | I13: 0.472 | J13: 0 | K13: 708 | L13: May19-May23/May 25 | M13: Buy | N13: 708 | O13: Swaps | P13: Dated | Q13: 2025 | R13: Buy | S13: Expired | T13: UnallocatedCFDHedge15000.47213 | U13: =IFERROR(_xlfn.XLOOKUP(A13,'2025 EOY'!A:A,'2025 EOY'!B:B),"No") -> No
A14: Unallocated | B14: 45727 | C14: WTI Sprds | D14: Hedge | E14: -4289 | F14: 45626 | G14: 45657 | H14: 0.62 | I14: 0.52 | J14: 428.9 | K14: -2659.18 | L14: Nov/Dec 24 | M14: Sell | N14: -2230.28 | O14: Futures | P14: WTI Sprds | Q14: 2024 | R14: Sell | S14: Expired | T14: UnallocatedWTI SprdsHedge-42890.5214 | U14: =IFERROR(_xlfn.XLOOKUP(A14,'2025 EOY'!A:A,'2025 EOY'!B:B),"No") -> No
A15: Jan 1-10 EXTAP VLCC | B15: 45727 | C15: WTI Sprds | D15: Hedge | E15: 1050 | F15: 45626 | G15: 45657 | H15: 0.62 | I15: 0.52 | J15: -105 | K15: 651 | L15: Nov/Dec 24 | M15: Buy | N15: 546 | O15: Futures | P15: WTI Sprds | Q15: 2024 | R15: Buy | S15: Expired | T15: Jan 1-10 EXTAP VLCCWTI SprdsHedge10500.5215 | U15: =IFERROR(_xlfn.XLOOKUP(A15,'2025 EOY'!A:A,'2025 EOY'!B:B),"No") -> No
A16: Jan 4-6 KAL Afra | B16: 45727 | C16: WTI Sprds | D16: Hedge | E16: 707 | F16: 45626 | G16: 45657 | H16: 0.62 | I16: 0.52 | J16: -70.7 | K16: 438.34 | L16: Nov/Dec 24 | M16: Buy | N16: 367.64 | O16: Futures | P16: WTI Sprds | Q16: 2024 | R16: Buy | S16: Expired | T16: Jan 4-6 KAL AfraWTI SprdsHedge7070.5216 | U16: =IFERROR(_xlfn.XLOOKUP(A16,'2025 EOY'!A:A,'2025 EOY'!B:B),"No") -> No
A17: Nov 19-21 Shell Rdam VLCC | B17: 45727 | C17: WTI Sprds | D17: Hedge | E17: 2100 | F17: 45626 | G17: 45657 | H17: 0.62 | I17: 0.52 | J17: -210 | K17: 1302 | L17: Nov/Dec 24 | M17: Buy | N17: 1092 | O17: Futures | P17: WTI Sprds | Q17: 2024 | R17: Buy | S17: Expired | T17: Nov 19-21 Shell Rdam VLCCWTI SprdsHedge21000.5217 | U17: =IFERROR(_xlfn.XLOOKUP(A17,'2025 EOY'!A:A,'2025 EOY'!B:B),"No") -> No
A18: Nov 22-26 Tranmere Afra | B18: 45727 | C18: WTI Sprds | D18: Hedge | E18: 432 | F18: 45626 | G18: 45657 | H18: 0.62 | I18: 0.52 | J18: -43.2 | K18: 267.84 | L18: Nov/Dec 24 | M18: Buy | N18: 224.64 | O18: Futures | P18: WTI Sprds | Q18: 2024 | R18: Buy | S18: Expired | T18: Nov 22-26 Tranmere AfraWTI SprdsHedge4320.5218 | U18: =IFERROR(_xlfn.XLOOKUP(A18,'2025 EOY'!A:A,'2025 EOY'!B:B),"No") -> No
A19: Unallocated | B19: 45727 | C19: WTI Sprds | D19: Hedge | E19: -1500 | F19: 45657 | G19: 45688 | H19: 0.28 | I19: 0.15 | J19: 195 | K19: -420 | L19: Dec/Jan 24 | M19: Sell | N19: -225 | O19: Futures | P19: WTI Sprds | Q19: 2024 | R19: Sell | S19: Expired | T19: UnallocatedWTI SprdsHedge-15000.1519 | U19: =IFERROR(_xlfn.XLOOKUP(A19,'2025 EOY'!A:A,'2025 EOY'!B:B),"No") -> No
A20: CPC TAIWAN JAN 8-14 | B20: 45727 | C20: WTI Sprds | D20: Hedge | E20: -50 | F20: 45657 | G20: 45688 | H20: 0.28 | I20: 0.15 | J20: 6.5 | K20: -14 | L20: Dec/Jan 24 | M20: Sell | N20: -7.5 | O20: Futures | P20: WTI Sprds | Q20: 2024 | R20: Sell | S20: Expired | T20: CPC TAIWAN JAN 8-14WTI SprdsHedge-500.1520 | U20: =IFERROR(_xlfn.XLOOKUP(A20,'2025 EOY'!A:A,'2025 EOY'!B:B),"No") -> No
A21: EXTAP Feb 15-25 | B21: 45727 | C21: WTI Sprds | D21: Hedge | E21: -24 | F21: 45657 | G21: 45688 | H21: 0.28 | I21: 0.15 | J21: 3.12 | K21: -6.72 | L21: Dec/Jan 24 | M21: Sell | N21: -3.6 | O21: Futures | P21: WTI Sprds | Q21: 2024 | R21: Sell | S21: Expired | T21: EXTAP Feb 15-25WTI SprdsHedge-240.1521 | U21: =IFERROR(_xlfn.XLOOKUP(A21,'2025 EOY'!A:A,'2025 EOY'!B:B),"No") -> No
A22: Gunvor FOB Dec 6-7 | B22: 45727 | C22: WTI Sprds | D22: Hedge | E22: 68 | F22: 45657 | G22: 45688 | H22: 0.28 | I22: 0.15 | J22: -8.84 | K22: 19.04 | L22: Dec/Jan 24 | M22: Buy | N22: 10.2 | O22: Futures | P22: WTI Sprds | Q22: 2024 | R22: Buy | S22: Expired | T22: Gunvor FOB Dec 6-7WTI SprdsHedge680.1522 | U22: =IFERROR(_xlfn.XLOOKUP(A22,'2025 EOY'!A:A,'2025 EOY'!B:B),"No") -> No | Z22: 28
A23: HDO Feb 5-15 | B23: 45727 | C23: WTI Sprds | D23: Hedge | E23: 24 | F23: 45657 | G23: 45688 | H23: 0.28 | I23: 0.15 | J23: -3.12 | K23: 6.72 | L23: Dec/Jan 24 | M23: Buy | N23: 3.6 | O23: Futures | P23: WTI Sprds | Q23: 2024 | R23: Buy | S23: Expired | T23: HDO Feb 5-15WTI SprdsHedge240.1523 | U23: =IFERROR(_xlfn.XLOOKUP(A23,'2025 EOY'!A:A,'2025 EOY'!B:B),"No") -> No
A24: Jan 1-10 EXTAP VLCC | B24: 45727 | C24: WTI Sprds | D24: Hedge | E24: 1050 | F24: 45657 | G24: 45688 | H24: 0.28 | I24: 0.15 | J24: -136.5 | K24: 294 | L24: Dec/Jan 24 | M24: Buy | N24: 157.5 | O24: Futures | P24: WTI Sprds | Q24: 2024 | R24: Buy | S24: Expired | T24: Jan 1-10 EXTAP VLCCWTI SprdsHedge10500.1524 | U24: =IFERROR(_xlfn.XLOOKUP(A24,'2025 EOY'!A:A,'2025 EOY'!B:B),"No") -> No
A25: Nov 22-26 Tranmere Afra | B25: 45727 | C25: WTI Sprds | D25: Hedge | E25: 432 | F25: 45657 | G25: 45688 | H25: 0.28 | I25: 0.15 | J25: -56.16 | K25: 120.96 | L25: Dec/Jan 24 | M25: Buy | N25: 64.8 | O25: Futures | P25: WTI Sprds | Q25: 2024 | R25: Buy | S25: Expired | T25: Nov 22-26 Tranmere AfraWTI SprdsHedge4320.1525 | U25: =IFERROR(_xlfn.XLOOKUP(A25,'2025 EOY'!A:A,'2025 EOY'!B:B),"No") -> No
A26: CPC TAIWAN FEB 20-24 | B26: 45727 | C26: WTI Sprds | D26: Hedge | E26: 800 | F26: 45688 | G26: 45716 | H26: 0.42 | I26: 0.56 | J26: 112 | K26: 336 | L26: Jan/Feb 25 | M26: Buy | N26: 448 | O26: Futures | P26: WTI Sprds | Q26: 2025 | R26: Buy | S26: Expired | T26: CPC TAIWAN FEB 20-24WTI SprdsHedge8000.5626 | U26: =IFERROR(_xlfn.XLOOKUP(A26,'2025 EOY'!A:A,'2025 EOY'!B:B),"No") -> No
A27: CPC TAIWAN MARCH 11-15 | B27: 45727 | C27: WTI Sprds | D27: Hedge | E27: 2096 | F27: 45688 | G27: 45716 | H27: 0.42 | I27: 0.56 | J27: 293.44 | K27: 880.32 | L27: Jan/Feb 25 | M27: Buy | N27: 1173.76 | O27: Futures | P27: WTI Sprds | Q27: 2025 | R27: Buy | S27: Expired | T27: CPC TAIWAN MARCH 11-15WTI SprdsHedge20960.5627 | U27: =IFERROR(_xlfn.XLOOKUP(A27,'2025 EOY'!A:A,'2025 EOY'!B:B),"No") -> No
A28: EXTAP Feb 15-25 | B28: 45727 | C28: WTI Sprds | D28: Hedge | E28: -24 | F28: 45688 | G28: 45716 | H28: 0.42 | I28: 0.56 | J28: -3.36 | K28: -10.08 | L28: Jan/Feb 25 | M28: Sell | N28: -13.44 | O28: Futures | P28: WTI Sprds | Q28: 2025 | R28: Sell | S28: Expired | T28: EXTAP Feb 15-25WTI SprdsHedge-240.5628 | U28: =IFERROR(_xlfn.XLOOKUP(A28,'2025 EOY'!A:A,'2025 EOY'!B:B),"No") -> No
A29: Feb EFP 2 | B29: 45727 | C29: WTI Sprds | D29: Hedge | E29: 700 | F29: 45688 | G29: 45716 | H29: 0.42 | I29: 0.56 | J29: 98 | K29: 294 | L29: Jan/Feb 25 | M29: Buy | N29: 392 | O29: Futures | P29: WTI Sprds | Q29: 2025 | R29: Buy | S29: Expired | T29: Feb EFP 2WTI SprdsHedge7000.5629 | U29: =IFERROR(_xlfn.XLOOKUP(A29,'2025 EOY'!A:A,'2025 EOY'!B:B),"No") -> No
A30: HDO Feb 5-15 | B30: 45727 | C30: WTI Sprds | D30: Hedge | E30: 47 | F30: 45688 | G30: 45716 | H30: 0.42 | I30: 0.56 | J30: 6.58 | K30: 19.74 | L30: Jan/Feb 25 | M30: Buy | N30: 26.32 | O30: Futures | P30: WTI Sprds | Q30: 2025 | R30: Buy | S30: Expired | T30: HDO Feb 5-15WTI SprdsHedge470.5630 | U30: =IFERROR(_xlfn.XLOOKUP(A30,'2025 EOY'!A:A,'2025 EOY'!B:B),"No") -> No
A31: Jan 4-6 KAL Afra | B31: 45727 | C31: WTI Sprds | D31: Hedge | E31: 35 | F31: 45688 | G31: 45716 | H31: 0.42 | I31: 0.56 | J31: 4.9 | K31: 14.7 | L31: Jan/Feb 25 | M31: Buy | N31: 19.6 | O31: Futures | P31: WTI Sprds | Q31: 2025 | R31: Buy | S31: Expired | T31: Jan 4-6 KAL AfraWTI SprdsHedge350.5631 | U31: =IFERROR(_xlfn.XLOOKUP(A31,'2025 EOY'!A:A,'2025 EOY'!B:B),"No") -> No
A32: Mitsui CIF Rdam Jan 27-29 | B32: 45727 | C32: WTI Sprds | D32: Hedge | E32: 735 | F32: 45688 | G32: 45716 | H32: 0.42 | I32: 0.56 | J32: 102.9 | K32: 308.7 | L32: Jan/Feb 25 | M32: Buy | N32: 411.6 | O32: Futures | P32: WTI Sprds | Q32: 2025 | R32: Buy | S32: Expired | T32: Mitsui CIF Rdam Jan 27-29WTI SprdsHedge7350.5632 | U32: =IFERROR(_xlfn.XLOOKUP(A32,'2025 EOY'!A:A,'2025 EOY'!B:B),"No") -> No
A33: Unallocated | B33: 45727 | C33: WTI Sprds | D33: Hedge | E33: -4389 | F33: 45688 | G33: 45716 | H33: 0.42 | I33: 0.56 | J33: -614.46 | K33: -1843.38 | L33: Jan/Feb 25 | M33: Sell | N33: -2457.84 | O33: Futures | P33: WTI Sprds | Q33: 2025 | R33: Sell | S33: Expired | T33: UnallocatedWTI SprdsHedge-43890.5633 | U33: =IFERROR(_xlfn.XLOOKUP(A33,'2025 EOY'!A:A,'2025 EOY'!B:B),"No") -> No
A34: BPCL DES India March 16-22 | B34: 45727 | C34: WTI Sprds | D34: Hedge | E34: 2079 | F34: 45716 | G34: 45747 | H34: 0.39 | I34: 0.49 | J34: 207.9 | K34: 810.81 | L34: Feb/Mar 25 | M34: Buy | N34: 1018.71 | O34: Futures | P34: WTI Sprds | Q34: 2025 | R34: Buy | S34: Expired | T34: BPCL DES India March 16-22WTI SprdsHedge20790.4934 | U34: =IFERROR(_xlfn.XLOOKUP(A34,'2025 EOY'!A:A,'2025 EOY'!B:B),"No") -> No
... A96: Mitsui CIF Rdam Jan 27-29 | B96: 45726 | C96: WTI-Brent | D96: Hedge | E96: 735 | F96: 45747 | G96: 45747 | H96: -3.5 | I96: -4.23 | J96: -536.55 | K96: -2572.5 | L96: Mar 25 | M96: Buy | N96: -3109.05 | O96: Swaps | P96: WTI-Brent | Q96: 2025 | R96: Buy | S96: Expired | T96: Mitsui CIF Rdam Jan 27-29WTI-BrentHedge735-4.2396 | U96: =IFERROR(_xlfn.XLOOKUP(A96,'2025 EOY'!A:A,'2025 EOY'!B:B),"No") -> No
A97: Unallocated | B97: 45726 | C97: WTI-Brent | D97: Hedge | E97: -5614 | F97: 45747 | G97: 45747 | H97: -3.5 | I97: -4.23 | J97: 4098.22 | K97: 19649 | L97: Mar 25 | M97: Sell | N97: 23747.22 | O97: Swaps | P97: WTI-Brent | Q97: 2025 | R97: Sell | S97: Expired | T97: UnallocatedWTI-BrentHedge-5614-4.2397 | U97: =IFERROR(_xlfn.XLOOKUP(A97,'2025 EOY'!A:A,'2025 EOY'!B:B),"No") -> No | W97: 0.35
A98: HDO April 12-22 25 | B98: 45726 | C98: WTI-Brent | D98: Hedge | E98: 68 | F98: 45777 | G98: 45777 | H98: -9.38 | I98: -3.42 | J98: 405.28 | K98: -637.84 | L98: Apr 25 | M98: Buy | N98: -232.56 | O98: Swaps | P98: WTI-Brent | Q98: 2025 | R98: Buy | S98: Expired | T98: HDO April 12-22 25WTI-BrentHedge68-3.4298 | U98: =IFERROR(_xlfn.XLOOKUP(A98,'2025 EOY'!A:A,'2025 EOY'!B:B),"No") -> No | W98: 1.3
A99: Unallocated | B99: 45726 | C99: WTI-Brent | D99: Hedge | E99: -68 | F99: 45777 | G99: 45777 | H99: -9.38 | I99: -3.42 | J99: -405.28 | K99: 637.84 | L99: Apr 25 | M99: Sell | N99: 232.56 | O99: Swaps | P99: WTI-Brent | Q99: 2025 | R99: Sell | S99: Expired | T99: UnallocatedWTI-BrentHedge-68-3.4299 | U99: =IFERROR(_xlfn.XLOOKUP(A99,'2025 EOY'!A:A,'2025 EOY'!B:B),"No") -> No | W99: 0.27
A100: Feb EFP 4 | B100: 45726 | C100: WTI-Brent | D100: Hedge | E100: 700 | F100: 45808 | G100: 45808 | H100: -3.83 | I100: -3.26 | J100: 399 | K100: -2681 | L100: May 25 | M100: Buy | N100: -2282 | O100: Swaps | P100: WTI-Brent | Q100: 2025 | R100: Buy | S100: Expired | T100: Feb EFP 4WTI-BrentHedge700-3.26100 | U100: =IFERROR(_xlfn.XLOOKUP(A100,'2025 EOY'!A:A,'2025 EOY'!B:B),"No") -> No | W100: 0.26
A101: Unallocated | B101: 45726 | C101: WTI-Brent | D101: Hedge | E101: -700 | F101: 45808 | G101: 45808 | H101: -3.83 | I101: -3.26 | J101: -399 | K101: 2681 | L101: May 25 | M101: Sell | N101: 2282 | O101: Swaps | P101: WTI-Brent | Q101: 2025 | R101: Sell | S101: Expired | T101: UnallocatedWTI-BrentHedge-700-3.26101 | U101: =IFERROR(_xlfn.XLOOKUP(A101,'2025 EOY'!A:A,'2025 EOY'!B:B),"No") -> No | W101: -3.76
...

Sheet Trades 2026
A1: RA Deal Number | B1: SAP Deal Number | C1: Physical Xref | D1: Cargo Name | E1: Date | F1: Sub-Instrument | G1: Expo Type | H1: Quantity | I1: Month1 | J1: Month2 | K1: Price | L1: Mtm | M1: PnL | N1: Average | O1: Name | P1: Buy/Sell | Q1: Average MtM | R1: Instrument Type | S1: Instrument | T1: Year | U1: Side | V1: Accounting | W1: M1 Instrument | X1: M1 Month | Y1: M1 Volume | Z1: M2 | AA1: M2 Month | AB1: M2 Volume
A2: Cargoes | B2: =_xlfn.XLOOKUP(Table3[[#This Row],[Cargo Name]],Ledger[Cargo Name],Ledger[SAP Deal Number]) -> ARA26HS00006 | C2: 0 | D2: CPC Taiwan Jan 17-21 | E2: 46022 | F2: Legacy 2025 | G2: Expo | I2: 45991 | J2: =I2 -> 45991 | M2: -196 | N2: =H2*K2 -> 0 | O2: =IF(I2=J2,TEXT(I2,"MMM YY"),TEXT(I2,"MMM")&"/"&TEXT(J2,"MMM")&" "&RIGHT(T2,2)) -> Nov 25 | P2: =IF(H2<0,"Sell","Buy") -> Buy | Q2: =H2*L2 -> 0 | R2: =VLOOKUP(F2,Control!$B:$C,2,FALSE) -> Legacy 2025 | S2: =VLOOKUP(F2,Control!$B:$D,3,FALSE) -> Legacy 2025 | T2: =YEAR(I2) -> 2025 | U2: =IFERROR(IF(H2>0,"Buy","Sell"),"") -> Sell | V2: Active | W2: =_xlfn.XLOOKUP(Table3[[#This Row],[Instrument]],Control!$B$2:$B$19,Control!$E$2:$E$19) -> 0 | X2: =Table3[[#This Row],[Month1]] -> 45991 | Y2: =Table3[[#This Row],[Quantity]] -> 0 | Z2: =_xlfn.XLOOKUP(Table3[[#This Row],[Instrument]],Control!$B$2:$B$19,Control!$F$2:$F$19) -> 0 | AA2: =Table3[[#This Row],[Month2]] -> 45991 | AB2: =-Y2 -> 0
A3: Cargoes | B3: =_xlfn.XLOOKUP(Table3[[#This Row],[Cargo Name]],Ledger[Cargo Name],Ledger[SAP Deal Number]) -> ARA26HS00013 | C3: 0 | D3: HDO March26 10-20 | E3: 46022 | F3: Legacy 2025 | G3: Expo | I3: 46022 | J3: =I3 -> 46022 | M3: -222 | N3: =H3*K3 -> 0 | O3: =IF(I3=J3,TEXT(I3,"MMM YY"),TEXT(I3,"MMM")&"/"&TEXT(J3,"MMM")&" "&RIGHT(T3,2)) -> Dec 25 | P3: =IF(H3<0,"Sell","Buy") -> Buy | Q3: =H3*L3 -> 0 | R3: =VLOOKUP(F3,Control!$B:$C,2,FALSE) -> Legacy 2025 | S3: =VLOOKUP(F3,Control!$B:$D,3,FALSE) -> Legacy 2025 | T3: =YEAR(I3) -> 2025 | U3: =IFERROR(IF(H3>0,"Buy","Sell"),"") -> Sell | V3: Active | W3: =_xlfn.XLOOKUP(Table3[[#This Row],[Instrument]],Control!$B$2:$B$19,Control!$E$2:$E$19) -> 0 | X3: =Table3[[#This Row],[Month1]] -> 46022 | Y3: =Table3[[#This Row],[Quantity]] -> 0 | Z3: =_xlfn.XLOOKUP(Table3[[#This Row],[Instrument]],Control!$B$2:$B$19,Control!$F$2:$F$19) -> 0 | AA3: =Table3[[#This Row],[Month2]] -> 46022 | AB3: =-Y3 -> 0
A4: Cargoes | B4: =_xlfn.XLOOKUP(Table3[[#This Row],[Cargo Name]],Ledger[Cargo Name],Ledger[SAP Deal Number]) -> ARA26HS00009 | C4: 0 | D4: Exxon CIF Rotts VLCC Jan 19-23 | E4: 46022 | F4: Legacy 2025 | G4: Expo | I4: 46022 | J4: =I4 -> 46022 | M4: 605 | N4: =H4*K4 -> 0 | O4: =IF(I4=J4,TEXT(I4,"MMM YY"),TEXT(I4,"MMM")&"/"&TEXT(J4,"MMM")&" "&RIGHT(T4,2)) -> Dec 25 | P4: =IF(H4<0,"Sell","Buy") -> Buy | Q4: =H4*L4 -> 0 | R4: =VLOOKUP(F4,Control!$B:$C,2,FALSE) -> Legacy 2025 | S4: =VLOOKUP(F4,Control!$B:$D,3,FALSE) -> Legacy 2025 | T4: =YEAR(I4) -> 2025 | U4: =IFERROR(IF(H4>0,"Buy","Sell"),"") -> Sell | V4: Active | W4: =_xlfn.XLOOKUP(Table3[[#This Row],[Instrument]],Control!$B$2:$B$19,Control!$E$2:$E$19) -> 0 | X4: =Table3[[#This Row],[Month1]] -> 46022 | Y4: =Table3[[#This Row],[Quantity]] -> 0 | Z4: =_xlfn.XLOOKUP(Table3[[#This Row],[Instrument]],Control!$B$2:$B$19,Control!$F$2:$F$19) -> 0 | AA4: =Table3[[#This Row],[Month2]] -> 46022 | AB4: =-Y4 -> 0
D5: Legacy 2025 | E5: 46022 | F5: Legacy 2025 | M5: 408 | N5: =H5*K5 -> 0 | P5: =IF(H5<0,"Sell","Buy") -> Buy | Q5: =H5*L5 -> 0 | R5: =VLOOKUP(F5,Control!$B:$C,2,FALSE) -> Legacy 2025 | S5: Brent Sprds | T5: 2025 | U5: =IFERROR(IF(H5>0,"Buy","Sell"),"") -> Sell | V5: Active | W5: =_xlfn.XLOOKUP(Table3[[#This Row],[Instrument]],Control!$B$2:$B$19,Control!$E$2:$E$19) -> Brent | X5: =Table3[[#This Row],[Month1]] -> 0 | Y5: =Table3[[#This Row],[Quantity]] -> 0 | Z5: =_xlfn.XLOOKUP(Table3[[#This Row],[Instrument]],Control!$B$2:$B$19,Control!$F$2:$F$19) -> Brent | AA5: =Table3[[#This Row],[Month2]] -> 0 | AB5: =-Y5 -> 0
D6: Legacy 2025 | E6: 46022 | F6: Legacy 2025 | M6: -191 | N6: =H6*K6 -> 0 | P6: =IF(H6<0,"Sell","Buy") -> Buy | Q6: =H6*L6 -> 0 | R6: =VLOOKUP(F6,Control!$B:$C,2,FALSE) -> Legacy 2025 | S6: WTI Sprds | T6: 2025 | U6: =IFERROR(IF(H6>0,"Buy","Sell"),"") -> Sell | W6: =_xlfn.XLOOKUP(Table3[[#This Row],[Instrument]],Control!$B$2:$B$19,Control!$E$2:$E$19) -> WTI | X6: =Table3[[#This Row],[Month1]] -> 0 | Y6: =Table3[[#This Row],[Quantity]] -> 0 | Z6: =_xlfn.XLOOKUP(Table3[[#This Row],[Instrument]],Control!$B$2:$B$19,Control!$F$2:$F$19) -> WTI | AA6: =Table3[[#This Row],[Month2]] -> 0 | AB6: =-Y6 -> 0
D7: Legacy 2025 | E7: 46022 | F7: Legacy 2025 | M7: 428 | N7: =H7*K7 -> 0 | P7: =IF(H7<0,"Sell","Buy") -> Buy | Q7: =H7*L7 -> 0 | R7: =VLOOKUP(F7,Control!$B:$C,2,FALSE) -> Legacy 2025 | S7: Freight | T7: 2025 | U7: =IFERROR(IF(H7>0,"Buy","Sell"),"") -> Sell | W7: =_xlfn.XLOOKUP(Table3[[#This Row],[Instrument]],Control!$B$2:$B$19,Control!$E$2:$E$19) -> #N/A | X7: =Table3[[#This Row],[Month1]] -> 0 | Y7: =Table3[[#This Row],[Quantity]] -> 0 | Z7: =_xlfn.XLOOKUP(Table3[[#This Row],[Instrument]],Control!$B$2:$B$19,Control!$F$2:$F$19) -> #N/A | AA7: =Table3[[#This Row],[Month2]] -> 0 | AB7: =-Y7 -> 0
D8: Legacy 2025 | E8: 46022 | F8: Legacy 2025 | M8: 386 | N8: =H8*K8 -> 0 | P8: =IF(H8<0,"Sell","Buy") -> Buy | Q8: =H8*L8 -> 0 | R8: =VLOOKUP(F8,Control!$B:$C,2,FALSE) -> Legacy 2025 | S8: Dated | T8: 2025 | U8: =IFERROR(IF(H8>0,"Buy","Sell"),"") -> Sell | W8: =_xlfn.XLOOKUP(Table3[[#This Row],[Instrument]],Control!$B$2:$B$19,Control!$E$2:$E$19) -> #N/A | X8: =Table3[[#This Row],[Month1]] -> 0 | Y8: =Table3[[#This Row],[Quantity]] -> 0 | Z8: =_xlfn.XLOOKUP(Table3[[#This Row],[Instrument]],Control!$B$2:$B$19,Control!$F$2:$F$19) -> #N/A | AA8: =Table3[[#This Row],[Month2]] -> 0 | AB8: =-Y8 -> 0
D9: Legacy 2025 | E9: 46022 | F9: Legacy 2025 | M9: -274 | N9: =H9*K9 -> 0 | P9: =IF(H9<0,"Sell","Buy") -> Buy | Q9: =H9*L9 -> 0 | R9: =VLOOKUP(F9,Control!$B:$C,2,FALSE) -> Legacy 2025 | S9: MEH | T9: 2025 | U9: =IFERROR(IF(H9>0,"Buy","Sell"),"") -> Sell | W9: =_xlfn.XLOOKUP(Table3[[#This Row],[Instrument]],Control!$B$2:$B$19,Control!$E$2:$E$19) -> 0 | X9: =Table3[[#This Row],[Month1]] -> 0 | Y9: =Table3[[#This Row],[Quantity]] -> 0 | Z9: =_xlfn.XLOOKUP(Table3[[#This Row],[Instrument]],Control!$B$2:$B$19,Control!$F$2:$F$19) -> 0 | AA9: =Table3[[#This Row],[Month2]] -> 0 | AB9: =-Y9 -> 0
D10: Legacy 2025 | E10: 46022 | F10: Legacy 2025 | M10: -342 | N10: =H10*K10 -> 0 | P10: =IF(H10<0,"Sell","Buy") -> Buy | Q10: =H10*L10 -> 0 | R10: =VLOOKUP(F10,Control!$B:$C,2,FALSE) -> Legacy 2025 | S10: WTI-Brent | T10: 2025 | U10: =IFERROR(IF(H10>0,"Buy","Sell"),"") -> Sell | W10: =_xlfn.XLOOKUP(Table3[[#This Row],[Instrument]],Control!$B$2:$B$19,Control!$E$2:$E$19) -> WTI | X10: =Table3[[#This Row],[Month1]] -> 0 | Y10: =Table3[[#This Row],[Quantity]] -> 0 | Z10: =_xlfn.XLOOKUP(Table3[[#This Row],[Instrument]],Control!$B$2:$B$19,Control!$F$2:$F$19) -> Brent | AA10: =Table3[[#This Row],[Month2]] -> 0 | AB10: =-Y10 -> 0
A11: Cargoes | B11: =_xlfn.XLOOKUP(Table3[[#This Row],[Cargo Name]],Ledger[Cargo Name],Ledger[SAP Deal Number]) -> BPP25HS00089 | C11: 0 | D11: BP FOB VLCC Nov 15-20 | E11: 45944 | F11: WTI-Brent | G11: Expo | H11: -2100 | I11: 46053 | J11: 46053 | K11: -3.96 | L11: -4.65 | N11: 8316 | O11: Jan 26 | P11: Sell | Q11: 9765 | R11: Swaps | S11: WTI-Brent | T11: 2026 | U11: Sell | V11: Active | W11: =_xlfn.XLOOKUP(Table3[[#This Row],[Instrument]],Control!$B$2:$B$19,Control!$E$2:$E$19) -> WTI | X11: =Table3[[#This Row],[Month1]] -> 46053 | Y11: =Table3[[#This Row],[Quantity]] -> -2100 | Z11: =_xlfn.XLOOKUP(Table3[[#This Row],[Instrument]],Control!$B$2:$B$19,Control!$F$2:$F$19) -> Brent | AA11: =Table3[[#This Row],[Month2]] -> 46053 | AB11: =-Y11 -> 2100
A12: Cargoes | B12: =_xlfn.XLOOKUP(Table3[[#This Row],[Cargo Name]],Ledger[Cargo Name],Ledger[SAP Deal Number]) -> ARA26HS00006 | C12: 0 | D12: CPC Taiwan Jan 17-21 | E12: 45947 | F12: Physical | G12: Expo | H12: 2100 | I12: 45991 | J12: 45991 | K12: ='Cargo Econs 2025'!$J$343 -> 3.8866667 | L12: ='Cargo Econs 2025'!$J$344 -> 3.98 | M12: =IFERROR((L12-K12)*H12,"") -> 196 | N12: =H12*K12 -> 8162 | O12: =IF(I12=J12,TEXT(I12,"MMM YY"),TEXT(I12,"MMM")&"/"&TEXT(J12,"MMM")&" "&RIGHT(T12,2)) -> Nov 25 | P12: =IF(H12<0,"Sell","Buy") -> Buy | Q12: =H12*L12 -> 8358 | R12: =VLOOKUP(F12,Control!$B:$C,2,FALSE) -> Physical | S12: =VLOOKUP(F12,Control!$B:$D,3,FALSE) -> Physical | T12: =YEAR(I12) -> 2025 | U12: =IFERROR(IF(H12>0,"Buy","Sell"),"") -> Buy | V12: Active | W12: =_xlfn.XLOOKUP(Table3[[#This Row],[Instrument]],Control!$B$2:$B$19,Control!$E$2:$E$19) -> 0 | X12: =Table3[[#This Row],[Month1]] -> 45991 | Y12: =Table3[[#This Row],[Quantity]] -> 2100 | Z12: =_xlfn.XLOOKUP(Table3[[#This Row],[Instrument]],Control!$B$2:$B$19,Control!$F$2:$F$19) -> 0 | AA12: =Table3[[#This Row],[Month2]] -> 45991 | AB12: =-Y12 -> -2100
A13: Cargoes | B13: =_xlfn.XLOOKUP(Table3[[#This Row],[Cargo Name]],Ledger[Cargo Name],Ledger[SAP Deal Number]) -> ARA26HS00006 | C13: 0 | D13: CPC Taiwan Jan 17-21 | E13: 45947 | F13: WTI-Brent | G13: Expo | H13: -2100 | I13: 46053 | J13: 46053 | K13: -3.95 | L13: =IF(OR(S13="WTI Sprds",S13="Brent Sprds",S13="WTI-Brent",S13="DFL"),INDEX(INDIRECT("'" & S13 & "'!$A$6:$XFD$1048576"),MATCH('PnL26'!$P$1,INDIRECT("'" & S13 & "'!$A$6:$A$1048576"),0),MATCH(EOMONTH(I13,0),INDIRECT("'" & S13 & "'!$A$4:$XFD$4"),0)),INDEX(BBG!$A:$BA,MATCH('PnL26'!$P$1,BBG!$A:$A,0),MATCH($I13,BBG!$A$4:$BA$4,0))-INDEX(BBG!$A:$BA,MATCH('PnL26'!$P$1,BBG!$A:$A,0),MATCH($J13,BBG!$A$4:$BA$4,0))) -> -4.65 | N13: =H13*K13 -> 8295 | O13: =IF(I13=J13,TEXT(I13,"MMM YY"),TEXT(I13,"MMM")&"/"&TEXT(J13,"MMM")&" "&RIGHT(T13,2)) -> Jan 26 | P13: =IF(H13<0,"Sell","Buy") -> Sell | Q13: =H13*L13 -> 9765 | R13: =VLOOKUP(F13,Control!$B:$C,2,FALSE) -> Swaps | S13: =VLOOKUP(F13,Control!$B:$D,3,FALSE) -> WTI-Brent | T13: =YEAR(I13) -> 2026 | U13: =IFERROR(IF(H13>0,"Buy","Sell"),"") -> Sell | V13: Active | W13: =_xlfn.XLOOKUP(Table3[[#This Row],[Instrument]],Control!$B$2:$B$19,Control!$E$2:$E$19) -> WTI | X13: =Table3[[#This Row],[Month1]] -> 46053 | Y13: =Table3[[#This Row],[Quantity]] -> -2100 | Z13: =_xlfn.XLOOKUP(Table3[[#This Row],[Instrument]],Control!$B$2:$B$19,Control!$F$2:$F$19) -> Brent | AA13: =Table3[[#This Row],[Month2]] -> 46053 | AB13: =-Y13 -> 2100
