Workbook

Sheet Sheet1
Z1: 2.3
J2: 12/10/2025 | S2: Brent | W2: WTI | X2: BRENT | AB2: CMA to MEH Premium
B3: Link Data Services End of Day | P3: =EOMONTH(BBG!D5,0) -> 46356 | Q3: =BBG!E5 -> 93.14 | R3: =BBG!F5 -> 90.42 | S3: =EOMONTH(BBG!H5,0) -> 46387 | T3: =BBG!K5 -> 102.49 | U3: =BBG!L5 -> 98.03 | V3: =EOMONTH(TODAY(),0) -> 46326 | W3: =BBG!E63 -> 92.39 | X3: =BBG!K63 -> 102.31 | Y3: =W3-X3 -> -9.92
B4: US DOMESTIC PIPELINE ASSESSMENTS | P4: =EOMONTH(P3,1) -> 46387 | Q4: =BBG!E6 -> 91.08 | R4: =BBG!F6 -> 88.42 | S4: =EOMONTH(S3,1) -> 46418 | T4: =BBG!K6 -> 98.62 | U4: =BBG!L6 -> 95.09 | V4: =EOMONTH(V3,1) -> 46356 | W4: =BBG!E64 -> 90.56 | X4: =BBG!K64 -> 98.46 | Y4: =W4-X4 -> -7.9 | Z4: =Y4+Z1 -> -5.6 | AB4: =VLOOKUP(USG!E25,$P$3:$Q$41,2,FALSE)-VLOOKUP(USG!E25,$V$3:$W$41,2,FALSE) -> 2.58
B5: GRADE | C5: 46296 | D5: 46327 | E5: 46357 | F5: 46388 | G5: 46419 | H5: 46447 | I5: 46478 | J5: 46508 | K5: 46539 | L5: 46569 | M5: 46600 | N5: 46631 | P5: =EOMONTH(P4,1) -> 46418 | Q5: =BBG!E7 -> 88.99 | R5: =BBG!F7 -> 86.73 | S5: =EOMONTH(S4,1) -> 46446 | T5: =BBG!K7 -> 95.54 | U5: =BBG!L7 -> 92.85 | V5: =EOMONTH(V4,1) -> 46387 | W5: =BBG!E65 -> 88.3 | X5: =BBG!K65 -> 95.32 | Y5: =W5-X5 -> -7.02 | Z5: =T5-W5 -> 7.24 | AB5: =VLOOKUP(USG!E28,$P$3:$Q$41,2,FALSE)-VLOOKUP(USG!E28,$V$3:$W$41,2,FALSE) -> #N/A
B6: CMA | C6: 8.25 | D6: 4.308 | E6: 3.383 | F6: 2.453 | G6: 1.768 | H6: 1.642 | I6: 1.565 | J6: 1.36 | K6: 1.254 | L6: 1.254 | M6: 1.095 | N6: 0.993 | P6: =EOMONTH(P5,1) -> 46446 | Q6: =BBG!E8 -> 86.89 | R6: =BBG!F8 -> 85.11 | S6: =EOMONTH(S5,1) -> 46477 | T6: =BBG!K8 -> 93.22 | U6: =BBG!L8 -> 91.15 | V6: =EOMONTH(V5,1) -> 46418 | W6: =BBG!E66 -> 86.13 | X6: =BBG!K66 -> 93.12 | Y6: =W6-X6 -> -6.99 | Z6: mat | AB6: =VLOOKUP(USG!E29,$P$3:$Q$41,2,FALSE)-VLOOKUP(USG!E29,$V$3:$W$41,2,FALSE) -> #N/A
B7: MEH | C7: 0.75 | D7: 1.35 | E7: 1 | F7: 1.2 | G7: 1.4 | H7: 1.55 | I7: 1.75 | J7: 1.8 | K7: 1.85 | L7: 1.85 | M7: 1.85 | N7: 1.85 | P7: =EOMONTH(P6,1) -> 46477 | Q7: =BBG!E9 -> 84.93 | R7: =BBG!F9 -> 83.71 | S7: =EOMONTH(S6,1) -> 46507 | T7: =BBG!K9 -> 91.31 | U7: =BBG!L9 -> 89.67 | V7: =EOMONTH(V6,1) -> 46446 | W7: =BBG!E67 -> 84.57 | X7: =BBG!K67 -> 91.21 | Y7: =W7-X7 -> -6.64 | AB7: =VLOOKUP(USG!E30,$P$3:$Q$41,2,FALSE)-VLOOKUP(USG!E30,$V$3:$W$41,2,FALSE) -> #N/A
B8: MIDSWT | C8: -2.5 | D8: 0.7 | E8: 0.35 | F8: 0.65 | G8: 0.85 | H8: 1 | I8: 1.15 | J8: 1.2 | K8: 1.25 | L8: 1.25 | M8: 1.25 | N8: 1.25 | P8: =EOMONTH(P7,1) -> 46507 | Q8: =BBG!E10 -> 83.27 | R8: =BBG!F10 -> 82.45 | S8: =EOMONTH(S7,1) -> 46538 | T8: =BBG!K10 -> 89.62 | U8: =BBG!L10 -> 88.34 | V8: =EOMONTH(V7,1) -> 46477 | W8: =BBG!E68 -> 82.89 | X8: =BBG!K68 -> 89.53 | Y8: =W8-X8 -> -6.64 | AB8: =VLOOKUP(USG!E32,$P$3:$Q$41,2,FALSE)-VLOOKUP(USG!E32,$V$3:$W$41,2,FALSE) -> #N/A
B9: WTL | C9: -3.15 | D9: 0.15 | E9: -0.2 | F9: 0.1 | G9: 0.3 | H9: 0.45 | I9: 0.6 | J9: 0.65 | K9: 0.7 | L9: 0.7 | M9: 0.7 | N9: 0.7 | P9: =EOMONTH(P8,1) -> 46538 | Q9: =BBG!E11 -> 81.91 | R9: =BBG!F11 -> 81.32 | S9: =EOMONTH(S8,1) -> 46568 | T9: =BBG!K11 -> 88.09 | U9: =BBG!L11 -> 87.09 | V9: =EOMONTH(V8,1) -> 46507 | W9: =BBG!E69 -> 81.43 | X9: =BBG!K69 -> 88.01 | Y9: =W9-X9 -> -6.58 | AB9: =VLOOKUP(USG!E33,$P$3:$Q$41,2,FALSE)-VLOOKUP(USG!E33,$V$3:$W$41,2,FALSE) -> #N/A
B10: WTS | C10: -5.5 | D10: -6 | E10: -6 | F10: -6.1 | G10: -6.1 | H10: -6.1 | I10: -6.1 | J10: -6.1 | K10: -6.1 | L10: -6.1 | M10: -6.1 | N10: -6.1 | P10: =EOMONTH(P9,1) -> 46568 | Q10: =BBG!E12 -> 80.65 | R10: =BBG!F12 -> 80.28 | S10: =EOMONTH(S9,1) -> 46599 | T10: =BBG!K12 -> 86.69 | U10: =BBG!L12 -> 85.91 | V10: =EOMONTH(V9,1) -> 46538 | W10: =BBG!E70 -> 80.32 | X10: =BBG!K70 -> 86.57 | Y10: =W10-X10 -> -6.25 | AB10: =VLOOKUP(USG!E34,$P$3:$Q$41,2,FALSE)-VLOOKUP(USG!E34,$V$3:$W$41,2,FALSE) -> #N/A
B11: WTI EX BASIN | C11: 0.9 | D11: 1.05 | E11: 0.7 | F11: 1 | G11: 1.2 | H11: 1.35 | I11: 1.5 | J11: 1.55 | K11: 1.6 | L11: 1.6 | M11: 1.6 | N11: 1.6 | P11: =EOMONTH(P10,1) -> 46599 | Q11: =BBG!E13 -> 79.51 | R11: =BBG!F13 -> 79.31 | S11: =EOMONTH(S10,1) -> 46630 | T11: =BBG!K13 -> 85.46 | U11: =BBG!L13 -> 84.81 | V11: =EOMONTH(V10,1) -> 46568 | W11: =BBG!E71 -> 79.26 | X11: =BBG!K71 -> 85.38 | Y11: =W11-X11 -> -6.12 | AB11: =VLOOKUP(USG!E35,$P$3:$Q$41,2,FALSE)-VLOOKUP(USG!E35,$V$3:$W$41,2,FALSE) -> #N/A
B12: LLS | C12: 3.25 | D12: 2.15 | E12: 2.05 | F12: 1.7 | G12: 1.85 | H12: 2 | I12: 2.2 | J12: 2.25 | K12: 2.3 | L12: 2.3 | M12: 2.3 | N12: 2.3 | P12: =EOMONTH(P11,1) -> 46630 | Q12: =BBG!E14 -> 78.62 | R12: =BBG!F14 -> 78.4 | S12: =EOMONTH(S11,1) -> 46660 | T12: =BBG!K14 -> 84.33 | U12: =BBG!L14 -> 83.79 | V12: =EOMONTH(V11,1) -> 46599 | W12: =BBG!E72 -> 78.19 | X12: =BBG!K72 -> 84.25 | Y12: =W12-X12 -> -6.06 | AB12: =VLOOKUP(USG!E36,$P$3:$Q$41,2,FALSE)-VLOOKUP(USG!E36,$V$3:$W$41,2,FALSE) -> #N/A
B13: HLS | C13: 0 | D13: 4 | E13: 4 | F13: 3.75 | G13: 3.75 | H13: 3.75 | I13: 4 | J13: 4 | K13: 4 | L13: 4 | M13: 4 | N13: 4 | P13: =EOMONTH(P12,1) -> 46660 | Q13: =BBG!E15 -> 77.59 | R13: =BBG!F15 -> 77.55 | S13: =EOMONTH(S12,1) -> 46691 | T13: =BBG!K15 -> 83.23 | U13: =BBG!L15 -> 82.86 | V13: =EOMONTH(V12,1) -> 46630 | W13: =BBG!E73 -> 77.36 | X13: =BBG!K73 -> 83.24 | Y13: =W13-X13 -> -5.88 | AB13: =VLOOKUP(USG!E37,$P$3:$Q$41,2,FALSE)-VLOOKUP(USG!E37,$V$3:$W$41,2,FALSE) -> #N/A
B14: MARS | C14: -5 | D14: -1 | E14: -1 | F14: -1.25 | G14: -1.25 | H14: -1.25 | I14: -1 | J14: -1 | K14: -1 | L14: -1 | M14: -1 | N14: -1 | P14: =EOMONTH(P13,1) -> 46691 | Q14: =BBG!E16 -> 76.84 | R14: =BBG!F16 -> 76.78 | S14: =EOMONTH(S13,1) -> 46721 | T14: =BBG!K16 -> 82.43 | U14: =BBG!L16 -> 82.03 | V14: =EOMONTH(V13,1) -> 46660 | W14: =BBG!E74 -> 76.55 | X14: =BBG!K74 -> 82.36 | Y14: =W14-X14 -> -5.81 | AB14: =VLOOKUP(USG!E38,$P$3:$Q$41,2,FALSE)-VLOOKUP(USG!E38,$V$3:$W$41,2,FALSE) -> #N/A
B15: LOOP SOUR | C15: -5.65 | D15: -1.65 | E15: -1.65 | F15: -1.9 | G15: -1.9 | H15: -1.9 | I15: -1.65 | J15: -1.65 | K15: -1.65 | L15: -1.65 | M15: -1.65 | N15: -1.65 | P15: =EOMONTH(P14,1) -> 46721 | Q15: =BBG!E17 -> 76.12 | R15: =BBG!F17 -> 76.1 | S15: =EOMONTH(S14,1) -> 46752 | T15: =BBG!K17 -> 81.58 | U15: =BBG!L17 -> 81.25 | V15: =EOMONTH(V14,1) -> 46691 | W15: =BBG!E75 -> 75.82 | X15: =BBG!K75 -> 81.52 | Y15: =W15-X15 -> -5.7 | AB15: =VLOOKUP(USG!E39,$P$3:$Q$41,2,FALSE)-VLOOKUP(USG!E39,$V$3:$W$41,2,FALSE) -> #N/A
B16: POSEIDON | C16: -5.35 | D16: -1.35 | E16: -1.35 | F16: -1.6 | G16: -1.6 | H16: -1.6 | I16: -1.35 | J16: -1.35 | K16: -1.35 | L16: -1.35 | M16: -1.35 | N16: -1.35 | P16: =EOMONTH(P15,1) -> 46752 | Q16: =BBG!E18 -> 75.36 | R16: =BBG!F18 -> 75.44 | S16: =EOMONTH(S15,1) -> 46783 | T16: =BBG!K18 -> 80.81 | U16: =BBG!L18 -> 80.51 | V16: =EOMONTH(V15,1) -> 46721 | W16: =BBG!E76 -> 75.17 | X16: =BBG!K76 -> 80.72 | Y16: =W16-X16 -> -5.55 | AB16: =VLOOKUP(USG!E40,$P$3:$Q$41,2,FALSE)-VLOOKUP(USG!E40,$V$3:$W$41,2,FALSE) -> #N/A
B17: T-HORSE | C17: -4 | D17: 0 | E17: 0 | F17: -0.25 | G17: -0.25 | H17: -0.25 | I17: 0 | J17: 0 | K17: 0 | L17: 0 | M17: 0 | N17: 0 | P17: =EOMONTH(P16,1) -> 46783 | Q17: =BBG!E19 -> 74.79 | R17: =BBG!F19 -> 74.84 | S17: =EOMONTH(S16,1) -> 46812 | T17: =BBG!K19 -> 80.07 | U17: =BBG!L19 -> 79.82 | V17: =EOMONTH(V16,1) -> 46752 | W17: =BBG!E77 -> 74.47 | X17: =BBG!K77 -> 79.95 | Y17: =W17-X17 -> -5.48 | AB17: =VLOOKUP(USG!G41,$P$3:$Q$41,2,FALSE)-VLOOKUP(USG!G41,$V$3:$W$41,2,FALSE) -> #N/A
B18: SGC | C18: -6 | D18: -3 | E18: -3 | F18: -2.25 | G18: -2.25 | H18: -2.25 | I18: -1.5 | J18: -1.5 | K18: -1.5 | L18: -1.25 | M18: -1.25 | N18: -1.25 | P18: =EOMONTH(P17,1) -> 46812 | Q18: =BBG!E20 -> 74.19 | R18: =BBG!F20 -> 74.27 | S18: =EOMONTH(S17,1) -> 46843 | T18: =BBG!K20 -> 79.41 | U18: =BBG!L20 -> 79.22 | V18: =EOMONTH(V17,1) -> 46783 | W18: =BBG!E78 -> 73.89 | X18: =BBG!K78 -> 79.33 | Y18: =W18-X18 -> -5.44 | AB18: =VLOOKUP(USG!G42,$P$3:$Q$41,2,FALSE)-VLOOKUP(USG!G42,$V$3:$W$41,2,FALSE) -> #N/A
B19: ROCKIES AND MIDCONTINENT PIPELINE ASSESSMENTS | P19: =EOMONTH(P18,1) -> 46843 | Q19: =BBG!E21 -> 73.65 | R19: =BBG!F21 -> 73.76 | S19: =EOMONTH(S18,1) -> 46873 | T19: =BBG!K21 -> 78.82 | U19: =BBG!L21 -> 78.69 | V19: =EOMONTH(V18,1) -> 46812 | W19: =BBG!E79 -> 73.41 | X19: =BBG!K79 -> 78.73 | Y19: =W19-X19 -> -5.32 | AB19: =VLOOKUP(USG!G43,$P$3:$Q$41,2,FALSE)-VLOOKUP(USG!G43,$V$3:$W$41,2,FALSE) -> #N/A
B20: GRADE | C20: 46296 | D20: 46327 | E20: 46357 | F20: 46388 | G20: 46419 | H20: 46447 | I20: 46478 | J20: 46508 | K20: 46539 | L20: 46569 | M20: 46600 | N20: 46631 | P20: =EOMONTH(P19,1) -> 46873 | Q20: =BBG!E22 -> 73.15 | R20: =BBG!F22 -> 73.29 | S20: =EOMONTH(S19,1) -> 46904 | T20: =BBG!K22 -> 78.29 | U20: =BBG!L22 -> 78.22 | V20: =EOMONTH(V19,1) -> 46843 | W20: =BBG!E80 -> 72.87 | X20: =BBG!K80 -> 78.2 | Y20: =W20-X20 -> -5.33 | AB20: =VLOOKUP(USG!G44,$P$3:$Q$41,2,FALSE)-VLOOKUP(USG!G44,$V$3:$W$41,2,FALSE) -> #N/A
B21: BLS CUSHING | C21: 1 | D21: 1 | E21: 1 | F21: 1 | G21: 1 | H21: 1 | I21: 1 | J21: 1 | K21: 1 | L21: 1 | M21: 1 | N21: 1 | P21: =EOMONTH(P20,1) -> 46904 | Q21: =BBG!E23 -> 72.69 | R21: =BBG!F23 -> 72.87 | S21: =EOMONTH(S20,1) -> 46934 | T21: =BBG!K23 -> 77.75 | U21: =BBG!L23 -> 77.78 | V21: =EOMONTH(V20,1) -> 46873 | W21: =BBG!E81 -> 72.42 | X21: =BBG!K81 -> 77.72 | Y21: =W21-X21 -> -5.3 | AB21: =VLOOKUP(USG!#REF!,$P$3:$Q$41,2,FALSE)-VLOOKUP(USG!#REF!,$V$3:$W$41,2,FALSE) -> #REF!
B22: NIO CUSHING | C22: 1.15 | D22: 1.15 | E22: 1.15 | F22: 1.15 | G22: 1.15 | H22: 1.15 | I22: 1.15 | J22: 1.15 | K22: 1.15 | L22: 1.15 | M22: 1.15 | N22: 1.15 | P22: =EOMONTH(P21,1) -> 46934 | Q22: =BBG!E24 -> 72.15 | R22: =BBG!F24 -> 72.46 | S22: =EOMONTH(S21,1) -> 46965 | T22: =BBG!K24 -> 77.31 | U22: =BBG!L24 -> 77.34 | V22: =EOMONTH(V21,1) -> 46904 | W22: =BBG!E82 -> 71.99 | X22: =BBG!K82 -> 77.24 | Y22: =W22-X22 -> -5.25 | AB22: =VLOOKUP(#REF!,$P$3:$Q$41,2,FALSE)-VLOOKUP(#REF!,$V$3:$W$41,2,FALSE) -> #REF!
B23: SHL LIGHT | C23: 0.3 | D23: 0.3 | E23: 0.3 | F23: 0.3 | G23: 0.3 | H23: 0.3 | I23: 0.3 | J23: 0.3 | K23: 0.3 | L23: 0.3 | M23: 0.3 | N23: 0.3 | P23: =EOMONTH(P22,1) -> 46965 | Q23: =BBG!E25 -> 71.79 | R23: =BBG!F25 -> 72.03 | S23: =EOMONTH(S22,1) -> 46996 | T23: =BBG!K25 -> 76.83 | U23: =BBG!L25 -> 76.89 | V23: =EOMONTH(V22,1) -> 46934 | W23: =BBG!E83 -> 71.49 | X23: =BBG!K83 -> 76.76 | Y23: =W23-X23 -> -5.27 | AB23: =VLOOKUP(#REF!,$P$3:$Q$41,2,FALSE)-VLOOKUP(#REF!,$V$3:$W$41,2,FALSE) -> #REF!
B24: SHL CRUDE | C24: 1.35 | D24: 1.35 | E24: 1.35 | F24: 1.35 | G24: 1.35 | H24: 1.35 | I24: 1.35 | J24: 1.35 | K24: 1.35 | L24: 1.35 | M24: 1.35 | N24: 1.35 | P24: =EOMONTH(P23,1) -> 46996 | Q24: =BBG!E26 -> 71.33 | R24: =BBG!F26 -> 71.62 | S24: =EOMONTH(S23,1) -> 47026 | T24: =BBG!K26 -> 76.36 | U24: =BBG!L26 -> 76.46 | V24: =EOMONTH(V23,1) -> 46965 | W24: =BBG!E84 -> 71.06 | X24: =BBG!K84 -> 76.29 | Y24: =W24-X24 -> -5.23 | AB24: =VLOOKUP(USG!#REF!,$P$3:$Q$41,2,FALSE)-VLOOKUP(USG!#REF!,$V$3:$W$41,2,FALSE) -> #REF!
B25: WHITECLIFFS | C25: 0.3 | D25: 0.3 | E25: 0.3 | F25: 0.3 | G25: 0.3 | H25: 0.3 | I25: 0.3 | J25: 0.3 | K25: 0.3 | L25: 0.3 | M25: 0.3 | N25: 0.3 | P25: =EOMONTH(P24,1) -> 47026 | Q25: =BBG!E27 -> 70.92 | R25: =BBG!F27 -> 71.24 | S25: =EOMONTH(S24,1) -> 47057 | T25: =BBG!K27 -> 75.89 | U25: =BBG!L27 -> 76.03 | V25: =EOMONTH(V24,1) -> 46996 | W25: =BBG!E85 -> 70.67 | X25: =BBG!K85 -> 75.82 | Y25: =W25-X25 -> -5.15 | AB25: =VLOOKUP(USG!E24,$P$3:$Q$41,2,FALSE)-VLOOKUP(USG!E24,$V$3:$W$41,2,FALSE) -> #N/A
B26: GRAND MESA LT | C26: 0.3 | D26: 0.3 | E26: 0.3 | F26: 0.3 | G26: 0.3 | H26: 0.3 | I26: 0.3 | J26: 0.3 | K26: 0.3 | L26: 0.3 | M26: 0.3 | N26: 0.3 | P26: =EOMONTH(P25,1) -> 47057 | Q26: =BBG!E28 -> 70.53 | R26: =BBG!F28 -> 70.86 | S26: =EOMONTH(S25,1) -> 47087 | T26: =BBG!K28 -> 75.45 | U26: =BBG!L28 -> 75.63 | V26: =EOMONTH(V25,1) -> 47026 | W26: =BBG!E86 -> 70.27 | X26: =BBG!K86 -> 75.38 | Y26: =W26-X26 -> -5.11 | AB26: =VLOOKUP(#REF!,$P$3:$Q$41,2,FALSE)-VLOOKUP(#REF!,$V$3:$W$41,2,FALSE) -> #REF!
B27: BAKKEN US GULF | C27: 1.65 | D27: 1.65 | E27: 1.65 | F27: 1.65 | G27: 1.65 | H27: 1.65 | I27: 1.65 | J27: 1.65 | K27: 1.65 | L27: 1.65 | M27: 1.65 | N27: 1.65 | P27: =EOMONTH(P26,1) -> 47087 | Q27: =BBG!E29 -> 70.18 | R27: =BBG!F29 -> 70.54 | S27: =EOMONTH(S26,1) -> 47118 | T27: =BBG!K29 -> 75.08 | U27: =BBG!L29 -> 75.29 | V27: =EOMONTH(V26,1) -> 47057 | W27: =BBG!E87 -> 69.94 | X27: =BBG!K87 -> 75.02 | Y27: =W27-X27 -> -5.08 | AB27: =VLOOKUP(#REF!,$P$3:$Q$41,2,FALSE)-VLOOKUP(#REF!,$V$3:$W$41,2,FALSE) -> #REF!
B28: CANADIAN PIPELINE ASSESSMENTS | P28: =EOMONTH(P27,1) -> 47118 | Q28: =BBG!E30 -> 69.74 | R28: =BBG!F30 -> 70.24 | S28: =EOMONTH(S27,1) -> 47149 | T28: =BBG!K30 -> 74.68 | U28: =BBG!L30 -> 74.94 | V28: =EOMONTH(V27,1) -> 47087 | W28: =BBG!E88 -> 69.6 | X28: =BBG!K88 -> 74.63 | Y28: =W28-X28 -> -5.03 | AB28: =VLOOKUP(USG!D1,$P$3:$Q$41,2,FALSE)-VLOOKUP(USG!D1,$V$3:$W$41,2,FALSE) -> #N/A
B29: GRADE | C29: 46296 | D29: 46327 | E29: 46357 | F29: 46388 | G29: 46419 | H29: 46447 | I29: 46478 | J29: 46508 | K29: 46539 | L29: 46569 | M29: 46600 | N29: 46631 | P29: =EOMONTH(P28,1) -> 47149 | Q29: =BBG!E31 -> 69.47 | R29: =BBG!F31 -> 69.91 | S29: =EOMONTH(S28,1) -> 47177 | T29: =BBG!K31 -> 74.32 | U29: =BBG!L31 -> 74.61 | V29: =EOMONTH(V28,1) -> 47118 | W29: =BBG!E89 -> 69.22 | X29: =BBG!K89 -> 74.26 | Y29: =W29-X29 -> -5.04 | AB29: =VLOOKUP(USG!D2,$P$3:$Q$41,2,FALSE)-VLOOKUP(USG!D2,$V$3:$W$41,2,FALSE) -> #N/A
B30: WCS CUSHING | C30: -15.25 | D30: -13.1 | E30: -12.55 | F30: -11.85 | G30: -11.45 | H30: -11.05 | I30: -10.6 | J30: -10.15 | K30: -9.7 | L30: -9.8 | M30: -9.9 | N30: -10 | P30: =EOMONTH(P29,1) -> 47177 | Q30: =BBG!E32 -> 69.1 | R30: =BBG!F32 -> 69.55 | S30: =EOMONTH(S29,1) -> 47208 | T30: =BBG!K32 -> 74.04 | U30: =BBG!L32 -> 74.35 | V30: =EOMONTH(V29,1) -> 47149 | W30: =BBG!E90 -> 68.86 | X30: =BBG!K90 -> 74 | Y30: =W30-X30 -> -5.14 | AB30: =VLOOKUP(USG!D4,$P$3:$Q$41,2,FALSE)-VLOOKUP(USG!D4,$V$3:$W$41,2,FALSE) -> #N/A
B31: CLK CUSHING | C31: -15.25 | D31: -13.1 | E31: -12.55 | F31: -11.85 | G31: -11.45 | H31: -11.05 | I31: -10.6 | J31: -10.15 | K31: -9.7 | L31: -9.8 | M31: -9.9 | N31: -10 | P31: =EOMONTH(P30,1) -> 47208 | Q31: =BBG!E33 -> 68.74 | R31: =BBG!F33 -> 69.22 | S31: =EOMONTH(S30,1) -> 47238 | T31: =BBG!K33 -> 73.76 | U31: =BBG!L33 -> 74.09 | V31: =EOMONTH(V30,1) -> 47177 | W31: =BBG!E91 -> 68.52 | X31: =BBG!K91 -> 73.72 | Y31: =W31-X31 -> -5.2 | AB31: =VLOOKUP(USG!D3,$P$3:$Q$41,2,FALSE)-VLOOKUP(USG!D3,$V$3:$W$41,2,FALSE) -> #N/A
B32: AWB CUSHING | C32: -15.5 | D32: -13.35 | E32: -12.8 | F32: -12.1 | G32: -11.7 | H32: -11.3 | I32: -10.85 | J32: -10.4 | K32: -9.95 | L32: -10.05 | M32: -10.15 | N32: -10.25 | P32: =EOMONTH(P31,1) -> 47238 | Q32: =BBG!E34 -> 68.4 | R32: =BBG!F34 -> 68.9 | S32: =EOMONTH(S31,1) -> 47269 | T32: =BBG!K34 -> 73.47 | U32: =BBG!L34 -> 73.82 | V32: =EOMONTH(V31,1) -> 47208 | W32: =BBG!E92 -> 68.19 | X32: =BBG!K92 -> 73.43 | Y32: =W32-X32 -> -5.24 | AB32: =VLOOKUP(USG!D5,$P$3:$Q$41,2,FALSE)-VLOOKUP(USG!D5,$V$3:$W$41,2,FALSE) -> #N/A
B33: WCS US GULF | C33: -14.25 | D33: -12 | E33: -11.45 | F33: -11.05 | G33: -10.65 | H33: -10.25 | I33: -9.8 | J33: -9.35 | K33: -8.9 | L33: -9 | M33: -9.1 | N33: -9.2 | P33: =EOMONTH(P32,1) -> 47269 | Q33: =BBG!E35 -> 68.1 | R33: =BBG!F35 -> 68.6 | S33: =EOMONTH(S32,1) -> 47299 | T33: =BBG!K35 -> 73.17 | U33: =BBG!L35 -> 73.54 | V33: =EOMONTH(V32,1) -> 47238 | W33: =BBG!E93 -> 67.88 | X33: =BBG!K93 -> 73.15 | Y33: =W33-X33 -> -5.27 | AB33: =VLOOKUP(USG!D6,$P$3:$Q$41,2,FALSE)-VLOOKUP(USG!D6,$V$3:$W$41,2,FALSE) -> #N/A
B34: CLK US GULF | C34: -14.25 | D34: -12 | E34: -11.45 | F34: -11.05 | G34: -10.65 | H34: -10.25 | I34: -9.8 | J34: -9.35 | K34: -8.9 | L34: -9 | M34: -9.1 | N34: -9.2 | P34: =EOMONTH(P33,1) -> 47299 | Q34: =BBG!E36 -> 67.65 | R34: =BBG!F36 -> 68.27 | S34: =EOMONTH(S33,1) -> 47330 | T34: =BBG!K36 -> 72.85 | U34: =BBG!L36 -> 73.24 | V34: =EOMONTH(V33,1) -> 47269 | W34: =BBG!E94 -> 67.55 | X34: =BBG!K94 -> 72.84 | Y34: =W34-X34 -> -5.29 | AB34: =VLOOKUP(USG!D7,$P$3:$Q$41,2,FALSE)-VLOOKUP(USG!D7,$V$3:$W$41,2,FALSE) -> #N/A
B35: AWB US GULF | C35: -15.45 | D35: -13.2 | E35: -12.65 | F35: -12.25 | G35: -11.85 | H35: -11.45 | I35: -11 | J35: -10.55 | K35: -10.1 | L35: -10.2 | M35: -10.3 | N35: -10.4 | P35: =EOMONTH(P34,1) -> 47330 | Q35: =BBG!E37 -> 67.41 | R35: =BBG!F37 -> 67.91 | S35: =EOMONTH(S34,1) -> 47361 | T35: =BBG!K37 -> 72.57 | U35: =BBG!L37 -> 72.97 | V35: =EOMONTH(V34,1) -> 47299 | W35: =BBG!E95 -> 67.18 | X35: =BBG!K95 -> 72.56 | Y35: =W35-X35 -> -5.38 | AB35: =VLOOKUP(USG!D8,$P$3:$Q$41,2,FALSE)-VLOOKUP(USG!D8,$V$3:$W$41,2,FALSE) -> #N/A
B36: CLK @ PATOKA | C36: -16.25 | D36: -14.1 | E36: -13.55 | F36: -12.85 | G36: -12.45 | H36: -12.05 | I36: -11.6 | J36: -11.15 | K36: -10.7 | L36: -10.8 | M36: -10.9 | N36: -11 | P36: =EOMONTH(P35,1) -> 47361 | Q36: =BBG!E38 -> 67.1 | R36: =BBG!F38 -> 67.61 | S36: =EOMONTH(S35,1) -> 47391 | T36: =BBG!K38 -> 72.28 | U36: =BBG!L38 -> 72.69 | V36: =EOMONTH(V35,1) -> 47330 | W36: =BBG!E96 -> 66.88 | X36: =BBG!K96 -> 72.27 | Y36: =W36-X36 -> -5.39 | AB36: =VLOOKUP(USG!D10,$P$3:$Q$41,2,FALSE)-VLOOKUP(USG!D10,$V$3:$W$41,2,FALSE) -> #N/A
B37: PHYSICAL FORWARD PIPELINE ASSESSMENTS | P37: =EOMONTH(P36,1) -> 47391 | Q37: =BBG!E39 -> 66.78 | R37: =BBG!F39 -> 67.3 | S37: =EOMONTH(S36,1) -> 47422 | T37: =BBG!K39 -> 72 | U37: =BBG!L39 -> 72.42 | V37: =EOMONTH(V36,1) -> 47361 | W37: =BBG!E97 -> 66.56 | X37: =BBG!K97 -> 71.99 | Y37: =W37-X37 -> -5.43 | AB37: =VLOOKUP(USG!D9,$P$3:$Q$41,2,FALSE)-VLOOKUP(USG!D9,$V$3:$W$41,2,FALSE) -> #N/A
B38: GRADE | C38: 4Q26 | D38: 1Q27 | E38: 2Q27 | F38: 3Q27 | G38: 4Q27 | H38: 1Q28 | I38: 1H27 | J38: 2H27 | K38: 1H28 | L38: Cal 27 | M38: Cal 28 | N38: Cal 29 | P38: =EOMONTH(P37,1) -> 47422 | Q38: =BBG!E40 -> 66.47 | R38: =BBG!F40 -> 67 | S38: =EOMONTH(S37,1) -> 47452 | T38: =BBG!K40 -> 71.69 | U38: =BBG!L40 -> 72.12 | V38: =EOMONTH(V37,1) -> 47391 | W38: =BBG!E98 -> 66.27 | X38: =BBG!K98 -> 71.68 | Y38: =W38-X38 -> -5.41 | AB38: =VLOOKUP(USG!D11,$P$3:$Q$41,2,FALSE)-VLOOKUP(USG!D11,$V$3:$W$41,2,FALSE) -> #N/A
B39: MIDSWT | C39: -0.483 | D39: 0.833 | E39: 1.2 | F39: 1.25 | G39: 1.25 | H39: 1.28 | I39: 1.017 | J39: 1.25 | K39: 1.28 | L39: 1.133 | M39: 1.3 | N39: 1.33 | P39: =EOMONTH(P38,1) -> 47452 | Q39: =BBG!E41 -> 66.18 | R39: =BBG!F41 -> 66.72 | S39: =EOMONTH(S38,1) -> 47483 | T39: =BBG!K41 -> 71.41 | U39: =BBG!L41 -> 71.84 | V39: =EOMONTH(V38,1) -> 47422 | W39: =BBG!E99 -> 65.97 | X39: =BBG!K99 -> 71.4 | Y39: =W39-X39 -> -5.43 | AB39: =VLOOKUP(USG!D12,$P$3:$Q$41,2,FALSE)-VLOOKUP(USG!D12,$V$3:$W$41,2,FALSE) -> #N/A
B40: MEH | C40: 1.033 | D40: 1.383 | E40: 1.8 | F40: 1.85 | G40: 1.9 | H40: 1.95 | I40: 1.592 | J40: 1.875 | K40: 1.95 | L40: 1.733 | M40: 1.98 | N40: 2.03 | P40: =EOMONTH(P39,1) -> 47483 | Q40: =BBG!E42 -> 65.75 | R40: =BBG!F42 -> 66.42 | S40: =EOMONTH(S39,1) -> 47514 | T40: =BBG!K42 -> 71.1 | U40: =BBG!L42 -> 71.54 | V40: =EOMONTH(V39,1) -> 47452 | W40: =BBG!E100 -> 65.62 | X40: =BBG!K100 -> 71.09 | Y40: =W40-X40 -> -5.47 | AB40: =VLOOKUP(USG!D13,$P$3:$Q$41,2,FALSE)-VLOOKUP(USG!D13,$V$3:$W$41,2,FALSE) -> #N/A
...

Sheet USG
A1: 46293 | C1: CFD WEEKS | E1: =Sheet1!S3 -> 46387 | F1: =EOMONTH(E1,1) -> 46418 | G1: =EOMONTH(F1,1) -> 46446 | H1: =EOMONTH(G1,1) -> 46477 | I1: vs. Cal Dtd | J1: 1-Wkr | K1: 2-Wkr | L1: 3-Wkr | N1: WTI arrivals (MEH FLAT, Platts pxg)
A2: =A1+7 -> 46300 | D2: Week | F2: =-(Sheet1!T4-Sheet1!T3) -> 3.87 | G2: =Sheet1!T4-Sheet1!T5 -> 3.08 | H2: =Sheet1!U4-Sheet1!U5 -> 2.24 | N2: =Q3 -> CFD Week | O2: =AB3 -> Curve Value | Q2: 1 | R2: =TEXT(A1,"mmmdd")&"-"&TEXT(WORKDAY(A1,4),"mmmdd") -> Sep28-Oct02
A3: =A2+7 -> 46307 | D3: Balmo | Q3: CFD Week | R3: vs. ICE Brent | S3: Diff | U3: Delivery Window | X3: MEH/Brent | Y3: FOB Premium | Z3: Cash Roll | AA3: Freight+Cost | AB3: Curve Value | AH3: USGC Load Window | AP3: Load WTI | AQ3: Delivery Brent
A4: =A3+7 -> 46314 | C4: 2670 | D4: =TEXT(A1,"mmmdd")&"-"&TEXT(WORKDAY(A1,4),"mmmdd") -> Sep28-Oct02 | E4: =C4/100 -> 26.7 | F4: =(E4)+F$2 -> 30.57 | G4: =(F4)+G$2 -> 33.65 | H4: =(G4)+H$2 -> 35.89 | J4: =C4-C5 -> 500 | K4: =C4-C6 -> 1210 | L4: =J4+J3+J5 -> 1210 | N4: =D4 -> Sep28-Oct02 | O4: =AB4 -> #N/A | P4: =VLOOKUP(Q4,USG!$D$1:$H$19,MATCH(USG!R4,USG!$D$1:$H$1,0),FALSE) -> 26.7 | Q4: =TEXT(A1,"mmmdd")&"-"&TEXT(WORKDAY(A1,4),"mmmdd") -> Sep28-Oct02 | R4: =EOMONTH(V4,2) -> 46387 | S4: =P4 -> 26.7 | U4: =A1 -> 46293 | V4: =WORKDAY(U4,4) -> 46297 | X4: =VLOOKUP(AP$4,Sheet1!$P$3:$Q$41,2,FALSE)-VLOOKUP($AQ4,Sheet1!$S$3:$T$41,2,FALSE)+HLOOKUP(AP4,$D$25:$H$26,2,FALSE) -> #N/A | Y4: 0 | Z4: =IF(EOMONTH(AI4,0)<AP4,USG!$D$29,0) -> 3 | AA4: =IFERROR(VLOOKUP(AG4,Freight!$A$3:$F$22,MATCH("TD25",Freight!$A$3:$F$3,0),FALSE),VLOOKUP(EOMONTH(AG4,1),Freight!$A$3:$F$22,MATCH("TD25",Freight!$A$3:$F$3,0),FALSE))+$AB$28 -> #VALUE! | AB4: =SUM(X4:AA4)-S4 -> #N/A | AG4: =IF(AH4<TODAY()+10,"Balmo",EOMONTH(AH4,0)) -> Balmo | AH4: =U4-17 -> 46276 | AI4: =V4-17 -> 46280 | AO4: =EOMONTH(AH4,0) -> 46295 | AP4: =IF(AI4>USG!$E$25,EOMONTH(AI4,0),USG!$E$25) -> 46356 | AQ4: =EOMONTH(U4,2) -> 46356
A5: =A4+7 -> 46321 | C5: 2170 | D5: =TEXT(A2,"mmmdd")&"-"&TEXT(WORKDAY(A2,4),"mmmdd") -> Oct05-Oct09 | E5: =C5/100 -> 21.7 | F5: =(E5)+F$2 -> 25.57 | G5: =(F5)+G$2 -> 28.65 | H5: =(G5)+H$2 -> 30.89 | J5: =C5-C6 -> 710 | K5: =J5+J6 -> 1310 | L5: =J5+J6+J7 -> 1585 | N5: =D5 -> Oct05-Oct09 | O5: =AB5 -> #VALUE! | P5: =VLOOKUP(Q5,USG!$D$1:$H$19,MATCH(USG!R5,USG!$D$1:$H$1,0),FALSE) -> 21.7 | Q5: =TEXT(A2,"mmmdd")&"-"&TEXT(WORKDAY(A2,4),"mmmdd") -> Oct05-Oct09 | R5: =EOMONTH(V5,2) -> 46387 | S5: =P5 -> 21.7 | U5: =WORKDAY(V4,1) -> 46300 | V5: =WORKDAY(U5,4) -> 46304 | X5: =VLOOKUP(AP$4,Sheet1!$P$3:$Q$41,2,FALSE)-VLOOKUP($AQ5,Sheet1!$S$3:$T$41,2,FALSE)+HLOOKUP(AP5,$D$25:$H$26,2,FALSE) -> -8.1 | Y5: 0 | Z5: =IF(EOMONTH(AI5,0)<AP5,USG!$D$29,0) -> 3 | AA5: =IFERROR(VLOOKUP(AG5,Freight!$A$3:$F$22,MATCH("TD25",Freight!$A$3:$F$3,0),FALSE),VLOOKUP(EOMONTH(AG5,1),Freight!$A$3:$F$22,MATCH("TD25",Freight!$A$3:$F$3,0),FALSE))+$AB$28 -> #VALUE! | AB5: =SUM(X5:AA5)-S5 -> #VALUE! | AG5: =IF(AH5<TODAY()+10,"Balmo",EOMONTH(AH5,0)) -> Balmo | AH5: =U5-17 -> 46283 | AI5: =V5-17 -> 46287 | AO5: =EOMONTH(AH5,0) -> 46295 | AP5: =IF(AI5>USG!$E$25,EOMONTH(AI5,0),USG!$E$25) -> 46356 | AQ5: =EOMONTH(U5,2) -> 46387
A6: =A5+7 -> 46328 | C6: 1460 | D6: =TEXT(A3,"mmmdd")&"-"&TEXT(WORKDAY(A3,4),"mmmdd") -> Oct12-Oct16 | E6: =C6/100 -> 14.6 | F6: =(E6)+F$2 -> 18.47 | G6: =(F6)+G$2 -> 21.55 | H6: =(G6)+H$2 -> 23.79 | J6: =C6-C7 -> 600 | K6: =J6+J7 -> 875 | L6: =J6+J7+J8 -> 1040 | N6: =D6 -> Oct12-Oct16 | O6: =AB6 -> #VALUE! | P6: =VLOOKUP(Q6,USG!$D$1:$H$19,MATCH(USG!R6,USG!$D$1:$H$1,0),FALSE) -> 14.6 | Q6: =TEXT(A3,"mmmdd")&"-"&TEXT(WORKDAY(A3,4),"mmmdd") -> Oct12-Oct16 | R6: =EOMONTH(V6,2) -> 46387 | S6: =P6 -> 14.6 | U6: =WORKDAY(V5,1) -> 46307 | V6: =WORKDAY(U6,4) -> 46311 | X6: =VLOOKUP(AP$4,Sheet1!$P$3:$Q$41,2,FALSE)-VLOOKUP($AQ6,Sheet1!$S$3:$T$41,2,FALSE)+HLOOKUP(AP6,$D$25:$H$26,2,FALSE) -> -8.1 | Y6: 0 | Z6: =IF(EOMONTH(AI6,0)<AP6,USG!$D$29,0) -> 3 | AA6: =IFERROR(VLOOKUP(AG6,Freight!$A$3:$F$22,MATCH("TD25",Freight!$A$3:$F$3,0),FALSE),VLOOKUP(EOMONTH(AG6,1),Freight!$A$3:$F$22,MATCH("TD25",Freight!$A$3:$F$3,0),FALSE))+$AB$28 -> #VALUE! | AB6: =SUM(X6:AA6)-S6 -> #VALUE! | AG6: =IF(AH6<TODAY()+10,"Balmo",EOMONTH(AH6,0)) -> Balmo | AH6: =U6-17 -> 46290 | AI6: =V6-17 -> 46294 | AO6: =EOMONTH(AH6,0) -> 46295 | AP6: =IF(AI6>USG!$E$25,EOMONTH(AI6,0),USG!$E$25) -> 46356 | AQ6: =EOMONTH(U6,2) -> 46387
C7: 860 | D7: =TEXT(A4,"mmmdd")&"-"&TEXT(WORKDAY(A4,4),"mmmdd") -> Oct19-Oct23 | E7: =C7/100 -> 8.6 | F7: =(E7)+F$2 -> 12.47 | G7: =(F7)+G$2 -> 15.55 | H7: =(G7)+H$2 -> 17.79 | J7: =C7-C8 -> 275 | K7: =J7+J8 -> 440 | L7: =J7+J8+J10 -> 630 | N7: =D7 -> Oct19-Oct23 | O7: =AB7 -> #VALUE! | P7: =VLOOKUP(Q7,USG!$D$1:$H$19,MATCH(USG!R7,USG!$D$1:$H$1,0),FALSE) -> 8.6 | Q7: =TEXT(A4,"mmmdd")&"-"&TEXT(WORKDAY(A4,4),"mmmdd") -> Oct19-Oct23 | R7: =EOMONTH(V7,2) -> 46387 | S7: =P7 -> 8.6 | U7: =WORKDAY(V6,1) -> 46314 | V7: =WORKDAY(U7,4) -> 46318 | X7: =VLOOKUP(AP$4,Sheet1!$P$3:$Q$41,2,FALSE)-VLOOKUP($AQ7,Sheet1!$S$3:$T$41,2,FALSE)+HLOOKUP(AP7,$D$25:$H$26,2,FALSE) -> -8.1 | Y7: 0 | Z7: =IF(EOMONTH(AI7,0)<AP7,USG!$D$29,0) -> 3 | AA7: =IFERROR(VLOOKUP(AG7,Freight!$A$3:$F$22,MATCH("TD25",Freight!$A$3:$F$3,0),FALSE),VLOOKUP(EOMONTH(AG7,1),Freight!$A$3:$F$22,MATCH("TD25",Freight!$A$3:$F$3,0),FALSE))+$AB$28 -> #VALUE! | AB7: =SUM(X7:AA7)-S7 -> #VALUE! | AG7: =IF(AH7<TODAY()+10,"Balmo",EOMONTH(AH7,0)) -> Balmo | AH7: =U7-17 -> 46297 | AI7: =V7-17 -> 46301 | AO7: =EOMONTH(AH7,0) -> 46326 | AP7: =IF(AI7>USG!$E$25,EOMONTH(AI7,0),USG!$E$25) -> 46356 | AQ7: =EOMONTH(U7,2) -> 46387
A8: =A9+7 -> 46342 | C8: 585 | D8: =TEXT(A5,"mmmdd")&"-"&TEXT(WORKDAY(A5,4),"mmmdd") -> Oct26-Oct30 | E8: =C8/100 -> 5.85 | F8: =(E8)+F$2 -> 9.72 | G8: =(F8)+G$2 -> 12.8 | H8: =(G8)+H$2 -> 15.04 | J8: =C8-C10 -> 165 | K8: =C8-C11 -> 355 | L8: =J8+J7+J10 -> 630 | N8: =D8 -> Oct26-Oct30 | O8: =AB8 -> #VALUE! | P8: =VLOOKUP(Q8,USG!$D$1:$H$19,MATCH(USG!R8,USG!$D$1:$H$1,0),FALSE) -> 5.85 | Q8: =TEXT(A5,"mmmdd")&"-"&TEXT(WORKDAY(A5,4),"mmmdd") -> Oct26-Oct30 | R8: =EOMONTH(V8,2) -> 46387 | S8: =P8 -> 5.85 | U8: =WORKDAY(V7,1) -> 46321 | V8: =WORKDAY(U8,4) -> 46325 | X8: =VLOOKUP(AP$4,Sheet1!$P$3:$Q$41,2,FALSE)-VLOOKUP($AQ8,Sheet1!$S$3:$T$41,2,FALSE)+HLOOKUP(AP8,$D$25:$H$26,2,FALSE) -> -8.1 | Y8: 0 | Z8: =IF(EOMONTH(AI8,0)<AP8,USG!$D$29,0) -> 3 | AA8: =IFERROR(VLOOKUP(AG8,Freight!$A$3:$F$22,MATCH("TD25",Freight!$A$3:$F$3,0),FALSE),VLOOKUP(EOMONTH(AG8,1),Freight!$A$3:$F$22,MATCH("TD25",Freight!$A$3:$F$3,0),FALSE))+$AB$28 -> #VALUE! | AB8: =SUM(X8:AA8)-S8 -> #VALUE! | AG8: =IF(AH8<TODAY()+10,"Balmo",EOMONTH(AH8,0)) -> Balmo | AH8: =U8-17 -> 46304 | AI8: =V8-17 -> 46308 | AO8: =EOMONTH(AH8,0) -> 46326 | AP8: =IF(AI8>USG!$E$25,EOMONTH(AI8,0),USG!$E$25) -> 46356 | AQ8: =EOMONTH(U8,2) -> 46387
A9: =A6+7 -> 46335 | D9: Full Month | E9: =AVERAGE(E4:E8) -> 15.49 | F9: =AVERAGE(F4:F8) -> 19.36 | G9: =AVERAGE(G4:G8) -> 22.44 | H9: =AVERAGE(H4:H8) -> 24.68 | N9: =D9 -> Full Month | O9: =AVERAGE(O4:O7) -> #N/A
A10: =A8+7 -> 46349 | C10: 420 | D10: =TEXT(A6,"mmmdd")&"-"&TEXT(WORKDAY(A6,4),"mmmdd") -> Nov02-Nov06 | E10: =C10/100 -> 4.2 | F10: =(E10)+F$2 -> 8.07 | G10: =(F10)+G$2 -> 11.15 | H10: =(G10)+H$2 -> 13.39 | J10: =C10-C11 -> 190 | K10: =C10-C12 -> 375 | L10: =J10+J9+J11 -> 375 | N10: =D10 -> Nov02-Nov06 | O10: =AB10 -> 7.94865 | P10: =VLOOKUP(Q10,USG!$D$1:$H$19,MATCH(USG!R10,USG!$D$1:$H$1,0),FALSE) -> 8.07 | Q10: =TEXT(A6,"mmmdd")&"-"&TEXT(WORKDAY(A6,4),"mmmdd") -> Nov02-Nov06 | R10: =EOMONTH(V10,2) -> 46418 | S10: =P10 -> 8.07 | U10: =WORKDAY(V8,1) -> 46328 | V10: =WORKDAY(U10,4) -> 46332 | X10: =VLOOKUP(AP$4,Sheet1!$P$3:$Q$41,2,FALSE)-VLOOKUP($AQ10,Sheet1!$S$3:$T$41,2,FALSE)+HLOOKUP(AP10,$D$25:$H$26,2,FALSE) -> -4.23 | Z10: =IF(EOMONTH(AI10,0)<AP10,USG!$D$29,0) -> 3 | AA10: =IFERROR(VLOOKUP(AG10,Freight!$A$3:$F$22,MATCH("TD25",Freight!$A$3:$F$3,0),FALSE),VLOOKUP(EOMONTH(AG10,1),Freight!$A$3:$F$22,MATCH("TD25",Freight!$A$3:$F$3,0),FALSE))+$AB$28 -> 17.24865 | AB10: =SUM(X10:AA10)-S10 -> 7.94865 | AG10: =IF(AH10<TODAY()+10,"Balmo",EOMONTH(AH10,0)) -> 46326 | AH10: =U10-17 -> 46311 | AI10: =V10-17 -> 46315 | AO10: =EOMONTH(AH10,0) -> 46326 | AP10: =IF(AI10>USG!$E$25,EOMONTH(AI10,0),USG!$E$25) -> 46356 | AQ10: =EOMONTH(U10,2) -> 46418
A11: =A10+7 -> 46356 | C11: 230 | D11: =TEXT(A9,"mmmdd")&"-"&TEXT(WORKDAY(A9,4),"mmmdd") -> Nov09-Nov13 | E11: =C11/100 -> 2.3 | F11: =(E11)+F$2 -> 6.17 | G11: =(F11)+G$2 -> 9.25 | H11: =(G11)+H$2 -> 11.49 | J11: =C11-C12 -> 185 | K11: =C11-C13 -> 285 | L11: =J11+J8+J12 -> 450 | N11: =D11 -> Nov09-Nov13 | O11: =AB11 -> 9.84865 | P11: =VLOOKUP(Q11,USG!$D$1:$H$19,MATCH(USG!R11,USG!$D$1:$H$1,0),FALSE) -> 6.17 | Q11: =TEXT(A9,"mmmdd")&"-"&TEXT(WORKDAY(A9,4),"mmmdd") -> Nov09-Nov13 | R11: =EOMONTH(V11,2) -> 46418 | S11: =P11 -> 6.17 | U11: =WORKDAY(V10,1) -> 46335 | V11: =WORKDAY(U11,4) -> 46339 | X11: =VLOOKUP(AP$4,Sheet1!$P$3:$Q$41,2,FALSE)-VLOOKUP($AQ11,Sheet1!$S$3:$T$41,2,FALSE)+HLOOKUP(AP11,$D$25:$H$26,2,FALSE) -> -4.23 | Z11: =IF(EOMONTH(AI11,0)<AP11,USG!$D$29,0) -> 3 | AA11: =IFERROR(VLOOKUP(AG11,Freight!$A$3:$F$22,MATCH("TD25",Freight!$A$3:$F$3,0),FALSE),VLOOKUP(EOMONTH(AG11,1),Freight!$A$3:$F$22,MATCH("TD25",Freight!$A$3:$F$3,0),FALSE))+$AB$28 -> 17.24865 | AB11: =SUM(X11:AA11)-S11 -> 9.84865 | AG11: =IF(AH11<TODAY()+10,"Balmo",EOMONTH(AH11,0)) -> 46326 | AH11: =U11-17 -> 46318 | AI11: =V11-17 -> 46322 | AO11: =EOMONTH(AH11,0) -> 46326 | AP11: =IF(AI11>USG!$E$25,EOMONTH(AI11,0),USG!$E$25) -> 46356 | AQ11: =EOMONTH(U11,2) -> 46418
A12: =A11+7 -> 46363 | C12: 45 | D12: =TEXT(A8,"mmmdd")&"-"&TEXT(WORKDAY(A8,4),"mmmdd") -> Nov16-Nov20 | E12: =C12/100 -> 0.45 | F12: =(E12)+F$2 -> 4.32 | G12: =(F12)+G$2 -> 7.4 | H12: =(G12)+H$2 -> 9.64 | J12: =C12-C13 -> 100 | K12: =C12-C15 -> 185 | L12: =J12+J10+J13 -> 375 | N12: =D12 -> Nov16-Nov20 | O12: =AB12 -> 8.69865 | P12: =VLOOKUP(Q12,USG!$D$1:$H$19,MATCH(USG!R12,USG!$D$1:$H$1,0),FALSE) -> 4.32 | Q12: =TEXT(A8,"mmmdd")&"-"&TEXT(WORKDAY(A8,4),"mmmdd") -> Nov16-Nov20 | R12: =EOMONTH(V12,2) -> 46418 | S12: =P12 -> 4.32 | U12: =WORKDAY(V11,1) -> 46342 | V12: =WORKDAY(U12,4) -> 46346 | X12: =VLOOKUP(AP$4,Sheet1!$P$3:$Q$41,2,FALSE)-VLOOKUP($AQ12,Sheet1!$S$3:$T$41,2,FALSE)+HLOOKUP(AP12,$D$25:$H$26,2,FALSE) -> -4.23 | Z12: =IF(EOMONTH(AI12,0)<AP12,USG!$D$29,0) -> 0 | AA12: =IFERROR(VLOOKUP(AG12,Freight!$A$3:$F$22,MATCH("TD25",Freight!$A$3:$F$3,0),FALSE),VLOOKUP(EOMONTH(AG12,1),Freight!$A$3:$F$22,MATCH("TD25",Freight!$A$3:$F$3,0),FALSE))+$AB$28 -> 17.24865 | AB12: =SUM(X12:AA12)-S12 -> 8.69865 | AG12: =IF(AH12<TODAY()+10,"Balmo",EOMONTH(AH12,0)) -> 46326 | AH12: =U12-17 -> 46325 | AI12: =V12-17 -> 46329 | AO12: =EOMONTH(AH12,0) -> 46326 | AP12: =IF(AI12>USG!$E$25,EOMONTH(AI12,0),USG!$E$25) -> 46356 | AQ12: =EOMONTH(U12,2) -> 46418
A13: =A14+7 -> 46377 | C13: -55 | D13: =TEXT(A10,"mmmdd")&"-"&TEXT(WORKDAY(A10,4),"mmmdd") -> Nov23-Nov27 | E13: =C13/100 -> -0.55 | F13: =(E13)+F$2 -> 3.32 | G13: =(F13)+G$2 -> 6.4 | H13: =(G13)+H$2 -> 8.64 | J13: =C13-C15 -> 85 | K13: =C13-C16 -> 170 | L13: =J13+J11+J14 -> 270 | N13: =D14 -> Full Month
A14: =A12+7 -> 46370 | D14: Full Month | E14: =AVERAGE(E10:E13) -> 1.6 | F14: =AVERAGE(F10:F13) -> 5.47 | G14: =AVERAGE(G10:G13) -> 8.55 | H14: =AVERAGE(H10:H13) -> 10.79 | N14: =D13 -> Nov23-Nov27 | O14: =AB14 -> 8.7325 | P14: =VLOOKUP(Q14,USG!$D$1:$H$19,MATCH(USG!R14,USG!$D$1:$H$1,0),FALSE) -> 3.32 | Q14: =TEXT(A10,"mmmdd")&"-"&TEXT(WORKDAY(A10,4),"mmmdd") -> Nov23-Nov27 | R14: =EOMONTH(V14,2) -> 46418 | S14: =P14 -> 3.32 | U14: =WORKDAY(V12,1) -> 46349 | V14: =WORKDAY(U14,4) -> 46353 | X14: =VLOOKUP(AP$4,Sheet1!$P$3:$Q$41,2,FALSE)-VLOOKUP($AQ14,Sheet1!$S$3:$T$41,2,FALSE)+HLOOKUP(AP14,$D$25:$H$26,2,FALSE) -> -4.23 | Z14: =IF(EOMONTH(AI14,0)<AP14,USG!$D$29,0) -> 0 | AA14: =IFERROR(VLOOKUP(AG14,Freight!$A$3:$F$22,MATCH("TD25",Freight!$A$3:$F$3,0),FALSE),VLOOKUP(EOMONTH(AG14,1),Freight!$A$3:$F$22,MATCH("TD25",Freight!$A$3:$F$3,0),FALSE))+$AB$28 -> 16.2825 | AB14: =SUM(X14:AA14)-S14 -> 8.7325 | AG14: =IF(AH14<TODAY()+10,"Balmo",EOMONTH(AH14,0)) -> 46356 | AH14: =U14-17 -> 46332 | AI14: =V14-17 -> 46336 | AO14: =EOMONTH(AH14,0) -> 46356 | AP14: =IF(AI14>USG!$E$25,EOMONTH(AI14,0),USG!$E$25) -> 46356 | AQ14: =EOMONTH(U14,2) -> 46418
A15: =A13+7 -> 46384 | C15: -140 | D15: =TEXT(A11,"mmmdd")&"-"&TEXT(WORKDAY(A11,4),"mmmdd") -> Nov30-Dec04 | E15: =C15/100 -> -1.4 | F15: =(E15)+F$2 -> 2.47 | G15: =(F15)+G$2 -> 5.55 | H15: =(G15)+H$2 -> 7.79 | J15: =C15-C16 -> 85 | K15: =C15-C17 -> 165 | L15: =J15+J14+J16 -> 165 | N15: =D15 -> Nov30-Dec04 | O15: =AB15 -> 6.5025 | P15: =VLOOKUP(Q15,USG!$D$1:$H$19,MATCH(USG!R15,USG!$D$1:$H$1,0),FALSE) -> 5.55 | Q15: =TEXT(A11,"mmmdd")&"-"&TEXT(WORKDAY(A11,4),"mmmdd") -> Nov30-Dec04 | R15: =EOMONTH(V15,2) -> 46446 | S15: =P15 -> 5.55 | U15: =WORKDAY(V14,1) -> 46356 | V15: =WORKDAY(U15,4) -> 46360 | X15: =VLOOKUP(AP$4,Sheet1!$P$3:$Q$41,2,FALSE)-VLOOKUP($AQ15,Sheet1!$S$3:$T$41,2,FALSE)+HLOOKUP(AP15,$D$25:$H$26,2,FALSE) -> -4.23 | Y15: 0 | Z15: =IF(EOMONTH(AI15,0)<AP15,USG!$D$29,0) -> 0 | AA15: =IFERROR(VLOOKUP(AG15,Freight!$A$3:$F$22,MATCH("TD25",Freight!$A$3:$F$3,0),FALSE),VLOOKUP(EOMONTH(AG15,1),Freight!$A$3:$F$22,MATCH("TD25",Freight!$A$3:$F$3,0),FALSE))+$AB$28 -> 16.2825 | AB15: =SUM(X15:AA15)-S15 -> 6.5025 | AG15: =IF(AH15<TODAY()+10,"Balmo",EOMONTH(AH15,0)) -> 46356 | AH15: =U15-17 -> 46339 | AI15: =V15-17 -> 46343 | AO15: =EOMONTH(AH15,0) -> 46356 | AP15: =IF(AI15>USG!$E$25,EOMONTH(AI15,0),USG!$E$25) -> 46356 | AQ15: =EOMONTH(U15,2) -> 46418
A16: =A15+7 -> 46391 | C16: -225 | D16: =TEXT(A12,"mmmdd")&"-"&TEXT(WORKDAY(A12,4),"mmmdd") -> Dec07-Dec11 | E16: =C16/100 -> -2.25 | F16: =(E16)+F$2 -> 1.62 | G16: =(F16)+G$2 -> 4.7 | H16: =(G16)+H$2 -> 6.94 | J16: =C16-C17 -> 80 | K16: =J16+J17 -> 150 | L16: =J16+J17+J18 -> -225 | N16: =D16 -> Dec07-Dec11 | O16: =AB16 -> 10.4325 | P16: =VLOOKUP(Q16,USG!$D$1:$H$19,MATCH(USG!R16,USG!$D$1:$H$1,0),FALSE) -> 4.7 | Q16: =TEXT(A12,"mmmdd")&"-"&TEXT(WORKDAY(A12,4),"mmmdd") -> Dec07-Dec11 | R16: =EOMONTH(V16,2) -> 46446 | S16: =P16 -> 4.7 | U16: =WORKDAY(V15,1) -> 46363 | V16: =WORKDAY(U16,4) -> 46367 | X16: =VLOOKUP(AP$4,Sheet1!$P$3:$Q$41,2,FALSE)-VLOOKUP($AQ16,Sheet1!$S$3:$T$41,2,FALSE)+HLOOKUP(AP16,$D$25:$H$26,2,FALSE) -> -1.15 | Y16: 0 | Z16: =IF(EOMONTH(AI16,0)<AP16,USG!$D$29,0) -> 0 | AA16: =IFERROR(VLOOKUP(AG16,Freight!$A$3:$F$22,MATCH("TD25",Freight!$A$3:$F$3,0),FALSE),VLOOKUP(EOMONTH(AG16,1),Freight!$A$3:$F$22,MATCH("TD25",Freight!$A$3:$F$3,0),FALSE))+$AB$28 -> 16.2825 | AB16: =SUM(X16:AA16)-S16 -> 10.4325 | AG16: =IF(AH16<TODAY()+10,"Balmo",EOMONTH(AH16,0)) -> 46356 | AH16: =U16-17 -> 46346 | AI16: =V16-17 -> 46350 | AO16: =EOMONTH(AH16,0) -> 46356 | AP16: =IF(AI16>USG!$E$25,EOMONTH(AI16,0),USG!$E$25) -> 46356 | AQ16: =EOMONTH(U16,2) -> 46446
A17: =A16+7 -> 46398 | C17: -305 | D17: =TEXT(A14,"mmmdd")&"-"&TEXT(WORKDAY(A14,4),"mmmdd") -> Dec14-Dec18 | E17: =C17/100 -> -3.05 | F17: =(E17)+F$2 -> 0.82 | G17: =(F17)+G$2 -> 3.9 | H17: =(G17)+H$2 -> 6.14 | J17: =C17-C18 -> 70 | K17: =J17+J18 -> -305 | L17: =J17+J18+J20 -> -305 | N17: =D17 -> Dec14-Dec18 | O17: =AB17 -> 10.8825 | P17: =VLOOKUP(Q17,USG!$D$1:$H$19,MATCH(USG!R17,USG!$D$1:$H$1,0),FALSE) -> 3.9 | Q17: =TEXT(A14,"mmmdd")&"-"&TEXT(WORKDAY(A14,4),"mmmdd") -> Dec14-Dec18 | R17: =EOMONTH(V17,2) -> 46446 | S17: =P17 -> 3.9 | U17: =WORKDAY(V16,1) -> 46370 | V17: =WORKDAY(U17,4) -> 46374 | X17: =VLOOKUP(AP$4,Sheet1!$P$3:$Q$41,2,FALSE)-VLOOKUP($AQ17,Sheet1!$S$3:$T$41,2,FALSE)+HLOOKUP(AP17,$D$25:$H$26,2,FALSE) -> -1.5 | Y17: 0 | Z17: =IF(EOMONTH(AI17,0)<AP17,USG!$D$29,0) -> 0 | AA17: =IFERROR(VLOOKUP(AG17,Freight!$A$3:$F$22,MATCH("TD25",Freight!$A$3:$F$3,0),FALSE),VLOOKUP(EOMONTH(AG17,1),Freight!$A$3:$F$22,MATCH("TD25",Freight!$A$3:$F$3,0),FALSE))+$AB$28 -> 16.2825 | AB17: =SUM(X17:AA17)-S17 -> 10.8825 | AG17: =IF(AH17<TODAY()+10,"Balmo",EOMONTH(AH17,0)) -> 46356 | AH17: =U17-17 -> 46353 | AI17: =V17-17 -> 46357 | AO17: =EOMONTH(AH17,0) -> 46356 | AP17: =IF(AI17>USG!$E$25,EOMONTH(AI17,0),USG!$E$25) -> 46387 | AQ17: =EOMONTH(U17,2) -> 46446
C18: -375 | D18: =TEXT(A13,"mmmdd")&"-"&TEXT(WORKDAY(A13,4),"mmmdd") -> Dec21-Dec25 | E18: =C18/100 -> -3.75 | F18: =(E18)+F$2 -> 0.12 | G18: =(F18)+G$2 -> 3.2 | H18: =(G18)+H$2 -> 5.44 | J18: =C18-C20 -> -375 | K18: =J18+J20 -> -375 | L18: =J18+J20+J21 -> -375 | N18: =D18 -> Dec21-Dec25 | O18: =AB18 -> 8.1473 | P18: =VLOOKUP(Q18,USG!$D$1:$H$19,MATCH(USG!R18,USG!$D$1:$H$1,0),FALSE) -> 3.2 | Q18: =TEXT(A13,"mmmdd")&"-"&TEXT(WORKDAY(A13,4),"mmmdd") -> Dec21-Dec25 | R18: =EOMONTH(V18,2) -> 46446 | S18: =P18 -> 3.2 | U18: =WORKDAY(V17,1) -> 46377 | V18: =WORKDAY(U18,4) -> 46381 | X18: =VLOOKUP(AP$4,Sheet1!$P$3:$Q$41,2,FALSE)-VLOOKUP($AQ18,Sheet1!$S$3:$T$41,2,FALSE)+HLOOKUP(AP18,$D$25:$H$26,2,FALSE) -> -1.5 | Y18: 0 | Z18: =IF(EOMONTH(AI18,0)<AP18,USG!$D$29,0) -> 0 | AA18: =IFERROR(VLOOKUP(AG18,Freight!$A$3:$F$22,MATCH("TD25",Freight!$A$3:$F$3,0),FALSE),VLOOKUP(EOMONTH(AG18,1),Freight!$A$3:$F$22,MATCH("TD25",Freight!$A$3:$F$3,0),FALSE))+$AB$28 -> 12.8473 | AB18: =SUM(X18:AA18)-S18 -> 8.1473 | AG18: =IF(AH18<TODAY()+10,"Balmo",EOMONTH(AH18,0)) -> 46387 | AH18: =U18-17 -> 46360 | AI18: =V18-17 -> 46364 | AO18: =EOMONTH(AH18,0) -> 46387 | AP18: =IF(AI18>USG!$E$25,EOMONTH(AI18,0),USG!$E$25) -> 46387 | AQ18: =EOMONTH(U18,2) -> 46446
D19: Full Month | E19: =AVERAGE(E15:E18) -> -2.6125 | F19: =AVERAGE(F15:F18,F13) -> 1.67 | G19: =AVERAGE(G15:G18,G13) -> 4.75 | H19: =AVERAGE(H15:H18) -> 6.5775 | N19: Full Month | O19: =AVERAGE(O15:O18) -> 8.9912
Q20: CFD Weeker | R20: vs. ICE Brent | S20: Diff | U20: Delivery Window | X20: MEH/Brent | Y20: FOB Premium | Z20: Cash Roll | AA20: Freight+Cost | AB20: Curve Value | AD20: Platts Window | AH20: USGC Load Window | AO20: =EOMONTH(AH21,0) -> #NUM! | AP20: =IF(AI21>USG!$E$25,EOMONTH(AI21,0),USG!$E$25) -> 46356 | AQ20: =EOMONTH(U20,2) -> #VALUE! | AS20: =WORKDAY(AT20,-1) -> #NUM! | AT20: =WORKDAY(AU20,-1) -> #NUM! | AU20: =WORKDAY(U22,-1) -> #NUM! | AV20: =WORKDAY(AU20,1) -> #NUM! | AW20: =WORKDAY(AV20,1) -> #NUM! | AX20: =IF(AI23>USG!$E$25,EOMONTH(AI23,0),USG!$E$25) -> 46356
Q21: Gunvor | R21: =EOMONTH(V21,2) -> 91 | S21: 0.88 | X21: =VLOOKUP(AP$21,Sheet1!$P$3:$Q$41,2,FALSE)-VLOOKUP(EOMONTH($AP4,2),Sheet1!$S$3:$T$41,2,FALSE)+HLOOKUP(AP4,$K$24:$O$25,2,FALSE) -> #N/A | Y21: =AD21-AB21 -> #NUM! | Z21: =$Z$4 -> 3 | AA21: =IFERROR(VLOOKUP(EOMONTH(AH21,0),Freight!$A$3:$F$22,MATCH("TD25",Freight!$A$3:$F$3,0),FALSE),VLOOKUP(EOMONTH(AH21,1),Freight!$A$3:$F$22,MATCH("TD25",Freight!$A$3:$F$3,0),FALSE))+$AB$28 -> #NUM! | AB21: =SUM(Z21:AA21)-S21+X21 -> #NUM! | AD21: 1.2 | AE21: =AS18 -> 0 | AF21: =AW18 -> 0 | AH21: =U21-17 -> -17 | AI21: =V21-17 -> -17 | AO21: =EOMONTH(AH23,0) -> #NUM! | AP21: =IF(AI23>USG!$E$25,EOMONTH(AI23,0),USG!$E$25) -> 46356 | AQ21: =EOMONTH(U21,2) -> 91 | AS21: =WORKDAY(AT21,-1) -> #NUM! | AT21: =WORKDAY(AU21,-1) -> #NUM! | AU21: =WORKDAY(U23,-1) -> #NUM! | AV21: =WORKDAY(AU21,1) -> #NUM! | AW21: =WORKDAY(AV21,1) -> #NUM! | AX21: =IF(AI24>USG!$E$25,EOMONTH(AI24,0),USG!$E$25) -> 46356 | BS21: =3-E51 -> 24.4
Q22: Gunvor | R22: =EOMONTH(V22,2) -> 91 | S22: 0.86 | X22: =VLOOKUP(AP$21,Sheet1!$P$3:$Q$41,2,FALSE)-VLOOKUP(EOMONTH($AP5,2),Sheet1!$S$3:$T$41,2,FALSE)+HLOOKUP(AP5,$K$24:$O$25,2,FALSE) -> #N/A | Y22: =AD22-AB22 -> #NUM! | Z22: =$Z$4 -> 3 | AA22: =IFERROR(VLOOKUP(EOMONTH(AH22,0),Freight!$A$3:$F$22,MATCH("TD25",Freight!$A$3:$F$3,0),FALSE),VLOOKUP(EOMONTH(AH22,1),Freight!$A$3:$F$22,MATCH("TD25",Freight!$A$3:$F$3,0),FALSE))+$AB$28 -> #NUM! | AB22: =SUM(Z22:AA22)-S22+X22 -> #NUM! | AD22: 1.2 | AE22: =AS20 -> #NUM! | AF22: =AW20 -> #NUM! | AH22: =U22-17 -> -17 | AI22: =V22-17 -> -17 | AO22: =EOMONTH(AH24,0) -> #NUM! | AP22: =IF(AI24>USG!$E$25,EOMONTH(AI24,0),USG!$E$25) -> 46356 | AQ22: =EOMONTH(U22,2) -> 91 | AS22: =WORKDAY(AT22,-1) -> #NUM! | AT22: =WORKDAY(AU22,-1) -> #NUM! | AU22: =WORKDAY(U24,-1) -> #NUM! | AV22: =WORKDAY(AU22,1) -> #NUM! | AW22: =WORKDAY(AV22,1) -> #NUM! | AX22: =IF(AI25>USG!$E$25,EOMONTH(AI25,0),USG!$E$25) -> 46356
X23: =VLOOKUP(AP$21,Sheet1!$P$3:$Q$41,2,FALSE)-VLOOKUP(EOMONTH($AP6,2),Sheet1!$S$3:$T$41,2,FALSE)+HLOOKUP(AP6,$K$24:$O$25,2,FALSE) -> #N/A | Y23: =AD23-AB23 -> #NUM! | Z23: =$Z$4 -> 3 | AA23: =IFERROR(VLOOKUP(EOMONTH(AH23,0),Freight!$A$3:$F$22,MATCH("TD25",Freight!$A$3:$F$3,0),FALSE),VLOOKUP(EOMONTH(AH23,1),Freight!$A$3:$F$22,MATCH("TD25",Freight!$A$3:$F$3,0),FALSE))+$AB$28 -> #NUM! | AB23: =SUM(Z23:AA23)-S23+X23 -> #NUM! | AD23: 1.2 | AE23: =AS21 -> #NUM! | AF23: =AW21 -> #NUM! | AH23: =U23-17 -> -17 | AI23: =V23-17 -> -17 | AO23: =EOMONTH(AH24,0) -> #NUM! | AP23: =IF(AI24>USG!$E$25,EOMONTH(AI24,0),USG!$E$25) -> 46356 | AQ23: =EOMONTH(U23,2) -> 91 | AS23: =WORKDAY(AT23,-1) -> #NUM! | AT23: =WORKDAY(AU23,-1) -> #NUM! | AU23: =WORKDAY(U25,-1) -> #NUM! | AV23: =WORKDAY(AU23,1) -> #NUM! | AW23: =WORKDAY(AV23,1) -> #NUM! | AX23: =IF(AI25>USG!$E$25,EOMONTH(AI25,0),USG!$E$25) -> 46356
B24: =Sheet1!AB4 -> 2.58 | C24: MID/MEH | D24: =Sheet1!B7-Sheet1!B8 -> #VALUE! | E24: =Sheet1!C7-Sheet1!C8 -> 3.25 | F24: =Sheet1!D7-Sheet1!D8 -> 0.65 | G24: =Sheet1!E7-Sheet1!E8 -> 0.65 | H24: =Sheet1!F7-Sheet1!F8 -> 0.55 | I24: =Sheet1!G7-Sheet1!G8 -> 0.55 | J24: =Sheet1!H7-Sheet1!H8 -> 0.55 | K24: =Sheet1!I7-Sheet1!I8 -> 0.6 | L24: =Sheet1!J7-Sheet1!J8 -> 0.6 | AH24: =U24-17 -> -17 | AO24: =EOMONTH(AH25,0) -> #NUM! | AP24: =IF(AI25>USG!$E$25,EOMONTH(AI25,0),USG!$E$25) -> 46356 | AQ24: =EOMONTH(U24,2) -> 91 | AS24: =WORKDAY(AT24,-1) -> #NUM! | AT24: =WORKDAY(AU24,-1) -> #NUM! | AU24: =WORKDAY(U26,-1) -> #NUM! | AV24: =WORKDAY(AU24,1) -> #NUM! | AW24: =WORKDAY(AV24,1) -> #NUM! | AX24: =IF(AI26>USG!$E$25,EOMONTH(AI26,0),USG!$E$25) -> 46356
C25: MEH | D25: =E25 -> 46356 | E25: =Sheet1!P3 -> 46356 | F25: =EOMONTH(E25,1) -> 46387 | G25: =EOMONTH(F25,1) -> 46418 | H25: =EOMONTH(G25,1) -> 46446 | I25: =EOMONTH(H25,1) -> 46477 | J25: =EOMONTH(I25,1) -> 46507 | K25: =EOMONTH(J25,1) -> 46538 | L25: =EOMONTH(K25,1) -> 46568 | AH25: =U25-17 -> -17 | AS25: =WORKDAY(AT25,-1) -> #NUM! | AT25: =WORKDAY(AU25,-1) -> #NUM! | AU25: =WORKDAY(U27,-1) -> #NUM! | AV25: =WORKDAY(AU25,1) -> #NUM! | AW25: =WORKDAY(AV25,1) -> #NUM! | AX25: =IF(AI27>USG!$E$25,EOMONTH(AI27,0),USG!$E$25) -> 46356
C26: HTT | D26: =E26 -> 1.25 | E26: 1.25 | F26: =E26+(-INDEX(Sheet1!$B$6:$N$18,MATCH("MEH",Sheet1!$B$6:$B$18,0),MATCH(EOMONTH(E25,-1)+1,Sheet1!$B$5:$N$5,0))+INDEX(Sheet1!$B$6:$N$18,MATCH("MEH",Sheet1!$B$6:$B$18,0),MATCH(EOMONTH(F25,-1)+1,Sheet1!$B$5:$N$5,0))) -> 0.9 | G26: =F26+(-INDEX(Sheet1!$B$6:$N$18,MATCH("MEH",Sheet1!$B$6:$B$18,0),MATCH(EOMONTH(F25,-1)+1,Sheet1!$B$5:$N$5,0))+INDEX(Sheet1!$B$6:$N$18,MATCH("MEH",Sheet1!$B$6:$B$18,0),MATCH(EOMONTH(G25,-1)+1,Sheet1!$B$5:$N$5,0))) -> 1.1 | H26: =G26+(-INDEX(Sheet1!$B$6:$N$18,MATCH("MEH",Sheet1!$B$6:$B$18,0),MATCH(EOMONTH(G25,-1)+1,Sheet1!$B$5:$N$5,0))+INDEX(Sheet1!$B$6:$N$18,MATCH("MEH",Sheet1!$B$6:$B$18,0),MATCH(EOMONTH(H25,-1)+1,Sheet1!$B$5:$N$5,0))) -> 1.3 | I26: =H26+(-INDEX(Sheet1!$B$6:$N$18,MATCH("MEH",Sheet1!$B$6:$B$18,0),MATCH(EOMONTH(H25,-1)+1,Sheet1!$B$5:$N$5,0))+INDEX(Sheet1!$B$6:$N$18,MATCH("MEH",Sheet1!$B$6:$B$18,0),MATCH(EOMONTH(I25,-1)+1,Sheet1!$B$5:$N$5,0))) -> 1.45 | J26: =I26+(-INDEX(Sheet1!$B$6:$N$18,MATCH("MEH",Sheet1!$B$6:$B$18,0),MATCH(EOMONTH(I25,-1)+1,Sheet1!$B$5:$N$5,0))+INDEX(Sheet1!$B$6:$N$18,MATCH("MEH",Sheet1!$B$6:$B$18,0),MATCH(EOMONTH(J25,-1)+1,Sheet1!$B$5:$N$5,0))) -> 1.65 | K26: =J26+(-INDEX(Sheet1!$B$6:$N$18,MATCH("MEH",Sheet1!$B$6:$B$18,0),MATCH(EOMONTH(J25,-1)+1,Sheet1!$B$5:$N$5,0))+INDEX(Sheet1!$B$6:$N$18,MATCH("MEH",Sheet1!$B$6:$B$18,0),MATCH(EOMONTH(K25,-1)+1,Sheet1!$B$5:$N$5,0))) -> 1.7 | L26: =K26+(-INDEX(Sheet1!$B$6:$N$18,MATCH("MEH",Sheet1!$B$6:$B$18,0),MATCH(EOMONTH(K25,-1)+1,Sheet1!$B$5:$N$5,0))+INDEX(Sheet1!$B$6:$N$18,MATCH("MEH",Sheet1!$B$6:$B$18,0),MATCH(EOMONTH(L25,-1)+1,Sheet1!$B$5:$N$5,0))) -> 1.75
C27: WTI | BM27: 1.25 | BN27: 1
C28: PREMIUM | E28: 0.3 | F28: 0 | AB28: 0.18
C29: CASH | D29: 3
C30: CASH PREMIUM | Y30: FOB | Z30: -3
Y31: Aug DFL | Z31: -0.16
C32: =EOMONTH(C33,-1) -> 46356 | D32: =VLOOKUP(D$25,Sheet1!$P$3:$Q$41,2,FALSE)+D$26-VLOOKUP($C32,Sheet1!$S$3:$T$41,2,FALSE)+D28+D29 -> #N/A | E32: =VLOOKUP(E$25,Sheet1!$P$3:$Q$41,2,FALSE)+E$26-VLOOKUP($C32,Sheet1!$S$3:$T$41,2,FALSE) -> #N/A | F32: =VLOOKUP(F$25,Sheet1!$P$3:$Q$41,2,FALSE)+F$26-VLOOKUP($C32,Sheet1!$S$3:$T$41,2,FALSE) -> #N/A | P32: =E25 -> 46356 | Q32: TD25 | R32: TD7 | S32: CIF Rdam | U32: CIF Nsea | V32: Open/Closed | Y32: Oct Arbs | Z32: -4.2
C33: =EOMONTH(E25,1) -> 46387 | D33: =VLOOKUP(D$25,Sheet1!$P$3:$Q$41,2,FALSE)+D$26-VLOOKUP($C33,Sheet1!$S$3:$T$41,2,FALSE)+$D$29+$D$30 -> -5.1 | E33: =VLOOKUP(E$25,Sheet1!$P$3:$Q$41,2,FALSE)+E$26-VLOOKUP($C33,Sheet1!$S$3:$T$41,2,FALSE) -> -8.1 | F33: =VLOOKUP(F$25,Sheet1!$P$3:$Q$41,2,FALSE)+F$26-VLOOKUP($C33,Sheet1!$S$3:$T$41,2,FALSE) -> -10.51 | G33: =VLOOKUP(G$25,Sheet1!$P$3:$Q$41,2,FALSE)+G$26-VLOOKUP($C33,Sheet1!$S$3:$T$41,2,FALSE) -> -12.4 | H33: =VLOOKUP(H$25,Sheet1!$P$3:$Q$41,2,FALSE)+H$26-VLOOKUP($C33,Sheet1!$S$3:$T$41,2,FALSE) -> -14.3 | I33: =VLOOKUP(I$25,Sheet1!$P$3:$Q$41,2,FALSE)+I$26-VLOOKUP($C33,Sheet1!$S$3:$T$41,2,FALSE) -> -16.11 | J33: =VLOOKUP(J$25,Sheet1!$P$3:$Q$41,2,FALSE)+J$26-VLOOKUP($C33,Sheet1!$S$3:$T$41,2,FALSE) -> -17.57 | K33: =VLOOKUP(K$25,Sheet1!$P$3:$Q$41,2,FALSE)+K$26-VLOOKUP($C33,Sheet1!$S$3:$T$41,2,FALSE) -> -18.88 | L33: =VLOOKUP(L$25,Sheet1!$P$3:$Q$41,2,FALSE)+L$26-VLOOKUP($C33,Sheet1!$S$3:$T$41,2,FALSE) -> -20.09 | Y33: Sep/Oct WTI | Z33: 0.5
C34: =EOMONTH(C33,1) -> 46418 | D34: =VLOOKUP(D$25,Sheet1!$P$3:$Q$41,2,FALSE)+D$26-VLOOKUP($C34,Sheet1!$S$3:$T$41,2,FALSE)+$D$29+$D$30 -> -1.23 | E34: =VLOOKUP(E$25,Sheet1!$P$3:$Q$41,2,FALSE)+E$26-VLOOKUP($C34,Sheet1!$S$3:$T$41,2,FALSE)+$E$28 -> -3.93 | F34: =VLOOKUP(F$25,Sheet1!$P$3:$Q$41,2,FALSE)+F$26-VLOOKUP($C34,Sheet1!$S$3:$T$41,2,FALSE) -> -6.64 | G34: =VLOOKUP(G$25,Sheet1!$P$3:$Q$41,2,FALSE)+G$26-VLOOKUP($C34,Sheet1!$S$3:$T$41,2,FALSE) -> -8.53 | H34: =VLOOKUP(H$25,Sheet1!$P$3:$Q$41,2,FALSE)+H$26-VLOOKUP($C34,Sheet1!$S$3:$T$41,2,FALSE)+H$28 -> -10.43 | I34: =VLOOKUP(I$25,Sheet1!$P$3:$Q$41,2,FALSE)+I$26-VLOOKUP($C34,Sheet1!$S$3:$T$41,2,FALSE)+I$28 -> -12.24 | J34: =VLOOKUP(J$25,Sheet1!$P$3:$Q$41,2,FALSE)+J$26-VLOOKUP($C34,Sheet1!$S$3:$T$41,2,FALSE)+J$28 -> -13.7 | K34: =VLOOKUP(K$25,Sheet1!$P$3:$Q$41,2,FALSE)+K$26-VLOOKUP($C34,Sheet1!$S$3:$T$41,2,FALSE)+K$28 -> -15.01 | L34: =VLOOKUP(L$25,Sheet1!$P$3:$Q$41,2,FALSE)+L$26-VLOOKUP($C34,Sheet1!$S$3:$T$41,2,FALSE)+L$28 -> -16.22 | Y34: vs Sep WTI | Z34: =Z30+Z31-Z32-Z33 -> 0.54
C35: =EOMONTH(C34,1) -> 46446 | D35: =VLOOKUP(D$25,Sheet1!$P$3:$Q$41,2,FALSE)+D$26-VLOOKUP($C35,Sheet1!$S$3:$T$41,2,FALSE)+$D$29+$D$30 -> 1.85 | E35: =VLOOKUP(E$25,Sheet1!$P$3:$Q$41,2,FALSE)+E$26-VLOOKUP($C35,Sheet1!$S$3:$T$41,2,FALSE)+$E$28 -> -0.85 | F35: =VLOOKUP(F$25,Sheet1!$P$3:$Q$41,2,FALSE)+F$26-VLOOKUP($C35,Sheet1!$S$3:$T$41,2,FALSE)+F$28 -> -3.56 | G35: =VLOOKUP(G$25,Sheet1!$P$3:$Q$41,2,FALSE)+G$26-VLOOKUP($C35,Sheet1!$S$3:$T$41,2,FALSE)+G$28 -> -5.45 | H35: =VLOOKUP(H$25,Sheet1!$P$3:$Q$41,2,FALSE)+H$26-VLOOKUP($C35,Sheet1!$S$3:$T$41,2,FALSE)+H$28 -> -7.35 | I35: =VLOOKUP(I$25,Sheet1!$P$3:$Q$41,2,FALSE)+I$26-VLOOKUP($C35,Sheet1!$S$3:$T$41,2,FALSE)+I$28 -> -9.16 | J35: =VLOOKUP(J$25,Sheet1!$P$3:$Q$41,2,FALSE)+J$26-VLOOKUP($C35,Sheet1!$S$3:$T$41,2,FALSE)+J$28 -> -10.62 | K35: =VLOOKUP(K$25,Sheet1!$P$3:$Q$41,2,FALSE)+K$26-VLOOKUP($C35,Sheet1!$S$3:$T$41,2,FALSE)+K$28 -> -11.93 | L35: =VLOOKUP(L$25,Sheet1!$P$3:$Q$41,2,FALSE)+L$26-VLOOKUP($C35,Sheet1!$S$3:$T$41,2,FALSE)+L$28 -> -13.14 | O35: 46356 | P35: =D33 -> -5.1 | Q35: =P59 -> 460.5 | R35: =Q62 -> 300 | S35: =P35+(Q35*21.47*70/700/100) -> 4.786935 | U35: =7.25*R35*86.7/100/700 -> 2.6938929 | V35: =U35-S35 -> -2.0930421
C36: =EOMONTH(C35,1) -> 46477 | D36: =VLOOKUP(D$25,Sheet1!$P$3:$Q$41,2,FALSE)+D$26-VLOOKUP($C36,Sheet1!$S$3:$T$41,2,FALSE)+$D$29+$D$30 -> 4.17 | E36: =VLOOKUP(E$25,Sheet1!$P$3:$Q$41,2,FALSE)+E$26-VLOOKUP($C36,Sheet1!$S$3:$T$41,2,FALSE)+$E$28 -> 1.47 | F36: =VLOOKUP(F$25,Sheet1!$P$3:$Q$41,2,FALSE)+F$26-VLOOKUP($C36,Sheet1!$S$3:$T$41,2,FALSE)+F$28 -> -1.24 | G36: =VLOOKUP(G$25,Sheet1!$P$3:$Q$41,2,FALSE)+G$26-VLOOKUP($C36,Sheet1!$S$3:$T$41,2,FALSE)+G$28 -> -3.13 | H36: =VLOOKUP(H$25,Sheet1!$P$3:$Q$41,2,FALSE)+H$26-VLOOKUP($C36,Sheet1!$S$3:$T$41,2,FALSE)+H$28 -> -5.03 | I36: =VLOOKUP(I$25,Sheet1!$P$3:$Q$41,2,FALSE)+I$26-VLOOKUP($C36,Sheet1!$S$3:$T$41,2,FALSE)+I$28 -> -6.84 | J36: =VLOOKUP(J$25,Sheet1!$P$3:$Q$41,2,FALSE)+J$26-VLOOKUP($C36,Sheet1!$S$3:$T$41,2,FALSE)+J$28 -> -8.3 | K36: =VLOOKUP(K$25,Sheet1!$P$3:$Q$41,2,FALSE)+K$26-VLOOKUP($C36,Sheet1!$S$3:$T$41,2,FALSE)+K$28 -> -9.61 | L36: =VLOOKUP(L$25,Sheet1!$P$3:$Q$41,2,FALSE)+L$26-VLOOKUP($C36,Sheet1!$S$3:$T$41,2,FALSE)+L$28 -> -10.82 | Y36: Freight | Z36: =+AA36/950 -> 3.6842105 | AA36: 3500
C37: =EOMONTH(C36,1) -> 46507 | D37: =VLOOKUP(D$25,Sheet1!$P$3:$Q$41,2,FALSE)+D$26-VLOOKUP($C37,Sheet1!$S$3:$T$41,2,FALSE)+$D$29+$D$30 -> 6.08 | E37: =VLOOKUP(E$25,Sheet1!$P$3:$Q$41,2,FALSE)+E$26-VLOOKUP($C37,Sheet1!$S$3:$T$41,2,FALSE)+$E$28 -> 3.38 | F37: =VLOOKUP(F$25,Sheet1!$P$3:$Q$41,2,FALSE)+F$26-VLOOKUP($C37,Sheet1!$S$3:$T$41,2,FALSE)+F$28 -> 0.67 | G37: =VLOOKUP(G$25,Sheet1!$P$3:$Q$41,2,FALSE)+G$26-VLOOKUP($C37,Sheet1!$S$3:$T$41,2,FALSE)+G$28 -> -1.22 | H37: =VLOOKUP(H$25,Sheet1!$P$3:$Q$41,2,FALSE)+H$26-VLOOKUP($C37,Sheet1!$S$3:$T$41,2,FALSE)+H$28 -> -3.12 | I37: =VLOOKUP(I$25,Sheet1!$P$3:$Q$41,2,FALSE)+I$26-VLOOKUP($C37,Sheet1!$S$3:$T$41,2,FALSE)+I$28 -> -4.93 | J37: =VLOOKUP(J$25,Sheet1!$P$3:$Q$41,2,FALSE)+J$26-VLOOKUP($C37,Sheet1!$S$3:$T$41,2,FALSE)+J$28 -> -6.39 | K37: =VLOOKUP(K$25,Sheet1!$P$3:$Q$41,2,FALSE)+K$26-VLOOKUP($C37,Sheet1!$S$3:$T$41,2,FALSE)+K$28 -> -7.7 | L37: =VLOOKUP(L$25,Sheet1!$P$3:$Q$41,2,FALSE)+L$26-VLOOKUP($C37,Sheet1!$S$3:$T$41,2,FALSE)+L$28 -> -8.91 | O37: 46387 | P37: =F33 -> -10.51 | Q37: =AVERAGE(P61:P62) -> 670 | R37: =R35 -> 300 | S37: =P37+(Q37*21.47*70/700/100) -> 3.8749 | U37: =7.25*R37*86.7/100/700 -> 2.6938929 | V37: =U37-S37 -> -1.1810071 | Y37: Secondary | Z37: 0.6 | BA37: 700 | BB37: -1.6 | BC37: 0.89 | BD37: =SUM(BB37:BC37) -> -0.71 | BE37: 0.1
B38: ICE Brent | C38: =EOMONTH(C37,1) -> 46538 | D38: =VLOOKUP(D$25,Sheet1!$P$3:$Q$41,2,FALSE)+D$26-VLOOKUP($C38,Sheet1!$S$3:$T$41,2,FALSE)+$D$29+$D$30 -> 7.77 | E38: =VLOOKUP(E$25,Sheet1!$P$3:$Q$41,2,FALSE)+E$26-VLOOKUP($C38,Sheet1!$S$3:$T$41,2,FALSE)+$E$28 -> 5.07 | F38: =VLOOKUP(F$25,Sheet1!$P$3:$Q$41,2,FALSE)+F$26-VLOOKUP($C38,Sheet1!$S$3:$T$41,2,FALSE)+F$28 -> 2.36 | G38: =VLOOKUP(G$25,Sheet1!$P$3:$Q$41,2,FALSE)+G$26-VLOOKUP($C38,Sheet1!$S$3:$T$41,2,FALSE)+G$28 -> 0.47 | H38: =VLOOKUP(H$25,Sheet1!$P$3:$Q$41,2,FALSE)+H$26-VLOOKUP($C38,Sheet1!$S$3:$T$41,2,FALSE)+H$28 -> -1.43 | I38: =VLOOKUP(I$25,Sheet1!$P$3:$Q$41,2,FALSE)+I$26-VLOOKUP($C38,Sheet1!$S$3:$T$41,2,FALSE)+I$28 -> -3.24 | J38: =VLOOKUP(J$25,Sheet1!$P$3:$Q$41,2,FALSE)+J$26-VLOOKUP($C38,Sheet1!$S$3:$T$41,2,FALSE)+J$28 -> -4.7 | K38: =VLOOKUP(K$25,Sheet1!$P$3:$Q$41,2,FALSE)+K$26-VLOOKUP($C38,Sheet1!$S$3:$T$41,2,FALSE)+K$28 -> -6.01 | L38: =VLOOKUP(L$25,Sheet1!$P$3:$Q$41,2,FALSE)+L$26-VLOOKUP($C38,Sheet1!$S$3:$T$41,2,FALSE)+L$28 -> -7.22 | O38: 46387 | P38: =F34 -> -6.64 | Q38: =P62 -> 590 | R38: =R37 -> 300 | S38: =P38+(Q38*21.47*70/700/100) -> 6.0273 | U38: =7.25*R38*86.7/100/700 -> 2.6938929 | V38: =U38-S38 -> -3.3334071 | Y38: Liza CFR USG | Z38: =Z36+Z34+Z37 -> 4.8242105 | BA38: 700 | BB38: -1.6 | BC38: 0.89 | BD38: =SUM(BB38:BC38) -> -0.71 | BE38: 0.1
C39: =EOMONTH(C38,1) -> 46568 | D39: =VLOOKUP(D$25,Sheet1!$P$3:$Q$41,2,FALSE)+D$26-VLOOKUP($C39,Sheet1!$S$3:$T$41,2,FALSE)+$D$29+$D$30 -> 9.3 | E39: =VLOOKUP(E$25,Sheet1!$P$3:$Q$41,2,FALSE)+E$26-VLOOKUP($C39,Sheet1!$S$3:$T$41,2,FALSE)+$E$28 -> 6.6 | F39: =VLOOKUP(F$25,Sheet1!$P$3:$Q$41,2,FALSE)+F$26-VLOOKUP($C39,Sheet1!$S$3:$T$41,2,FALSE)+F$28 -> 3.89 | G39: =VLOOKUP(G$25,Sheet1!$P$3:$Q$41,2,FALSE)+G$26-VLOOKUP($C39,Sheet1!$S$3:$T$41,2,FALSE)+G$28 -> 2 | H39: =VLOOKUP(H$25,Sheet1!$P$3:$Q$41,2,FALSE)+H$26-VLOOKUP($C39,Sheet1!$S$3:$T$41,2,FALSE)+H$28 -> 0.1 | I39: =VLOOKUP(I$25,Sheet1!$P$3:$Q$41,2,FALSE)+I$26-VLOOKUP($C39,Sheet1!$S$3:$T$41,2,FALSE)+I$28 -> -1.71 | J39: =VLOOKUP(J$25,Sheet1!$P$3:$Q$41,2,FALSE)+J$26-VLOOKUP($C39,Sheet1!$S$3:$T$41,2,FALSE)+J$28 -> -3.17 | K39: =VLOOKUP(K$25,Sheet1!$P$3:$Q$41,2,FALSE)+K$26-VLOOKUP($C39,Sheet1!$S$3:$T$41,2,FALSE)+K$28 -> -4.48 | L39: =VLOOKUP(L$25,Sheet1!$P$3:$Q$41,2,FALSE)+L$26-VLOOKUP($C39,Sheet1!$S$3:$T$41,2,FALSE)+L$28 -> -5.69 | BA39: 700 | BB39: =-0.84-0.89 -> -1.73 | BD39: -0.84 | BE39: -0.13
C40: =EOMONTH(C39,1) -> 46599 | D40: =VLOOKUP(D$25,Sheet1!$P$3:$Q$41,2,FALSE)+D$26-VLOOKUP($C40,Sheet1!$S$3:$T$41,2,FALSE)+$D$29+$D$30 -> 10.7 | E40: =VLOOKUP(E$25,Sheet1!$P$3:$Q$41,2,FALSE)+E$26-VLOOKUP($C40,Sheet1!$S$3:$T$41,2,FALSE)+$E$28 -> 8 | F40: =VLOOKUP(F$25,Sheet1!$P$3:$Q$41,2,FALSE)+F$26-VLOOKUP($C40,Sheet1!$S$3:$T$41,2,FALSE)+F$28 -> 5.29 | G40: =VLOOKUP(G$25,Sheet1!$P$3:$Q$41,2,FALSE)+G$26-VLOOKUP($C40,Sheet1!$S$3:$T$41,2,FALSE)+G$28 -> 3.4 | H40: =VLOOKUP(H$25,Sheet1!$P$3:$Q$41,2,FALSE)+H$26-VLOOKUP($C40,Sheet1!$S$3:$T$41,2,FALSE)+H$28 -> 1.5 | I40: =VLOOKUP(I$25,Sheet1!$P$3:$Q$41,2,FALSE)+I$26-VLOOKUP($C40,Sheet1!$S$3:$T$41,2,FALSE)+I$28 -> -0.31 | J40: =VLOOKUP(J$25,Sheet1!$P$3:$Q$41,2,FALSE)+J$26-VLOOKUP($C40,Sheet1!$S$3:$T$41,2,FALSE)+J$28 -> -1.77 | K40: =VLOOKUP(K$25,Sheet1!$P$3:$Q$41,2,FALSE)+K$26-VLOOKUP($C40,Sheet1!$S$3:$T$41,2,FALSE)+K$28 -> -3.08 | L40: =VLOOKUP(L$25,Sheet1!$P$3:$Q$41,2,FALSE)+L$26-VLOOKUP($C40,Sheet1!$S$3:$T$41,2,FALSE)+L$28 -> -4.29 | O40: 46053 | P40: =G34 -> -8.53 | Q40: =AVERAGE(P62:P63) -> 486.57544 | R40: =Q63 -> 212.24087 | S40: =P40+(Q40*21.47*70/700/100) -> 1.9167747 | U40: =7.25*R40*86.7/100/700 -> 1.9058472 | V40: =U40-S40 -> -0.010927502 | Y40: Sep SGC | Z40: -2.5 | BB40: =AVERAGE(BB37:BB39) -> -1.6433333 | BD40: =-AVERAGE(BD37:BD39) -> 0.75333333 | BE40: {=SUMPRODUCT(BE37:BE39,BA37:BA39/SUM(BA37:BA39))} -> 0.023333333
...

Sheet FWD
A1: 0 | B1: 1 | D1: 0.7 | M1: EUROPE vs BFOETM Cash (Cal Dated basis) | AF1: ASIA vs. Murban (m-1 Dubai basis)
J2: =J5-0.81 -> -4.13 | M2: First decade loaders | X2: Second/Third Decade | AN2: ** 2/3 of actual spread
C3: Freight | D3: Diff | E3: Load | F3: MEH | G3: WTI Sprds | H3: Arbs | I3: FOB Premium | J3: FOB WTI vs. Brent | K3: HTT-BK | M3: Arrival | N3: Freight | O3: DFLs | P3: WTI CIF Rdam | Q3: FOB Nsea | R3: X-Nsea Freight | S3: M1-M3 Brent | T3: DFLs | U3: Cash BFOETM | V3: (Closed)/Open | X3: Arrival | Y3: Brent Sprds | Z3: Freight | AA3: DFLs | AB3: =P3 -> WTI CIF Rdam | AC3: Cash BFOETM | AD3: (Closed)/Open | AF3: Arrival | AG3: Brent Sprds | AH3: Freight | AI3: B/D | AJ3: WTI CFR N.Asia vs DUB | AL3: Load | AM3: Murban FOB | AN3: Brent Sprds | AO3: Freight | AP3: B/D | AQ3: Arrival | AR3: MURBAN CFR N.Asia vs DUB | AT3: (Closed)/Open
C4: =E4 -> 46326 | D4: =EOMONTH(E4,-1)+1 -> 46296 | E4: =EOMONTH(E5,-1) -> 46326 | F4: =IFERROR(INDEX(Sheet1!$B$5:$N$27,MATCH(FWD!$F$3,Sheet1!$B$5:$B$27,0),MATCH(FWD!D4,Sheet1!$B$5:$N$5,0)),F5) -> 0.75 | G4: =BBG!F5-BBG!F6 -> 2 | H4: =IF(BBG!$D$5=BBG!$J$5,BBG!F6-BBG!L6,BBG!F6-BBG!L5) -> -9.61 | I4: =$B$6 -> 3 | J4: =SUM(F4:I4) -> -3.86 | M4: =EOMONTH(M5,-1) -> 46326 | N4: =VLOOKUP($C4,Freight!$A$3:$F$17,MATCH(FWD!$N$41,Freight!$A$3:$F$3,0),FALSE)+$B$7 -> 17.18865 | O4: =VLOOKUP(EOMONTH(M4,0),BBG!$N$63:$R$123,5,FALSE) -> 9.01 | P4: =J4+N4-O4 -> 4.31865 | R4: =VLOOKUP($C4,Freight!$A$3:$F$17,MATCH(FWD!$U$41,Freight!$A$3:$F$3,0),FALSE) -> 3.5918571 | S4: =INDEX(BBG!$H$4:$L$53,MATCH(FWD!$M4,BBG!$H$4:$H$53,0),MATCH("Settle",BBG!$H$4:$L$4,0))-INDEX(BBG!$H$4:$L$53,MATCH(FWD!$M6,BBG!$H$4:$H$53,0),MATCH("Settle",BBG!$H$4:$L$4,0)) -> #N/A | T4: =O4 -> 9.01 | U4: =SUM(Q4:S4)-T4 -> #N/A | V4: =IFERROR(U4-P4,"Expired") -> Expired | X4: =EOMONTH(M4,1) -> 46356 | Y4: =IF(BBG!$D$5=BBG!$J$5,BBG!L6-BBG!L7,BBG!L5-BBG!L6) -> 2.94 | Z4: =VLOOKUP($C4,Freight!$A$3:$F$17,MATCH(FWD!$N$41,Freight!$A$3:$F$3,0),FALSE)+$B$7 -> 17.18865 | AA4: =VLOOKUP(EOMONTH(X4,0),BBG!$N$63:$R$123,5,FALSE) -> 3.33 | AB4: =J4+Y4+Z4-AA4 -> 12.93865 | AC4: =U5 -> #N/A | AD4: =IFERROR(AC4-AB4,"Expired") -> Expired
A5: EFP | B5: 0.03 | C5: =E5 -> 46356 | D5: =EOMONTH(E5,-1)+1 -> 46327 | E5: =USG!E25 -> 46356 | F5: =+INDEX(Sheet1!$B$5:$N$27,MATCH(FWD!$F$3,Sheet1!$B$5:$B$27,0),MATCH(FWD!D5,Sheet1!$B$5:$N$5,0)) -> 1.35 | G5: =BBG!F5-BBG!F7 -> 3.69 | H5: =IF(BBG!$D$5=BBG!$J$5,BBG!F7-BBG!L7,BBG!F7-BBG!L6) -> -8.36 | I5: 0 | J5: =SUM(F5:I5) -> -3.32 | K5: =BBG!G64+FWD!F5 -> -5.6333 | M5: =EOMONTH(E5,0) -> 46356 | N5: =AVERAGE(VLOOKUP($C5,Freight!$A$3:$F$17,MATCH(FWD!$N$41,Freight!$A$3:$F$3,0),FALSE),VLOOKUP($C4,Freight!$A$3:$F$17,MATCH(FWD!$N$41,Freight!$A$3:$F$3,0),FALSE))+$B$7 -> 16.705575 | O5: =VLOOKUP(EOMONTH(M5,0),BBG!$N$63:$R$123,5,FALSE) -> 3.33 | P5: =J5+N5-O5 -> 10.055575 | Q5: =$B$5 -> 0.03 | R5: =VLOOKUP($C5,Freight!$A$3:$F$17,MATCH(FWD!$U$41,Freight!$A$3:$F$3,0),FALSE) -> 3.142875 | S5: =INDEX(BBG!$H$4:$L$53,MATCH(FWD!$M5,BBG!$H$4:$H$53,0),MATCH("Settle",BBG!$H$4:$L$4,0))-INDEX(BBG!$H$4:$L$53,MATCH(FWD!$M7,BBG!$H$4:$H$53,0),MATCH("Settle",BBG!$H$4:$L$4,0)) -> #N/A | T5: =O5 -> 3.33 | U5: =SUM(Q5:S5)-T5 -> #N/A | V5: =IFERROR(U5-P5,"Expired") -> Expired | X5: =EOMONTH(M5,1) -> 46387 | Y5: =IF(BBG!$D$5=BBG!$J$5,BBG!L7-BBG!L8,BBG!L6-BBG!L7) -> 2.24 | Z5: =VLOOKUP($C5,Freight!$A$3:$F$17,MATCH(FWD!$N$41,Freight!$A$3:$F$3,0),FALSE)+$B$7 -> 16.2225 | AA5: =VLOOKUP(EOMONTH(X5,0),BBG!$N$63:$R$123,5,FALSE) -> 2.61 | AB5: =J5+Y5+Z5-AA5 -> 12.5325 | AC5: =U6 -> 5.2938929 | AD5: =IFERROR(AC5-AB5,"Expired") -> -7.2386071 | AF5: =EOMONTH(E5,2) -> 46418 | AG5: =Y5 -> 2.24 | AH5: =VLOOKUP($C4,Freight!$A$3:$F$17,MATCH(FWD!$AH$41,Freight!$A$3:$F$3,0),FALSE) -> 26.349086 | AI5: =VLOOKUP(X5,BBG!$U$63:$Y$123,4,FALSE) -> 0.607 | AJ5: =AI5+J5+AH5+AG5 -> 25.876086 | AL5: =EOMONTH(E5,1) -> 46387 | AM5: =VLOOKUP(AL5,BBG!$AE$64:$AJ$100,6,FALSE) -> 9.5545 | AN5: =Y6 -> 1.7 | AO5: =VLOOKUP($C5,Freight!$A$3:$G$22,MATCH(FWD!$AO$41,Freight!$A$3:$G$3,0),FALSE) -> 27.22356 | AP5: =AI5 -> 0.607 | AQ5: =AF5 -> 46418 | AR5: =AM5+AN5+AO5+AP5 -> 39.08506 | AT5: =-(AJ5-AR5) -> 13.208974
A6: Cash | B6: =USG!D29 -> 3 | C6: =E6 -> 46387 | D6: =EOMONTH(E6,-1)+1 -> 46357 | E6: =EOMONTH(E5,1) -> 46387 | F6: =+INDEX(Sheet1!$B$5:$N$27,MATCH(FWD!$F$3,Sheet1!$B$5:$B$27,0),MATCH(FWD!D6,Sheet1!$B$5:$N$5,0)) -> 1 | G6: =BBG!F6-BBG!F8 -> 3.31 | H6: =IF(BBG!$D$5=BBG!$J$5,BBG!F8-BBG!L8,BBG!F8-BBG!L7) -> -7.74 | I6: =I5 -> 0 | J6: =SUM(F6:I6) -> -3.43 | K6: =BBG!G65+FWD!F6 -> -5.4855 | M6: =EOMONTH(E6,0) -> 46387 | N6: =AVERAGE(VLOOKUP($C6,Freight!$A$3:$F$17,MATCH(FWD!$N$41,Freight!$A$3:$F$3,0),FALSE),VLOOKUP($C5,Freight!$A$3:$F$17,MATCH(FWD!$N$41,Freight!$A$3:$F$3,0),FALSE))+$B$7 -> 14.5049 | O6: =VLOOKUP(EOMONTH(M6,0),BBG!$N$63:$R$123,5,FALSE) -> 2.61 | P6: =J6+N6-O6 -> 8.4649 | Q6: =$B$5 -> 0.03 | R6: =VLOOKUP($C6,Freight!$A$3:$F$17,MATCH(FWD!$U$41,Freight!$A$3:$F$3,0),FALSE) -> 2.6938929 | S6: =INDEX(BBG!$H$4:$L$53,MATCH(FWD!$M6,BBG!$H$4:$H$53,0),MATCH("Settle",BBG!$H$4:$L$4,0))-INDEX(BBG!$H$4:$L$53,MATCH(FWD!$M8,BBG!$H$4:$H$53,0),MATCH("Settle",BBG!$H$4:$L$4,0)) -> 5.18 | T6: =O6 -> 2.61 | U6: =SUM(Q6:S6)-T6 -> 5.2938929 | V6: =IFERROR(U6-P6,"Expired") -> -3.1710071 | X6: =EOMONTH(M6,1) -> 46418 | Y6: =IF(BBG!$D$5=BBG!$J$5,BBG!L8-BBG!L9,BBG!L7-BBG!L8) -> 1.7 | Z6: =VLOOKUP($C6,Freight!$A$3:$F$17,MATCH(FWD!$N$41,Freight!$A$3:$F$3,0),FALSE)+$B$7 -> 12.7873 | AA6: =VLOOKUP(EOMONTH(X6,0),BBG!$N$63:$R$123,5,FALSE) -> 2.03 | AB6: =J6+Y6+Z6-AA6 -> 9.0273 | AC6: =U7 -> 3.8458472 | AD6: =IFERROR(AC6-AB6,"Expired") -> -5.1814528 | AF6: =EOMONTH(E6,2) -> 46446 | AG6: =IF(BBG!$D$5=BBG!$J$5,BBG!L8-BBG!L10,BBG!L7-BBG!L9)*2/3 -> 2.12 | AH6: =VLOOKUP($C6,Freight!$A$3:$F$17,MATCH(FWD!$AH$41,Freight!$A$3:$F$3,0),FALSE)+$B$7 -> 19.152013 | AI6: =VLOOKUP(X6,BBG!$U$63:$Y$123,4,FALSE) -> 0.527 | AJ6: =AI6+J6+AH6+AG6 -> 18.369013 | AL6: =EOMONTH(E6,1) -> 46418 | AM6: =VLOOKUP(AL6,BBG!$AE$64:$AJ$100,6,FALSE) -> 3.444 | AN6: =Y7 -> 1.48 | AO6: =VLOOKUP($C6,Freight!$A$3:$G$22,MATCH(FWD!$AO$41,Freight!$A$3:$G$3,0),FALSE) -> 23.231644 | AP6: =AI6 -> 0.527 | AQ6: =AF6 -> 46446 | AR6: =AM6+AN6+AO6+AP6 -> 28.682644 | AT6: =-(AJ6-AR6) -> 10.313631
