Workbook
Name Index: Control!$Q$3:$U$62
Name Lightering: Control!$AB$3:$AF$69
Name Overages: Control!$E$17:$O$21
Name Overages_Column: Control!$E$17:$E$21
Name Overages_Row: Control!$E$17:$O$17
Name Port_Info: Control!$Q$3:$T$62
Name Port_List: Control!$B$3:$B$1048576
Name TVM_PortList: Control!$Q$3:$Q$62
Name Vessel_Minimum_MT: Control!$E$11:$O$15
Name Zones: Control!$B$3:$C$63

Sheet Control
W1: 2 | X1: 1
B2: Port/Zone Locator | E2: CANAL OPTIONS | H2: Overages | Q2: Port Info | W2: =W3-W7 -> -10 | X2: =X3-X7 -> 0 | AB2: Lightering/Reverse Lightering | AK2: Lightering/Reverse Lightering | AW2: Load | AY2: STS+Load | AZ2: Sail | BA2: Transit | BB2: Arrive | BC2: NOR+xx | BD2: BL+30 Pay Out | BE2: Domestic
B3: Saint John | C3: ECC | E3: NEW | H3: 0 | Q3: Port | R3: Outturn Losses | S3: EU TAX | T3: Payment | U3: Type | V3: Location | W3: =WTI!B9+30 -> 46366 | X3: =W3 -> 46366 | AB3: Port | AC3: Panamax | AD3: Aframax | AE3: Suezmax | AF3: VLCC | AG3: VLCC-MODA | AH3: VLCC-STG | AI3: Suezmax-MODA | AK3: Port | AL3: Panamax | AM3: Aframax | AN3: Suezmax | AO3: VLCC | AW3: =WTI!A9 -> 46334 | AX3: 700 | AY3: =AW3+1+3 -> 46338 | AZ3: =$AY$5 -> 46341 | BA3: 54 | BB3: =AZ3+BA3 -> 46395 | BC3: =BB3+T59 -> 46405 | BD3: =AW3+1+30 -> 46365 | BE3: =EOMONTH($AW$3,0)+20 -> 46376 | BG3: =BC3-BD3 -> 40 | BH3: =BC3-BE3 -> 29
B4: Augusta | C4: Med | E4: OLD | H4: 0.5 | Q4: Saint John | R4: 0 | S4: 0 | T4: 30 | U4: BL | V4: US | AB4: Liza FPSO | AC4: 0 | AD4: 0 | AE4: 0 | AF4: 0 | AG4: 0 | AH4: 0 | AI4: 0 | AK4: Augusta | AM4: 60 | AN4: 72.5 | AO4: 100 | AW4: =AW3+1.5 -> 46335.5 | AX4: 700 | AY4: =AW4+1+3 -> 46339.5 | AZ4: =$AY$5 -> 46341 | BA4: 54 | BB4: =AZ4+BA4 -> 46395 | BC4: =BB4+T60 -> 46405 | BD4: =AW4+1+30 -> 46366.5 | BE4: =EOMONTH($AW$3,0)+20 -> 46376 | BG4: =BC4-BD4 -> 38.5 | BH4: =BC4-BE4 -> 29
B5: Sao Sebastiao | C5: BAYOVAR+T | E5: Vessel List | Q5: Corpus Christi - MODA | R5: 1 | S5: 1 | T5: =T7 -> 30 | U5: BL | V5: US | W5: =W7 -> 46376 | X5: =X7 -> 46366 | AB5: Augusta | AC5: 0 | AD5: 0 | AE5: 0 | AF5: 0 | AG5: 0 | AH5: 0 | AI5: 0 | AK5: Pembroke | AW5: =AW4+1.5 -> 46337 | AX5: 700 | AY5: =AW5+1+3 -> 46341 | AZ5: =$AY$5 -> 46341 | BA5: 54 | BB5: =AZ5+BA5 -> 46395 | BC5: =BB5+T61 -> 46405 | BD5: =AW5+1+30 -> 46368 | BE5: =EOMONTH($AW$3,0)+20 -> 46376 | BG5: =BC5-BD5 -> 37 | BH5: =BC5-BE5 -> 29
B6: Corpus Christi - MODA | C6: USGC | E6: Panamax | Q6: Corpus Christi - STG | R6: 1 | S6: 1 | T6: 30 | U6: BL | V6: US | W6: =W5 -> 46376 | X6: =X5 -> 46366 | AB6: Sao Sebastiao | AC6: 0 | AD6: 0 | AE6: 1 | AF6: 1 | AG6: 1 | AH6: 1 | AI6: 1 | AK6: Rotterdam | AM6: 60 | AN6: =$AN$4 -> 72.5 | AO6: =$AO$4 -> 100 | BC6: =AVERAGE(BC3:BC5) -> 46405 | BD6: =AVERAGE(BD3:BD5) -> 46366.5 | BE6: =AVERAGE(BE3:BE5) -> 46376 | BF6: =BD6-BE6 -> -9.5 | BG6: =AVERAGE(BG3:BG5) -> 38.5 | BH6: =AVERAGE(BH3:BH5) -> 29
B7: Taiwan | C7: TAIWAN | E7: Aframax | Q7: Corpus Christi | R7: 0 | S7: 0 | T7: 30 | U7: BL | V7: US | W7: =W58 -> 46376 | X7: =WTI!B9+30 -> 46366 | AB7: Beaumont | AC7: 0 | AD7: 0 | AE7: 1 | AF7: 1 | AG7: 1 | AH7: 1 | AI7: 1 | AK7: Tranmere | AM7: 60 | AN7: =$AN$4 -> 72.5 | AO7: =$AO$4 -> 100
B8: Corpus Christi - STG | C8: USGC | E8: Suezmax | Q8: El Segundo | R8: 1 | S8: 1 | T8: 13 | U8: NOR | V8: US | AB8: Corpus Christi - STG | AC8: 0 | AD8: 0 | AE8: 0 | AF8: 0 | AG8: 0 | AH8: 0 | AI8: 0 | AK8: Trieste | AM8: 60 | AN8: =$AN$4 -> 72.5 | AO8: =$AO$4 -> 100 | AW8: Load | AY8: STS+Load | AZ8: Sail | BA8: Transit | BB8: Arrive | BC8: NOR+xx | BD8: BL+30 Pay Out | BE8: Domestic
B9: Chiba | C9: JAPAN | E9: VLCC | Q9: Canaport SPM | R9: 0 | S9: 0 | T9: 30 | U9: BL | V9: US | AB9: Chiba | AC9: 0 | AD9: 0 | AE9: 0 | AF9: 0 | AG9: 0 | AH9: 0 | AI9: 0 | AK9: Antwerp | AM9: 60 | AN9: =$AN$4 -> 72.5 | AO9: =$AO$4 -> 100 | AW9: =WTI!A15 -> 46334 | AX9: 1400 | AY9: =AW9+1+3 -> 46338 | AZ9: =$AY$5 -> 46341 | BA9: 54 | BB9: =AZ9+BA9 -> 46395 | BC9: =BB9+T65 -> 46395 | BD9: =AW9+1+30 -> 46365 | BE9: =EOMONTH($AW$3,0)+20 -> 46376 | BG9: =BC9-BD9 -> 30 | BH9: =BC9-BE9 -> 19
B10: Chiriqui Grande | C10: CARIBS | Q10: Houston | R10: 1 | S10: 0 | T10: 30 | U10: BL | V10: US | AB10: Chiriqui Grande | AC10: 0 | AD10: 0 | AE10: 0 | AF10: 0 | AG10: 0 | AH10: 0 | AI10: 0 | AK10: Finnart | AM10: 60 | AN10: =$AN$4 -> 72.5 | AO10: =$AO$4 -> 100 | AW10: =AW9+1.5 -> 46335.5 | AX10: 700 | AY10: =AW10+1+3 -> 46339.5 | AZ10: =$AY$5 -> 46341 | BA10: 54 | BB10: =AZ10+BA10 -> 46395 | BC10: =BB10+T66 -> 46395 | BD10: =AW10+1+30 -> 46366.5 | BE10: =EOMONTH($AW$3,0)+20 -> 46376 | BG10: =BC10-BD10 -> 28.5 | BH10: =BC10-BE10 -> 19
B11: Conchan/Talara | C11: CONCHAN+T | E11: Vessel Minimum MT | F11: Covenas | G11: Chiriqui Grande | H11: Puerto Armuelles | I11: Corpus Christi | J11: Corpus Christi - MODA | K11: Rotterdam-STS | L11: La Paloma (Alpha Ligh. Zone) | M11: Liza FPSO | N11: Loop | O11: Nederland | Q11: LA+SF | R11: 1 | S11: 1 | T11: 13 | U11: NOR | V11: US | AB11: Conchan/Talara | AC11: 0 | AD11: 0 | AE11: 0 | AF11: 0 | AG11: 0 | AH11: 0 | AI11: 0 | AK11: Whitegate
B12: Corpus Christi | C12: USGC | E12: Panamax | F12: 50000 | G12: =$F12 -> 50000 | H12: =$I12 -> 50000 | I12: 50000 | J12: 50000 | K12: =F12 -> 50000 | L12: =I12 -> 50000 | M12: 50000 | N12: =J12 -> 50000 | O12: 50000 | Q12: Loop | R12: 1 | S12: 0 | T12: 30 | U12: BL | V12: US | AB12: Corpus Christi | AC12: 0 | AD12: 0 | AE12: 1 | AF12: 1 | AG12: 1 | AH12: 1 | AI12: 1 | AK12: Gdansk | AM12: 60 | AN12: =$AN$4 -> 72.5 | AO12: =$AO$4 -> 100 | BC12: =AVERAGE(BC9:BC11) -> 46395 | BD12: =AVERAGE(BD9:BD11) -> 46365.75 | BE12: =AVERAGE(BE9:BE11) -> 46376 | BF12: =BD12-BE12 -> -10.25 | BG12: =AVERAGE(BG9:BG11) -> 29.25 | BH12: =AVERAGE(BH9:BH11) -> 19
B13: Covenas | C13: CARIBS | E13: Aframax | F13: 70000 | G13: =$F13 -> 70000 | H13: =$I13 -> 70000 | I13: 70000 | J13: 70000 | K13: 80000 | L13: =I13 -> 70000 | M13: 70000 | N13: =J13 -> 70000 | O13: 70000 | Q13: Los Angeles | R13: 1 | S13: 1 | T13: 13 | U13: NOR | V13: US | AB13: Covenas | AC13: 0 | AD13: 0 | AE13: 0 | AF13: 0 | AG13: 0 | AH13: 0 | AI13: 0 | AK13: Lagos | AM13: 60 | AN13: =$AN$4 -> 72.5 | AO13: =$AO$4 -> 100
B14: El Segundo | C14: USWC | E14: Suezmax | F14: 150000 | G14: 150000 | H14: =$I14 -> 145000 | I14: 145000 | J14: 145000 | K14: 145000 | L14: =I14 -> 145000 | M14: 145000 | N14: =J14 -> 145000 | O14: 130000 | Q14: Paulsboro | R14: 0 | S14: 0 | T14: 30 | U14: BL | V14: US | AB14: El Segundo | AC14: 0 | AD14: 0 | AE14: 0 | AF14: 0 | AG14: 0 | AH14: 0 | AI14: 0 | AK14: Sines | AM14: 60 | AN14: =$AN$4 -> 72.5 | AO14: =$AO$4 -> 100
B15: Quebec | C15: ECC | E15: VLCC | F15: 270000 | G15: =$F15 -> 270000 | H15: =$I15 -> 270000 | I15: 270000 | J15: 270000 | K15: =F15 -> 270000 | L15: =I15 -> 270000 | M15: 270000 | N15: =J15 -> 270000 | O15: 270000 | Q15: Quebec | R15: 0 | S15: 0 | T15: 30 | U15: BL | V15: US | AB15: ES+Richmond | AC15: 0 | AD15: 0 | AE15: 0 | AF15: 0 | AG15: 0 | AH15: 0 | AI15: 0 | AK15: Milazzo | AM15: 60 | AN15: =$AN$4 -> 72.5 | AO15: =$AO$4 -> 100
B16: Rotterdam-STS | C16: Nsea | Q16: Pascagoula | R16: 1 | S16: 0 | T16: 13 | U16: NOR | V16: US | AB16: Esmeraldas | AC16: 0 | AD16: 0 | AE16: 0 | AF16: 0 | AG16: 0 | AH16: 0 | AI16: 0 | AK16: Butinge | AM16: 60 | AN16: =$AN$4 -> 72.5 | AO16: =$AO$4 -> 100
B17: Houston | C17: USGC | E17: Overages | F17: Covenas | G17: Chiriqui Grande | H17: Puerto Armuelles | I17: Corpus Christi | J17: Corpus Christi - MODA | K17: =K11 -> Rotterdam-STS | L17: La Paloma (Alpha Ligh. Zone) | M17: =M11 -> Liza FPSO | N17: Loop | O17: =O11 -> Nederland | Q17: Omisalj | R17: 0 | S17: 0 | T17: 30 | U17: BL | V17: South America | W17: =$W$7 -> 46376 | X17: =$X$7 -> 46366 | Y17: =X17-W17 -> -10 | AB17: Corpus Christi | AC17: 0 | AD17: 0 | AE17: 1 | AF17: 1 | AG17: 1 | AH17: 1 | AI17: 1 | AK17: Porvoo | AM17: 60 | AN17: =$AN$4 -> 72.5 | AO17: =$AO$4 -> 100 | AS17: Load | AT17: =WTI!A9 -> 46334 | AX17: 9 | AY17: 700 | BA17: 0 | BB17: 700
B18: Jamnagar | C18: INDIA | E18: Panamax | F18: 0.5 | G18: =$F18 -> 0.5 | H18: =$I18 -> 0.5 | I18: 0.5 | J18: 0.5 | K18: 0.5 | L18: =I18 -> 0.5 | M18: 0.5 | N18: =J18 -> 0.5 | O18: 50000 | Q18: Sao Sebastiao | R18: 0 | S18: 0 | T18: 13 | U18: NOR | V18: South America | AB18: Jamnagar | AC18: 0 | AD18: 0 | AE18: 0 | AF18: 0 | AG18: 0 | AH18: 0 | AI18: 0 | AK18: La Coruña | AM18: 60 | AN18: =$AN$4 -> 72.5 | AO18: =$AO$4 -> 100 | AS18: Transit | AT18: =WTI!BC43+AY20+1 -> 59 | AX18: 6 | AY18: 700 | BA18: 3 | BB18: 1400
B19: Omisalj | C19: Med | E19: Aframax | F19: 0 | G19: =$F19 -> 0 | H19: =$K19 -> 0.5 | I19: 0 | J19: 0 | K19: 0.5 | L19: =I19 -> 0 | M19: 0 | N19: =J19 -> 0 | O19: 70000 | Q19: Chiriqui Grande | R19: 1 | S19: 0 | T19: 13 | U19: NOR | V19: South America | AB19: Kingston | AC19: 0 | AD19: 0 | AE19: 0 | AF19: 0 | AG19: 0 | AH19: 0 | AI19: 0 | AK19: Algericas | AM19: 60 | AN19: =$AN$4 -> 72.5 | AO19: =$AO$4 -> 100 | AS19: NOR | AT19: =AT17+AT18 -> 46393 | AX19: 3 | AY19: 700 | BB19: {=SUMPRODUCT(BA17:BA18,BB17:BB18/SUM(BB17:BB18))} -> 2
B20: La Paloma (Alpha Ligh. Zone) | C20: LATAM EAST | E20: Suezmax | F20: 0.5 | G20: =$F20 -> 0.5 | H20: =$I20 -> 0.5 | I20: 0.5 | J20: 0.5 | K20: 0.5 | L20: =I20 -> 0.5 | M20: 0.5 | N20: =J20 -> 0.5 | O20: 130000 | Q20: Conchan/Talara | R20: 0 | S20: 0 | T20: 17 | U20: NOR | V20: South America | AB20: La Paloma (Alpha Ligh. Zone) | AC20: 0 | AD20: 0 | AE20: 0 | AF20: 0 | AG20: 0 | AH20: 0 | AI20: 0 | AK20: Wilhelmshaven | AM20: 60 | AN20: =$AN$4 -> 72.5 | AO20: =$AO$4 -> 100 | AS20: xxx | AT20: =+AT19+T59 -> 46403 | AU20: =AT17+1+30 -> 46365 | AV20: =AT20-AU20 -> 38 | AY20: {=SUMPRODUCT(AX17:AX19,AY17:AY19/SUM(AY17:AY19))} -> 6
B21: La Pampilla | C21: PAMPILLA | E21: VLCC | F21: 0.5 | G21: =$F21 -> 0.5 | H21: =$I21 -> 0.5 | I21: 0.5 | J21: 0.5 | K21: 0.5 | L21: =I21 -> 0.5 | M21: 0.5 | N21: =J21 -> 0.5 | O21: 270000 | Q21: Covenas | R21: 1 | S21: 0 | T21: 15 | U21: NOR | V21: South America | AB21: La Pampilla | AC21: 0 | AD21: 0 | AE21: 0 | AF21: 0 | AG21: 0 | AH21: 0 | AI21: 0 | AK21: Kalundborg | AM21: 60 | AN21: =$AN$4 -> 72.5 | AO21: =$AO$4 -> 100 | AU21: =$W$17 -> 46376 | AV21: =AT20-AU21 -> 27
B22: LA+SF | C22: USWC | Q22: Rotterdam-STS | R22: 0 | S22: 0 | T22: 15 | U22: BL | V22: South America | AB22: LA+SF | AC22: 0 | AD22: 0 | AE22: 0 | AF22: 0 | AG22: 0 | AH22: 0 | AI22: 0 | AK22: Aliaga | AM22: 60 | AN22: =$AN$4 -> 72.5 | AO22: =$AO$4 -> 100 | AZ22: Load | BA22: STS | BB22: Sail | BC22: Payment
B23: Los Angeles | C23: USWC | Q23: Omisalj | R23: 1 | S23: 0 | T23: 30 | U23: BL | V23: South America | AB23: Los Angeles | AC23: 0 | AD23: 0 | AE23: 0 | AF23: 0 | AG23: 0 | AH23: 0 | AI23: 0 | AK23: Botas Ceyhan | AM23: 60 | AN23: =$AN$4 -> 72.5 | AO23: =$AO$4 -> 100 | AS23: Chiba | AT23: =AT24-2 -> 36.5 | AY23: 700 | AZ23: 45734 | BA23: 3 | BB23: =BA23+AZ23 -> 45737
B24: Ningbo | C24: KOREA | E24: Max Load | F24: Beaumont | G24: Corpu Christi | H24: Houston | I24: LOOP | J24: Puerto Armuelles | Q24: La Paloma (Alpha Ligh. Zone) | R24: 1 | S24: 0 | T24: 30 | U24: NOR | V24: South America | AB24: Ningbo | AC24: 0 | AD24: 0 | AE24: 0 | AF24: 0 | AG24: 0 | AH24: 0 | AI24: 0 | AK24: Agioi Theodori | AM24: 60 | AN24: =$AN$4 -> 72.5 | AO24: =$AO$4 -> 100 | AS24: Daesan | AT24: =$BG$6 -> 38.5 | AY24: 700 | AZ24: =+AZ23+2 -> 45736 | BA24: 3 | BB24: =BA24+AZ24 -> 45739
B25: Paulsboro | C25: USGC | E25: Panamax | F25: 490000 | G25: 490000 | H25: 490000 | I25: 490000 | Q25: La Pampilla | R25: 0 | S25: 0 | T25: 13 | U25: NOR | V25: South America | AB25: Paulsboro | AC25: 0 | AD25: 0 | AE25: 0 | AF25: 0 | AG25: 0 | AH25: 0 | AI25: 0 | AK25: Thessalonski | AM25: 60 | AN25: =$AN$4 -> 72.5 | AO25: =$AO$4 -> 100 | AS25: Jamnagar | AT25: =AT27-3 -> 25.5 | AY25: 700 | AZ25: =+AZ24+2 -> 45738 | BA25: 3 | BB25: =BA25+AZ25 -> 45741
B26: Puerto Armuelles | C26: Panama WC | E26: Aframax | F26: 500000 | G26: 750000 | H26: 700000 | I26: 750000 | Q26: Liza FPSO | R26: 1 | S26: 0 | T26: 30 | U26: BL | V26: South America | AB26: Puerto Armuelles | AC26: 0 | AD26: 0 | AE26: 0 | AF26: 0 | AG26: 0 | AH26: 0 | AI26: 0 | AK26: Odessa | AM26: 60 | AN26: =$AN$4 -> 72.5 | AO26: =$AO$4 -> 100 | AS26: Ningbo | AT26: =AT23-1 -> 35.5
B27: Quintero (MB) | C27: LATAM WEST | E27: Suezmax | F27: 700000 | G27: 850000 | H27: 0 | I27: 1000000 | Q27: Mamonal | R27: 1 | S27: 0 | T27: 13 | U27: NOR | V27: South America | AB27: Quintero (MB) | AC27: 0 | AD27: 0 | AE27: 0 | AF27: 0 | AG27: 0 | AH27: 0 | AI27: 0 | AK27: Savona | AM27: 60 | AN27: =$AN$4 -> 72.5 | AO27: =$AO$4 -> 100 | AS27: Singapore | AT27: =AT24-10 -> 28.5
B28: Quintero (Port) | C28: LATAM WEST | E28: VLCC | F28: 0 | G28: 1250000 | H28: 0 | I28: 2000000 | Q28: Puerto Armuelles | R28: 1 | S28: 0 | T28: 15 | U28: BL | V28: South America | AB28: Quintero (Port) | AC28: 0 | AD28: 0 | AE28: 0 | AF28: 0 | AG28: 0 | AH28: 0 | AI28: 0 | AK28: Midla | AM28: 60 | AN28: =$AN$4 -> 72.5 | AO28: =$AO$4 -> 100 | AS28: Taiwan | AT28: =AT24-3 -> 35.5
B29: Pembroke | C29: Nsea | E29: STS Size | F29: =F26 -> 500000 | G29: =G26 -> 750000 | H29: =H26 -> 700000 | I29: =I26 -> 750000 | Q29: Quintero (MB) | R29: 0 | S29: 0 | T29: 30 | U29: BL | V29: South America | AB29: Richmond | AC29: 0 | AD29: 0 | AE29: 0 | AF29: 0 | AG29: 0 | AH29: 0 | AI29: 0 | AK29: Rotterdam-CASH | AM29: 60 | AN29: =$AN$4 -> 72.5 | AO29: =$AO$4 -> 100
B30: Rotterdam | C30: Nsea | Q30: Quintero (Port) | R30: 0 | S30: 0 | T30: 30 | U30: BL | V30: South America | AB30: Rotterdam | AC30: 0 | AD30: 0 | AE30: 0 | AF30: 0 | AG30: 0 | AH30: 0 | AI30: 0
B31: Canaport SPM | C31: ECC | E31: Load | F31: 2000000 | G31: =F31-G28 -> 750000 | H31: =G31/J28 -> #DIV/0! | Q31: San Vicente | R31: 1 | S31: 0 | T31: 13 | U31: NOR | V31: Europe | AB31: San Francisco | AC31: 0 | AD31: 0 | AE31: 0 | AF31: 0 | AG31: 0 | AH31: 0 | AI31: 0
B32: San Vicente | C32: LATAM WEST | E32: STS Size | F32: 700000 | H32: =COUNT(H31) -> 0 | P32: 1 | Q32: Augusta | R32: 0 | S32: 0 | T32: 30 | U32: BL | V32: Europe | W32: =$W$7 -> 46376 | X32: =$X$7 -> 46366 | Y32: =X32-W32 -> -10 | AB32: San Vicente | AC32: 0 | AD32: 0 | AE32: 0 | AF32: 0 | AG32: 0 | AH32: 0 | AI32: 0
B33: Trieste | C33: Med | Q33: Pembroke | R33: 0 | S33: 0 | T33: 30 | U33: BL | V33: Europe | W33: =$W$7 -> 46376 | X33: =$X$7 -> 46366 | Y33: =X33-W33 -> -10 | AB33: Trieste | AC33: 0 | AD33: 0 | AE33: 0 | AF33: 0 | AG33: 0 | AH33: 0 | AI33: 0
B34: Tranmere | C34: Nsea | P34: 1 | Q34: Rotterdam | R34: 0 | S34: 0 | T34: 30 | U34: BL | V34: Europe | W34: =$W$7 -> 46376 | X34: =$X$7 -> 46366 | Y34: =X34-W34 -> -10 | AB34: Tranmere | AC34: 0 | AD34: 0 | AE34: 0 | AF34: 0 | AG34: 0 | AH34: 0 | AI34: 0
B35: Mamonal | C35: CARIBS | P35: 1 | Q35: Tranmere | R35: 0 | S35: 0 | T35: 30 | U35: BL | V35: Asia | W35: =$W$7 -> 46376 | X35: =$X$7 -> 46366 | Y35: =X35-W35 -> -10 | AB35: Mamonal | AC35: 0 | AD35: 0 | AE35: 0 | AF35: 0 | AG35: 0 | AH35: 0 | AI35: 0 | AS35: TVM Calcs | AT35: 8 | AU35: 2 | AW35: 10
B36: Liza FPSO | C36: CARIBS | P36: 1 | Q36: Trieste | R36: 0 | S36: 0 | T36: 30 | U36: =U32 -> BL | V36: Asia | W36: =$W$7 -> 46376 | X36: =$X$7 -> 46366 | Y36: =X36-W36 -> -10 | AB36: =Q59 -> Daesan | AC36: 0 | AD36: 0 | AE36: 0 | AF36: 0 | AG36: 0 | AH36: 0 | AI36: 0 | AT36: ATA Sourced | AU36: BL+30 | AX36: ATA TVM | AY36: Ext. TVM
B37: LOOP | C37: USGC | P37: 1 | Q37: Antwerp | R37: 0 | S37: 0 | T37: 30 | U37: BL | V37: Asia | W37: =$W$7 -> 46376 | X37: =$X$7 -> 46366 | Y37: =X37-W37 -> -10 | AB37: Loop | AC37: 0 | AD37: 0 | AE37: 0 | AF37: 0 | AG37: 0 | AH37: 0 | AI37: 0 | AS37: Chiba | AT37: =AT38-2 -> 25 | AU37: =Control!AT23 -> 36.5 | AV37: =SUMPRODUCT(AT37:AU37,$AT$35:$AU$35/SUM($AT$35:$AU$35)) -> 27.3 | AX37: =$AX$38 -> -9.5 | AY37: =AU37 -> 36.5 | BE37: BL Date | BF37: Transit | BG37: NOR | BH37: 10
B38: Daesan | C38: KOREA | P38: 1 | Q38: Finnart | R38: 0 | S38: 0 | T38: 30 | U38: BL | V38: Asia | W38: =$W$7 -> 46376 | X38: =$X$7 -> 46366 | Y38: =X38-W38 -> -10 | AB38: Daesan | AC38: 0 | AD38: 0 | AE38: 0 | AF38: 0 | AG38: 0 | AH38: 0 | AI38: 0 | AS38: Daesan | AT38: =AV21 -> 27 | AU38: =Control!AT24 -> 38.5 | AV38: =SUMPRODUCT(AT38:AU38,$AT$35:$AU$35/SUM($AT$35:$AU$35)) -> 29.3 | AX38: =BF6 -> -9.5 | AY38: =AU38 -> 38.5 | BD38: 45734 | BE38: =BD38+3 -> 45737 | BF38: =54+9 -> 63 | BG38: =BD38+BF38 -> 45797 | BH38: =BG38+10 -> 45807
B39: Singapore | C39: Singapore | Q39: Whitegate | R39: 0 | S39: 0 | T39: 30 | U39: BL | V39: Asia | W39: =$W$7 -> 46376 | X39: =$X$7 -> 46366 | Y39: =X39-W39 -> -10 | AB39: Singapore | AC39: 0 | AD39: 0 | AE39: 0 | AF39: 0 | AG39: 0 | AH39: 0 | AI39: 0 | AS39: Jamnagar | AT39: =AT41-3 -> 14 | AU39: =Control!AT25 -> 25.5 | AV39: =SUMPRODUCT(AT39:AU39,$AT$35:$AU$35/SUM($AT$35:$AU$35)) -> 16.3 | AX39: =$AX$38 -> -9.5 | AY39: =AU39 -> 25.5
B40: Nederland | C40: USGC | P40: 1 | Q40: Gdansk | R40: 1 | S40: 0 | T40: 30 | U40: BL | W40: =$W$7 -> 46376 | X40: =$X$7 -> 46366 | Y40: =X40-W40 -> -10 | AB40: Augusta | AC40: 0 | AD40: 0 | AE40: 0 | AF40: 0 | AG40: 0 | AH40: 0 | AI40: 0 | AS40: Ningbo | AT40: =AT37-1 -> 24 | AU40: =Control!AT26 -> 35.5 | AV40: =SUMPRODUCT(AT40:AU40,$AT$35:$AU$35/SUM($AT$35:$AU$35)) -> 26.3 | AX40: =$AX$38 -> -9.5 | AY40: =AU40 -> 35.5 | BD40: BL+30 | BE40: =BD38+30 -> 45764 | BF40: =BF41 -> 45807 | BG40: =BF40-BE40 -> 43
...

Sheet WTI
W1: =INDEX(Vessel_Minimum_MT,MATCH(Y1,Control!$E$11:$E$15,0),MATCH(V1,Control!$E$11:$J$11,0)) -> #N/A | AI1: =AF1*VLOOKUP($Y1,Control!$F$75:$H$79,3,FALSE)/$AB1 -> #N/A
D2: WTI MIDLAND
D3: FOB Corpus Christi | Y3: -3.6 | AD3: 1400 | AE3: 0.8 | AJ3: ATA TVM | AK3: 0 | AL3: 1 | AV3: ICE Brent | AW3: Dubai | AX3: Dated | BC3: 1 | BD3: 46296 | BE3: =EOMONTH(BD3,1) -> 46356 | BF3: =EOMONTH(BE3,1) -> 46387 | BG3: =EOMONTH(BF3,1) -> 46418 | BH3: =EOMONTH(BG3,1) -> 46446 | BJ3: 46101 | BL3: 4480 | BO3: 25
D4: MEH/Brent | T4: Leave | U4: Payment Terms | V4: Payment Date | AD4: 700 | AE4: 0.1 | AJ4: Ext. TVM | AK4: 1 | AV4: 0 | AW4: 1 | AX4: 2 | AZ4: <----- | BC4: Spreads | BD4: 3.75 | BE4: 2.9 | BF4: 2.25 | BG4: 1.9 | BH4: 1.7 | BJ4: =BJ3+19 -> 46120 | BL4: 4867 | BO4: 15
D5: EFP | T5: =A9 -> 46334 | U5: 13 | V5: =T5+BC31+U5 -> 46396 | AE5: {=SUMPRODUCT(AE3:AE4,AD3:AD4/SUM(AD3:AD4))} -> 0.56666667 | AV5: ICE Brent | AW5: Dubai | AX5: Dated | BC5: Dated | BD5: 13.5 | BE5: 5.28 | BF5: 3.98 | BG5: 2.93 | BH5: 2.45 | BJ5: =BJ4-30 -> 46090 | BL5: 3665 | BO5: =AVERAGE(BO3:BO4) -> 20
AZ6: EXTAP Toggle | BC6: Dubai | BD6: -5.25 | BE6: -1.7 | BF6: -0.9 | BG6: -0.7 | BH6: -0.65 | BI6: 0.17 | BL6: =AVERAGE(BL3:BL4) -> 4673.5
BC7: CMA | BD7: 21 | BE7: 22 | BF7: 23 | BG7: 21 | BH7: 22
A8: Load Window | Y8: CORPUS-ASIA | BC8: 1 | BD8: --> 1, Natural Arrival ; 0 M-1 | BH8: 1 | BL8: =BL6/30 -> 155.78333
A9: 46334 | B9: =A9+2 -> 46336 | D9: STS Time | E9: Depart | T9: Flat | U9: Overages | V9: Loadport | W9: Vessel MT | X9: Actual MT | Y9: Vessel | Z9: Destination | AA9: Route | AB9: Volume | AC9: Current WS Rate | AD9: WS Rate Call | AE9: Destination Freight | AF9: Demurrage | AG9: ATA TVM | AH9: Ext. TVM | AI9: Demurrage $ | AJ9: TVM | AL9: STS | AM9: Wharfage | AN9: Panama Canal | AO9: Insurance | AP9: Inspection | AQ9: Outturn Losses | AR9: EU TAX | AS9: Other costs | AT9: Pipeline Fee | AU9: Total Secondary Costs | AV9: All In Cost | AW9: Structure | AX9: Basis | AY9: Brt Swap | AZ9: DES Price | BC9: Transit Time | BD9: Arrival Window | BF9: Basis | BG9: Pricing Month | BH9: Delivery Month
A10: =+$A$9 -> 46334 | B10: =IF(ISBLANK(A10),"",A10+2) -> 46336 | D10: =IF(AL10=0,0,VLOOKUP(Y10,Control!$G$41:$J$44,4,FALSE)) -> 0 | T10: #N/A | U10: =INDEX(Control!$E$17:$J$21,MATCH(Y10,Control!$E$17:$E$21,0),MATCH(V10,Control!$E$17:$J$17,0)) -> 0.5 | V10: Puerto Armuelles | W10: =INDEX(Vessel_Minimum_MT,MATCH(Y10,Control!$E$11:$E$15,0),MATCH(V10,Control!$E$11:$J$11,0)) -> 50000 | X10: =AB10/Control!$D$84 -> 62424.328 | Y10: Panamax | Z10: Quintero (MB) | AA10: =IF(Z10=V10,"",CONCATENATE(CONCATENATE(VLOOKUP(V10,Zones,2,FALSE),"/",VLOOKUP(Z10,Zones,2,FALSE)))) -> Panama WC/LATAM WEST | AB10: 485000 | AC10: 245 | AD10: 100 | AE10: =IF(AD10>1000,IF(AD10=0,AD10,AD10)/AB10,((W10*T10*(IF(AD10=0,AD10,AD10)/100))+IF(X10<W10,0,(X10-W10)*T10*IF(AD10=0,AD10,AD10)/100*U10))/AB10) -> #N/A | AF10: 5 | AG10: =IF(INDEX(Index,MATCH(Z10,TVM_PortList,0),MATCH("Type",Control!$Q$3:$U$3,0))="BL",INDEX(Index,MATCH(Z10,TVM_PortList,0),MATCH("Payment",Control!$Q$3:$U$3,0))-INDEX(Index,MATCH(V10,TVM_PortList,0),MATCH("Payment",Control!$Q$3:$U$3,0)),BC10+INDEX(Index,MATCH(Z10,TVM_PortList,0),MATCH("Payment",Control!$Q$3:$U$3,0))-INDEX(Index,MATCH(V10,TVM_PortList,0),MATCH("Payment",Control!$Q$3:$U$3,0))) -> 15 | AI10: =AF10*VLOOKUP($Y10,Control!$F$75:$H$79,3,FALSE)/$AB10 -> 0.46391753 | AJ10: =IF(AG10<0,0,$AG10*Control!$D$77) -> 0.19554247 | AL10: =INDEX(Lightering,MATCH($V10,Control!$AB$3:$AB$29,0),MATCH(WTI!$Y10,Control!$AB$3:$AF$3,0))*($AB10/Control!$D$85)*Control!$H$90/$AB10 -> 0 | AM10: =IF(I10="Corpus Christi",Control!$D$76,0) -> 0 | AN10: 0 | AO10: =Control!$D$78 -> 0 | AP10: =Control!$D$79 -> 0.0673 | AQ10: =IF(INDEX(Control!$Q$3:$S$62,MATCH($Z10,Control!$Q$3:$Q$62,0),MATCH(AQ$9,Control!$Q$3:$S$3,0))=1,Control!$D$81*Control!$E$81,0) -> 0 | AR10: =IF(INDEX(Control!$Q$3:$S$62,MATCH($Z10,Control!$Q$3:$Q$62,0),MATCH(AR$9,Control!$Q$3:$S$3,0))=1,Control!$D$82/$AB10,0) -> 0 | AT10: =IF(AND(L10="Chiriqui Grande",V10="Puerto Armuelles"),Control!$G$93,0) -> 0 | AU10: =SUM(AI10:AT10) -> 0.72675999 | AV10: =+R10+AE10+AU10 -> #N/A | AW10: =IF((MONTH(A10)=MONTH(BE10)),0,IF((MONTH(BE10)+12)-(MONTH(A10)+12)>1,VLOOKUP("Spreads",$BC$3:$BG$4,MATCH(EOMONTH(BE10,0),$BC$3:$BG$3,0),FALSE)+VLOOKUP("Spreads",$BC$3:$BG$4,MATCH(EOMONTH(BE10,-1),$BC$3:$BG$3,0),FALSE),VLOOKUP("Spreads",$BC$3:$BG$4,MATCH(EOMONTH(A10,0),$BC$3:$BG$3,0)))) -> #N/A | AX10: 0 | AZ10: =$Y$3+AV10+AW10+AX10 -> #N/A | BC10: =INDEX('[1]Transit Time'!$A:$DZ,MATCH(I10,'[1]Transit Time'!$A:$A,0),MATCH(L10,'[1]Transit Time'!$A$1:$DZ$1,0))+INDEX('[1]Transit Time'!$A:$DZ,MATCH(L10,'[1]Transit Time'!$A:$A,0),MATCH(V10,'[1]Transit Time'!$A$1:$DZ$1,0))+INDEX('[1]Transit Time'!$A:$DZ,MATCH(V10,'[1]Transit Time'!$A:$A,0),MATCH(Z10,'[1]Transit Time'!$A$1:$DZ$1,0)) -> #N/A | BD10: =IF(ISBLANK(A10),"",A10+$BC10+D10) -> #N/A | BE10: =IF(ISBLANK(B10),"",B10+$BC10) -> #N/A
A11: =+$A$10 -> 46334 | B11: =IF(ISBLANK(A11),"",A11+2) -> 46336 | D11: =IF(AL11=0,0,VLOOKUP(Y11,Control!$G$41:$J$44,4,FALSE)) -> 0 | T11: =INDEX('[2]Flat Rates 2025'!$A:$DZ,MATCH(V11,'[2]Flat Rates 2025'!$A:$A,0),MATCH(Z11,'[2]Flat Rates 2025'!$A$1:$DZ$1,0)) -> 10.63 | U11: =INDEX(Control!$E$17:$J$21,MATCH(Y11,Control!$E$17:$E$21,0),MATCH(V11,Control!$E$17:$J$17,0)) -> 0.5 | V11: Puerto Armuelles | W11: =INDEX(Vessel_Minimum_MT,MATCH(Y11,Control!$E$11:$E$15,0),MATCH(V11,Control!$E$11:$J$11,0)) -> 70000 | X11: =AB11/Control!$D$84 -> 96532.466 | Y11: Aframax | Z11: Quintero (MB) | AA11: =IF(Z11=V11,"",CONCATENATE(CONCATENATE(VLOOKUP(V11,Zones,2,FALSE),"/",VLOOKUP(Z11,Zones,2,FALSE)))) -> Panama WC/LATAM WEST | AB11: 750000 | AC11: 155 | AE11: =IF(AC11>1000,IF(AD11=0,AC11,AD11)/AB11,((W11*T11*(IF(AD11=0,AC11,AD11)/100))+IF(X11<W11,0,(X11-W11)*T11*IF(AD11=0,AC11,AD11)/100*U11))/AB11) -> 1.8292481 | AF11: 0 | AG11: =IF(INDEX(Index,MATCH(Z11,TVM_PortList,0),MATCH("Type",Control!$Q$3:$U$3,0))="BL",INDEX(Index,MATCH(Z11,TVM_PortList,0),MATCH("Payment",Control!$Q$3:$U$3,0))-INDEX(Index,MATCH(V11,TVM_PortList,0),MATCH("Payment",Control!$Q$3:$U$3,0)),BC11+INDEX(Index,MATCH(Z11,TVM_PortList,0),MATCH("Payment",Control!$Q$3:$U$3,0))-INDEX(Index,MATCH(V11,TVM_PortList,0),MATCH("Payment",Control!$Q$3:$U$3,0))) -> 15 | AI11: =AF11*VLOOKUP($Y11,Control!$F$75:$H$79,3,FALSE)/$AB11 -> 0 | AJ11: =IF(AG11<0,0,$AG11*Control!$D$77) -> 0.19554247 | AL11: =INDEX(Lightering,MATCH($V11,Control!$AB$3:$AB$29,0),MATCH(WTI!$Y11,Control!$AB$3:$AF$3,0))*($AB11/Control!$D$85)*Control!$H$90/$AB11 -> 0 | AM11: =IF(I11="Corpus Christi",Control!$D$76,0) -> 0 | AN11: 0 | AO11: =Control!$D$78 -> 0 | AP11: =Control!$D$79 -> 0.0673 | AQ11: =IF(INDEX(Control!$Q$3:$S$62,MATCH($Z11,Control!$Q$3:$Q$62,0),MATCH(AQ$9,Control!$Q$3:$S$3,0))=1,Control!$D$81*Control!$E$81,0) -> 0 | AR11: =IF(INDEX(Control!$Q$3:$S$62,MATCH($Z11,Control!$Q$3:$Q$62,0),MATCH(AR$9,Control!$Q$3:$S$3,0))=1,Control!$D$82/$AB11,0) -> 0 | AT11: =IF(AND(L11="Chiriqui Grande",V11="Puerto Armuelles"),Control!$G$93,0) -> 0 | AU11: =SUM(AI11:AT11) -> 0.26284247 | AV11: =+R11+AE11+AU11 -> 2.0920906 | AW11: =IF((MONTH(A11)=MONTH(BE11)),0,IF((MONTH(BE11)+12)-(MONTH(A11)+12)>1,VLOOKUP("Spreads",$BC$3:$BG$4,MATCH(EOMONTH(BE11,0),$BC$3:$BG$3,0),FALSE)+VLOOKUP("Spreads",$BC$3:$BG$4,MATCH(EOMONTH(BE11,-1),$BC$3:$BG$3,0),FALSE),VLOOKUP("Spreads",$BC$3:$BG$4,MATCH(EOMONTH(A11,0),$BC$3:$BG$3,0)))) -> #VALUE! | AX11: 0 | AZ11: =$Y$3+AV11+AW11+AX11 -> #VALUE! | BC11: =INDEX('[1]Transit Time'!$A:$DZ,MATCH(I11,'[1]Transit Time'!$A:$A,0),MATCH(L11,'[1]Transit Time'!$A$1:$DZ$1,0))+INDEX('[1]Transit Time'!$A:$DZ,MATCH(L11,'[1]Transit Time'!$A:$A,0),MATCH(V11,'[1]Transit Time'!$A$1:$DZ$1,0))+INDEX('[1]Transit Time'!$A:$DZ,MATCH(V11,'[1]Transit Time'!$A:$A,0),MATCH(Z11,'[1]Transit Time'!$A$1:$DZ$1,0)) -> #N/A | BD11: =IF(ISBLANK(A11),"",A11+$BC11) -> #N/A | BE11: =IFERROR(IF(ISBLANK(B11),"",B11+$BC11),"")
A12: =+$A$10 -> 46334 | B12: =IF(ISBLANK(A12),"",A12+2) -> 46336 | D12: =IF(AL12=0,0,VLOOKUP(Y12,Control!$G$41:$J$44,4,FALSE)) -> 0 | T12: =INDEX('[2]Flat Rates 2025'!$A:$DZ,MATCH(V12,'[2]Flat Rates 2025'!$A:$A,0),MATCH(Z12,'[2]Flat Rates 2025'!$A$1:$DZ$1,0)) -> 10.63 | U12: =INDEX(Control!$E$17:$J$21,MATCH(Y12,Control!$E$17:$E$21,0),MATCH(V12,Control!$E$17:$J$17,0)) -> 0.5 | V12: Puerto Armuelles | W12: =INDEX(Vessel_Minimum_MT,MATCH(Y12,Control!$E$11:$E$15,0),MATCH(V12,Control!$E$11:$J$11,0)) -> 145000 | X12: =AB12/Control!$D$84 -> 128709.95 | Y12: Suezmax | Z12: Quintero (MB) | AA12: =IF(Z12=V12,"",CONCATENATE(CONCATENATE(VLOOKUP(V12,Zones,2,FALSE),"/",VLOOKUP(Z12,Zones,2,FALSE)))) -> Panama WC/LATAM WEST | AB12: 1000000 | AC12: 110 | AE12: =IF(AC12>1000,IF(AD12=0,AC12,AD12)/AB12,((W12*T12*(IF(AD12=0,AC12,AD12)/100))+IF(X12<W12,0,(X12-W12)*T12*IF(AD12=0,AC12,AD12)/100*U12))/AB12) -> 1.695485 | AF12: 0 | AG12: =IF(INDEX(Index,MATCH(Z12,TVM_PortList,0),MATCH("Type",Control!$Q$3:$U$3,0))="BL",INDEX(Index,MATCH(Z12,TVM_PortList,0),MATCH("Payment",Control!$Q$3:$U$3,0))-INDEX(Index,MATCH(V12,TVM_PortList,0),MATCH("Payment",Control!$Q$3:$U$3,0)),BC12+INDEX(Index,MATCH(Z12,TVM_PortList,0),MATCH("Payment",Control!$Q$3:$U$3,0))-INDEX(Index,MATCH(V12,TVM_PortList,0),MATCH("Payment",Control!$Q$3:$U$3,0))) -> 15 | AI12: =AF12*VLOOKUP($Y12,Control!$F$75:$H$79,3,FALSE)/$AB12 -> 0 | AJ12: =IF(AG12<0,0,$AG12*Control!$D$77) -> 0.19554247 | AL12: =INDEX(Lightering,MATCH($V12,Control!$AB$3:$AB$29,0),MATCH(WTI!$Y12,Control!$AB$3:$AF$3,0))*($AB12/Control!$D$85)*Control!$H$90/$AB12 -> 0 | AM12: =IF(I12="Corpus Christi",Control!$D$76,0) -> 0 | AN12: 0 | AO12: =Control!$D$78 -> 0 | AP12: =Control!$D$79 -> 0.0673 | AQ12: =IF(INDEX(Control!$Q$3:$S$62,MATCH($Z12,Control!$Q$3:$Q$62,0),MATCH(AQ$9,Control!$Q$3:$S$3,0))=1,Control!$D$81*Control!$E$81,0) -> 0 | AR12: =IF(INDEX(Control!$Q$3:$S$62,MATCH($Z12,Control!$Q$3:$Q$62,0),MATCH(AR$9,Control!$Q$3:$S$3,0))=1,Control!$D$82/$AB12,0) -> 0 | AT12: =IF(AND(L12="Chiriqui Grande",V12="Puerto Armuelles"),Control!$G$93,0) -> 0 | AU12: =SUM(AI12:AT12) -> 0.26284247 | AV12: =+R12+AE12+AU12 -> 1.9583275 | AW12: =IF((MONTH(A12)=MONTH(BE12)),0,IF((MONTH(BE12)+12)-(MONTH(A12)+12)>1,VLOOKUP("Spreads",$BC$3:$BG$4,MATCH(EOMONTH(BE12,0),$BC$3:$BG$3,0),FALSE)+VLOOKUP("Spreads",$BC$3:$BG$4,MATCH(EOMONTH(BE12,-1),$BC$3:$BG$3,0),FALSE),VLOOKUP("Spreads",$BC$3:$BG$4,MATCH(EOMONTH(A12,0),$BC$3:$BG$3,0)))) -> #VALUE! | AX12: 0 | AZ12: =$Y$3+AV12+AW12+AX12 -> #VALUE! | BC12: =INDEX('[1]Transit Time'!$A:$DZ,MATCH(I12,'[1]Transit Time'!$A:$A,0),MATCH(L12,'[1]Transit Time'!$A$1:$DZ$1,0))+INDEX('[1]Transit Time'!$A:$DZ,MATCH(L12,'[1]Transit Time'!$A:$A,0),MATCH(V12,'[1]Transit Time'!$A$1:$DZ$1,0))+INDEX('[1]Transit Time'!$A:$DZ,MATCH(V12,'[1]Transit Time'!$A:$A,0),MATCH(Z12,'[1]Transit Time'!$A$1:$DZ$1,0)) -> #N/A | BD12: =IF(ISBLANK(A12),"",A12+$BC12) -> #N/A | BE12: =IFERROR(IF(ISBLANK(B12),"",B12+$BC12),"")
A13: =+$A$10 -> 46334 | B13: =IF(ISBLANK(A13),"",A13+2) -> 46336 | D13: =IF(AL13=0,0,VLOOKUP(Y13,Control!$G$41:$J$44,4,FALSE)) -> 0 | T13: =INDEX('[2]Flat Rates 2025'!$A:$DZ,MATCH(V13,'[2]Flat Rates 2025'!$A:$A,0),MATCH(Z13,'[2]Flat Rates 2025'!$A$1:$DZ$1,0)) -> 5.93 | U13: =INDEX(Control!$E$17:$J$21,MATCH(Y13,Control!$E$17:$E$21,0),MATCH(V13,Control!$E$17:$J$17,0)) -> 0.5 | V13: Puerto Armuelles | W13: =INDEX(Vessel_Minimum_MT,MATCH(Y13,Control!$E$11:$E$15,0),MATCH(V13,Control!$E$11:$J$11,0)) -> 50000 | X13: =AB13/Control!$D$84 -> 61137.228 | Y13: Panamax | Z13: La Pampilla | AA13: =IF(Z13=V13,"",CONCATENATE(CONCATENATE(VLOOKUP(V13,Zones,2,FALSE),"/",VLOOKUP(Z13,Zones,2,FALSE)))) -> Panama WC/PAMPILLA | AB13: 475000 | AC13: 1001 | AD13: 700000 | AE13: =IF(AC13>1000,IF(AD13=0,AC13,AD13)/AB13,((W13*T13*(IF(AD13=0,AC13,AD13)/100))+IF(X13<W13,0,(X13-W13)*T13*IF(AD13=0,AC13,AD13)/100*U13))/AB13) -> 1.4736842 | AF13: 0 | AG13: =IF(INDEX(Index,MATCH(Z13,TVM_PortList,0),MATCH("Type",Control!$Q$3:$U$3,0))="BL",INDEX(Index,MATCH(Z13,TVM_PortList,0),MATCH("Payment",Control!$Q$3:$U$3,0))-INDEX(Index,MATCH(V13,TVM_PortList,0),MATCH("Payment",Control!$Q$3:$U$3,0)),BC13+INDEX(Index,MATCH(Z13,TVM_PortList,0),MATCH("Payment",Control!$Q$3:$U$3,0))-INDEX(Index,MATCH(V13,TVM_PortList,0),MATCH("Payment",Control!$Q$3:$U$3,0))) -> #N/A | AI13: =AF13*VLOOKUP($Y13,Control!$F$75:$H$79,3,FALSE)/$AB13 -> 0 | AJ13: =IF(AG13<0,0,$AG13*Control!$D$77) -> #N/A | AL13: =INDEX(Lightering,MATCH($V13,Control!$AB$3:$AB$29,0),MATCH(WTI!$Y13,Control!$AB$3:$AF$3,0))*($AB13/Control!$D$85)*Control!$H$90/$AB13 -> 0 | AM13: =IF(I13="Corpus Christi",Control!$D$76,0) -> 0 | AN13: 0 | AO13: =Control!$D$78 -> 0 | AP13: =Control!$D$79 -> 0.0673 | AQ13: =IF(INDEX(Control!$Q$3:$S$62,MATCH($Z13,Control!$Q$3:$Q$62,0),MATCH(AQ$9,Control!$Q$3:$S$3,0))=1,Control!$D$81*Control!$E$81,0) -> 0 | AR13: =IF(INDEX(Control!$Q$3:$S$62,MATCH($Z13,Control!$Q$3:$Q$62,0),MATCH(AR$9,Control!$Q$3:$S$3,0))=1,Control!$D$82/$AB13,0) -> 0 | AT13: =IF(AND(L13="Chiriqui Grande",V13="Puerto Armuelles"),Control!$G$93,0) -> 0 | AU13: =SUM(AI13:AT13) -> #N/A | AV13: =+R13+AE13+AU13 -> #N/A | AW13: =IF((MONTH(A13)=MONTH(BE13)),0,IF((MONTH(BE13)+12)-(MONTH(A13)+12)>1,VLOOKUP("Spreads",$BC$3:$BG$4,MATCH(EOMONTH(BE13,0),$BC$3:$BG$3,0),FALSE)+VLOOKUP("Spreads",$BC$3:$BG$4,MATCH(EOMONTH(BE13,-1),$BC$3:$BG$3,0),FALSE),VLOOKUP("Spreads",$BC$3:$BG$4,MATCH(EOMONTH(A13,0),$BC$3:$BG$3,0)))) -> #VALUE! | AX13: 0 | AZ13: =$Y$3+AV13+AW13+AX13 -> #N/A | BC13: =INDEX('[1]Transit Time'!$A:$DZ,MATCH(I13,'[1]Transit Time'!$A:$A,0),MATCH(L13,'[1]Transit Time'!$A$1:$DZ$1,0))+INDEX('[1]Transit Time'!$A:$DZ,MATCH(L13,'[1]Transit Time'!$A:$A,0),MATCH(V13,'[1]Transit Time'!$A$1:$DZ$1,0))+INDEX('[1]Transit Time'!$A:$DZ,MATCH(V13,'[1]Transit Time'!$A:$A,0),MATCH(Z13,'[1]Transit Time'!$A$1:$DZ$1,0)) -> #N/A | BD13: =IF(ISBLANK(A13),"",A13+$BC13) -> #N/A | BE13: =IFERROR(IF(ISBLANK(B13),"",B13+$BC13),"")
A14: =+$A$10 -> 46334 | B14: =IF(ISBLANK(A14),"",A14+2) -> 46336 | D14: =IF(AL14=0,0,VLOOKUP(Y14,Control!$G$41:$J$44,4,FALSE)) -> 0 | T14: =INDEX('[2]Flat Rates 2025'!$A:$DZ,MATCH(V14,'[2]Flat Rates 2025'!$A:$A,0),MATCH(Z14,'[2]Flat Rates 2025'!$A$1:$DZ$1,0)) -> 5.93 | U14: =INDEX(Control!$E$17:$J$21,MATCH(Y14,Control!$E$17:$E$21,0),MATCH(V14,Control!$E$17:$J$17,0)) -> 0.5 | V14: Puerto Armuelles | W14: =INDEX(Vessel_Minimum_MT,MATCH(Y14,Control!$E$11:$E$15,0),MATCH(V14,Control!$E$11:$J$11,0)) -> 70000 | X14: =AB14/Control!$D$84 -> 84948.57 | Y14: Aframax | Z14: La Pampilla | AA14: =IF(Z14=V14,"",CONCATENATE(CONCATENATE(VLOOKUP(V14,Zones,2,FALSE),"/",VLOOKUP(Z14,Zones,2,FALSE)))) -> Panama WC/PAMPILLA | AB14: 660000 | AC14: 205 | AD14: 0 | AE14: =IF(AC14>1000,IF(AD14=0,AC14,AD14)/AB14,((W14*T14*(IF(AD14=0,AC14,AD14)/100))+IF(X14<W14,0,(X14-W14)*T14*IF(AD14=0,AC14,AD14)/100*U14))/AB14) -> 1.4269942 | AF14: 0 | AG14: =IF(INDEX(Index,MATCH(Z14,TVM_PortList,0),MATCH("Type",Control!$Q$3:$U$3,0))="BL",INDEX(Index,MATCH(Z14,TVM_PortList,0),MATCH("Payment",Control!$Q$3:$U$3,0))-INDEX(Index,MATCH(V14,TVM_PortList,0),MATCH("Payment",Control!$Q$3:$U$3,0)),BC14+INDEX(Index,MATCH(Z14,TVM_PortList,0),MATCH("Payment",Control!$Q$3:$U$3,0))-INDEX(Index,MATCH(V14,TVM_PortList,0),MATCH("Payment",Control!$Q$3:$U$3,0))) -> #N/A | AI14: =AF14*VLOOKUP($Y14,Control!$F$75:$H$79,3,FALSE)/$AB14 -> 0 | AJ14: =IF(AG14<0,0,$AG14*Control!$D$77) -> #N/A | AL14: =INDEX(Lightering,MATCH($V14,Control!$AB$3:$AB$29,0),MATCH(WTI!$Y14,Control!$AB$3:$AF$3,0))*($AB14/Control!$D$85)*Control!$H$90/$AB14 -> 0 | AM14: =IF(I14="Corpus Christi",Control!$D$76,0) -> 0 | AN14: 0 | AO14: =Control!$D$78 -> 0 | AP14: =Control!$D$79 -> 0.0673 | AQ14: =IF(INDEX(Control!$Q$3:$S$62,MATCH($Z14,Control!$Q$3:$Q$62,0),MATCH(AQ$9,Control!$Q$3:$S$3,0))=1,Control!$D$81*Control!$E$81,0) -> 0 | AR14: =IF(INDEX(Control!$Q$3:$S$62,MATCH($Z14,Control!$Q$3:$Q$62,0),MATCH(AR$9,Control!$Q$3:$S$3,0))=1,Control!$D$82/$AB14,0) -> 0 | AT14: =IF(AND(L14="Chiriqui Grande",V14="Puerto Armuelles"),Control!$G$93,0) -> 0 | AU14: =SUM(AI14:AT14) -> #N/A | AV14: =+R14+AE14+AU14 -> #N/A | AW14: =IF((MONTH(A14)=MONTH(BE14)),0,IF((MONTH(BE14)+12)-(MONTH(A14)+12)>1,VLOOKUP("Spreads",$BC$3:$BG$4,MATCH(EOMONTH(BE14,0),$BC$3:$BG$3,0),FALSE)+VLOOKUP("Spreads",$BC$3:$BG$4,MATCH(EOMONTH(BE14,-1),$BC$3:$BG$3,0),FALSE),VLOOKUP("Spreads",$BC$3:$BG$4,MATCH(EOMONTH(A14,0),$BC$3:$BG$3,0)))) -> #VALUE! | AX14: 0 | AZ14: =$Y$3+AV14+AW14+AX14 -> #N/A | BC14: =INDEX('[1]Transit Time'!$A:$DZ,MATCH(I14,'[1]Transit Time'!$A:$A,0),MATCH(L14,'[1]Transit Time'!$A$1:$DZ$1,0))+INDEX('[1]Transit Time'!$A:$DZ,MATCH(L14,'[1]Transit Time'!$A:$A,0),MATCH(V14,'[1]Transit Time'!$A$1:$DZ$1,0))+INDEX('[1]Transit Time'!$A:$DZ,MATCH(V14,'[1]Transit Time'!$A:$A,0),MATCH(Z14,'[1]Transit Time'!$A$1:$DZ$1,0)) -> #N/A | BD14: =IF(ISBLANK(A14),"",A14+$BC14) -> #N/A | BE14: =IFERROR(IF(ISBLANK(B14),"",B14+$BC14),"")
A15: =+$A$10 -> 46334 | B15: =IF(ISBLANK(A15),"",A15+2) -> 46336 | D15: =IF(AL15=0,0,VLOOKUP(Y15,Control!$G$41:$J$44,4,FALSE)) -> 0 | T15: =INDEX('[2]Flat Rates 2025'!$A:$DZ,MATCH(V15,'[2]Flat Rates 2025'!$A:$A,0),MATCH(Z15,'[2]Flat Rates 2025'!$A$1:$DZ$1,0)) -> #N/A | U15: =INDEX(Control!$E$17:$J$21,MATCH(Y15,Control!$E$17:$E$21,0),MATCH(V15,Control!$E$17:$J$17,0)) -> 0.5 | V15: Puerto Armuelles | W15: =INDEX(Vessel_Minimum_MT,MATCH(Y15,Control!$E$11:$E$15,0),MATCH(V15,Control!$E$11:$J$11,0)) -> 50000 | X15: =AB15/Control!$D$84 -> 51355.272 | Y15: Panamax | Z15: Bayovar/Talara | AA15: =IF(Z15=V15,"",CONCATENATE(CONCATENATE(VLOOKUP(V15,Zones,2,FALSE),"/",VLOOKUP(Z15,Zones,2,FALSE)))) -> #N/A | AB15: 399000 | AC15: 1001 | AD15: 700000 | AE15: =IF(AC15>1000,IF(AD15=0,AC15,AD15)/AB15,((W15*T15*(IF(AD15=0,AC15,AD15)/100))+IF(X15<W15,0,(X15-W15)*T15*IF(AD15=0,AC15,AD15)/100*U15))/AB15) -> 1.754386 | AF15: 0 | AG15: =IF(INDEX(Index,MATCH(Z15,TVM_PortList,0),MATCH("Type",Control!$Q$3:$U$3,0))="BL",INDEX(Index,MATCH(Z15,TVM_PortList,0),MATCH("Payment",Control!$Q$3:$U$3,0))-INDEX(Index,MATCH(V15,TVM_PortList,0),MATCH("Payment",Control!$Q$3:$U$3,0)),BC15+INDEX(Index,MATCH(Z15,TVM_PortList,0),MATCH("Payment",Control!$Q$3:$U$3,0))-INDEX(Index,MATCH(V15,TVM_PortList,0),MATCH("Payment",Control!$Q$3:$U$3,0))) -> #N/A | AI15: =AF15*VLOOKUP($Y15,Control!$F$75:$H$79,3,FALSE)/$AB15 -> 0 | AJ15: =IF(AG15<0,0,$AG15*Control!$D$77) -> #N/A | AL15: =INDEX(Lightering,MATCH($V15,Control!$AB$3:$AB$29,0),MATCH(WTI!$Y15,Control!$AB$3:$AF$3,0))*($AB15/Control!$D$85)*Control!$H$90/$AB15 -> 0 | AM15: =IF(I15="Corpus Christi",Control!$D$76,0) -> 0 | AN15: 0 | AO15: =Control!$D$78 -> 0 | AP15: =Control!$D$79 -> 0.0673 | AQ15: =IF(INDEX(Control!$Q$3:$S$62,MATCH($Z15,Control!$Q$3:$Q$62,0),MATCH(AQ$9,Control!$Q$3:$S$3,0))=1,Control!$D$81*Control!$E$81,0) -> #N/A | AR15: =IF(INDEX(Control!$Q$3:$S$62,MATCH($Z15,Control!$Q$3:$Q$62,0),MATCH(AR$9,Control!$Q$3:$S$3,0))=1,Control!$D$82/$AB15,0) -> #N/A | AT15: =IF(AND(L15="Chiriqui Grande",V15="Puerto Armuelles"),Control!$G$93,0) -> 0 | AU15: =SUM(AI15:AT15) -> #N/A | AV15: =+R15+AE15+AU15 -> #N/A | AW15: =IF((MONTH(A15)=MONTH(BE15)),0,IF((MONTH(BE15)+12)-(MONTH(A15)+12)>1,VLOOKUP("Spreads",$BC$3:$BG$4,MATCH(EOMONTH(BE15,0),$BC$3:$BG$3,0),FALSE)+VLOOKUP("Spreads",$BC$3:$BG$4,MATCH(EOMONTH(BE15,-1),$BC$3:$BG$3,0),FALSE),VLOOKUP("Spreads",$BC$3:$BG$4,MATCH(EOMONTH(A15,0),$BC$3:$BG$3,0)))) -> #VALUE! | AX15: 0 | AZ15: =$Y$3+AV15+AW15+AX15 -> #N/A | BC15: =INDEX('[1]Transit Time'!$A:$DZ,MATCH(I15,'[1]Transit Time'!$A:$A,0),MATCH(L15,'[1]Transit Time'!$A$1:$DZ$1,0))+INDEX('[1]Transit Time'!$A:$DZ,MATCH(L15,'[1]Transit Time'!$A:$A,0),MATCH(V15,'[1]Transit Time'!$A$1:$DZ$1,0))+INDEX('[1]Transit Time'!$A:$DZ,MATCH(V15,'[1]Transit Time'!$A:$A,0),MATCH(Z15,'[1]Transit Time'!$A$1:$DZ$1,0)) -> #N/A | BD15: =IF(ISBLANK(A15),"",A15+$BC15) -> #N/A | BE15: =IFERROR(IF(ISBLANK(B15),"",B15+$BC15),"")
A16: =+$A$10 -> 46334 | B16: =IF(ISBLANK(A16),"",A16+2) -> 46336 | D16: =IF(AL16=0,0,VLOOKUP(Y16,Control!$G$41:$J$44,4,FALSE)) -> 0 | T16: =INDEX('[2]Flat Rates 2025'!$A:$DZ,MATCH(V16,'[2]Flat Rates 2025'!$A:$A,0),MATCH(Z16,'[2]Flat Rates 2025'!$A$1:$DZ$1,0)) -> #N/A | U16: =INDEX(Control!$E$17:$J$21,MATCH(Y16,Control!$E$17:$E$21,0),MATCH(V16,Control!$E$17:$J$17,0)) -> 0 | V16: Chiriqui Grande | W16: =INDEX(Vessel_Minimum_MT,MATCH(Y16,Control!$E$11:$E$15,0),MATCH(V16,Control!$E$11:$J$11,0)) -> 70000 | X16: =AB16/Control!$D$84 -> 64354.977 | Y16: Aframax | Z16: Mamonal | AA16: =IF(Z16=V16,"",CONCATENATE(CONCATENATE(VLOOKUP(V16,Zones,2,FALSE),"/",VLOOKUP(Z16,Zones,2,FALSE)))) -> CARIBS/CARIBS | AB16: 500000 | AC16: 180 | AD16: 325 | AE16: =IF(AC16>1000,IF(AD16=0,AC16,AD16)/AB16,((W16*T16*(IF(AD16=0,AC16,AD16)/100))+IF(X16<W16,0,(X16-W16)*T16*IF(AD16=0,AC16,AD16)/100*U16))/AB16) -> #N/A | AF16: 0 | AG16: =IF(INDEX(Index,MATCH(Z16,TVM_PortList,0),MATCH("Type",Control!$Q$3:$U$3,0))="BL",INDEX(Index,MATCH(Z16,TVM_PortList,0),MATCH("Payment",Control!$Q$3:$U$3,0))-INDEX(Index,MATCH(V16,TVM_PortList,0),MATCH("Payment",Control!$Q$3:$U$3,0)),BC16+INDEX(Index,MATCH(Z16,TVM_PortList,0),MATCH("Payment",Control!$Q$3:$U$3,0))-INDEX(Index,MATCH(V16,TVM_PortList,0),MATCH("Payment",Control!$Q$3:$U$3,0))) -> #N/A | AI16: =AF16*VLOOKUP($Y16,Control!$F$75:$H$79,3,FALSE)/$AB16 -> 0 | AJ16: =IF(AG16<0,0,$AG16*Control!$D$77) -> #N/A | AL16: =INDEX(Lightering,MATCH($V16,Control!$AB$3:$AB$29,0),MATCH(WTI!$Y16,Control!$AB$3:$AF$3,0))*($AB16/Control!$D$85)*Control!$H$90/$AB16 -> 0 | AM16: =IF(I16="Corpus Christi",Control!$D$76,0) -> 0 | AN16: 0 | AO16: =Control!$D$78 -> 0 | AP16: =Control!$D$79 -> 0.0673 | AQ16: =IF(INDEX(Control!$Q$3:$S$62,MATCH($Z16,Control!$Q$3:$Q$62,0),MATCH(AQ$9,Control!$Q$3:$S$3,0))=1,Control!$D$81*Control!$E$81,0) -> 0.2 | AR16: =IF(INDEX(Control!$Q$3:$S$62,MATCH($Z16,Control!$Q$3:$Q$62,0),MATCH(AR$9,Control!$Q$3:$S$3,0))=1,Control!$D$82/$AB16,0) -> 0 | AT16: =IF(AND(L16="Chiriqui Grande",V16="Puerto Armuelles"),Control!$G$93,0) -> 0 | AU16: =SUM(AI16:AT16) -> #N/A | AV16: =+R16+AE16+AU16 -> #N/A | AW16: =IF((MONTH(A16)=MONTH(BE16)),0,IF((MONTH(BE16)+12)-(MONTH(A16)+12)>1,VLOOKUP("Spreads",$BC$3:$BG$4,MATCH(EOMONTH(BE16,0),$BC$3:$BG$3,0),FALSE)+VLOOKUP("Spreads",$BC$3:$BG$4,MATCH(EOMONTH(BE16,-1),$BC$3:$BG$3,0),FALSE),VLOOKUP("Spreads",$BC$3:$BG$4,MATCH(EOMONTH(A16,0),$BC$3:$BG$3,0)))) -> #VALUE! | AX16: 0 | AZ16: =$Y$3+AV16+AW16+AX16 -> #N/A | BC16: =INDEX('[1]Transit Time'!$A:$DZ,MATCH(I16,'[1]Transit Time'!$A:$A,0),MATCH(L16,'[1]Transit Time'!$A$1:$DZ$1,0))+INDEX('[1]Transit Time'!$A:$DZ,MATCH(L16,'[1]Transit Time'!$A:$A,0),MATCH(V16,'[1]Transit Time'!$A$1:$DZ$1,0))+INDEX('[1]Transit Time'!$A:$DZ,MATCH(V16,'[1]Transit Time'!$A:$A,0),MATCH(Z16,'[1]Transit Time'!$A$1:$DZ$1,0)) -> #N/A | BD16: =IF(ISBLANK(A16),"",A16+$BC16) -> #N/A | BE16: =IFERROR(IF(ISBLANK(B16),"",B16+$BC16),"")
B17: =IF(ISBLANK(A17),"",A17+2) -> #VALUE! | D17: =IF(AL17=0,0,VLOOKUP(Y17,Control!$G$41:$J$44,4,FALSE)) -> 0 | E17: =AVERAGE(A17:B17)+D17 -> #VALUE! | T17: =INDEX('[2]Flat Rates 2025'!$A:$DZ,MATCH(V17,'[2]Flat Rates 2025'!$A:$A,0),MATCH(Z17,'[2]Flat Rates 2025'!$A$1:$DZ$1,0)) -> 0 | U17: =INDEX(Control!$E$17:$J$21,MATCH(Y17,Control!$E$17:$E$21,0),MATCH(V17,Control!$E$17:$J$17,0)) -> 0 | V17: Corpus Christi | W17: =INDEX(Vessel_Minimum_MT,MATCH(Y17,Control!$E$11:$E$15,0),MATCH(V17,Control!$E$11:$J$11,0)) -> 70000 | X17: =AB17/Control!$D$84 -> 96532.466 | Y17: Aframax | Z17: Quintero (MB) | AA17: =IF(Z17=V17,"",CONCATENATE(CONCATENATE(VLOOKUP(V17,Zones,2,FALSE),"/",VLOOKUP(Z17,Zones,2,FALSE)))) -> USGC/LATAM WEST | AB17: 750000 | AC17: 1001 | AD17: 1600000 | AE17: =IF(AC17>1000,IF(AD17=0,AC17,AD17)/AB17,((W17*T17*(IF(AD17=0,AC17,AD17)/100))+IF(X17<W17,0,(X17-W17)*T17*IF(AD17=0,AC17,AD17)/100*U17))/AB17) -> 2.1333333 | AF17: 3 | AG17: =IF(INDEX(Index,MATCH(Z17,TVM_PortList,0),MATCH("Type",Control!$Q$3:$U$3,0))="BL",INDEX(Index,MATCH(Z17,TVM_PortList,0),MATCH("Payment",Control!$Q$3:$U$3,0))-INDEX(Index,MATCH(V17,TVM_PortList,0),MATCH("Payment",Control!$Q$3:$U$3,0)),BC17+INDEX(Index,MATCH(Z17,TVM_PortList,0),MATCH("Payment",Control!$Q$3:$U$3,0))-INDEX(Index,MATCH(V17,TVM_PortList,0),MATCH("Payment",Control!$Q$3:$U$3,0))) -> 0 | AI17: =AF17*VLOOKUP($Y17,Control!$F$75:$H$79,3,FALSE)/$AB17 -> 0.32 | AJ17: =IF(AG17<0,0,$AG17*Control!$D$77) -> 0 | AL17: =INDEX(Lightering,MATCH($V17,Control!$AB$3:$AB$29,0),MATCH(WTI!$Y17,Control!$AB$3:$AF$3,0))*($AB17/Control!$D$85)*Control!$H$90/$AB17 -> 0 | AM17: =IF(I17="Corpus Christi",Control!$D$76,0) -> 0 | AN17: 0 | AO17: =Control!$D$78 -> 0 | AP17: =Control!$D$79 -> 0.0673 | AQ17: =IF(INDEX(Control!$Q$3:$S$62,MATCH($Z17,Control!$Q$3:$Q$62,0),MATCH(AQ$9,Control!$Q$3:$S$3,0))=1,Control!$D$81*Control!$E$81,0) -> 0 | AR17: =IF(INDEX(Control!$Q$3:$S$62,MATCH($Z17,Control!$Q$3:$Q$62,0),MATCH(AR$9,Control!$Q$3:$S$3,0))=1,Control!$D$82/$AB17,0) -> 0 | AT17: =IF(AND(L17="Chiriqui Grande",V17="Puerto Armuelles"),Control!$G$93,0) -> 0 | AU17: =SUM(AI17:AT17) -> 0.3873 | AV17: =+R17+AE17+AU17 -> 2.5206333 | AW17: =IF((MONTH(A17)=MONTH(BH17)),0,IF(((MONTH(BH17))-MONTH(A17))+12*YEAR(BG17)-YEAR(A17)>1,SUMIFS($BD$4:$BG$4,$BD$3:$BG$3,"<="&EOMONTH(BG17,-1),$BD$3:$BG$3,">="&EOMONTH(A17,0)),VLOOKUP("Spreads",$BC$3:$BG$4,MATCH(EOMONTH(A17,0),$BC$3:$BG$3,0)))) -> #VALUE! | AX17: =+IF($BC$3=1,HLOOKUP(EOMONTH(BE17,0),$BD$3:$BG$6,4,FALSE),IF($BC$3=2,-HLOOKUP(EOMONTH(BE17,0),$BD$3:$BG$6,3,FALSE),0)) -> #VALUE! | AZ17: =$Y$3+AV17+AW17+AX17 -> #VALUE! | BC17: =+INDEX('[1]Transit Time'!$A:$DZ,MATCH(V17,'[1]Transit Time'!$A:$A,0),MATCH(Z17,'[1]Transit Time'!$A$1:$DZ$1,0)) -> 18 | BD17: =IF(ISBLANK(A17),"",A17+$BC17+D17) -> #VALUE! | BE17: =IFERROR(IF(ISBLANK(B17),"",B17+$BC17),"") | BF17: =HLOOKUP($BC$3,$AV$3:$AX$3,2,FALSE) -> #N/A | BG17: =IF($BC$8=0,IF(BF17="ICE Brent",EOMONTH(BE17,2),EOMONTH(BE17,0)),IF(BF17="ICE Brent",EOMONTH(BE17,1),EOMONTH(BE17,-1))) -> #N/A | BH17: =IF($BC$8=1,EOMONTH(BE17,-1),EOMONTH(BE17,0)) -> #VALUE!
A18: =+$A$10 -> 46334 | B18: =IF(ISBLANK(A18),"",A18+2) -> 46336 | D18: =IF(AL18=0,0,VLOOKUP(Y18,Control!$G$41:$J$44,4,FALSE)) -> 0 | E18: =AVERAGE(A18:B18)+D18 -> 46335 | T18: =INDEX('[2]Flat Rates 2025'!$A:$DZ,MATCH(V18,'[2]Flat Rates 2025'!$A:$A,0),MATCH(Z18,'[2]Flat Rates 2025'!$A$1:$DZ$1,0)) -> 0 | U18: =INDEX(Control!$E$17:$J$21,MATCH(Y18,Control!$E$17:$E$21,0),MATCH(V18,Control!$E$17:$J$17,0)) -> 0 | V18: Corpus Christi | W18: =INDEX(Vessel_Minimum_MT,MATCH(Y18,Control!$E$11:$E$15,0),MATCH(V18,Control!$E$11:$J$11,0)) -> 70000 | X18: =AB18/Control!$D$84 -> 96532.466 | Y18: Aframax | Z18: Sao Sebastiao | AA18: =IF(Z18=V18,"",CONCATENATE(CONCATENATE(VLOOKUP(V18,Zones,2,FALSE),"/",VLOOKUP(Z18,Zones,2,FALSE)))) -> USGC/BAYOVAR+T | AB18: 750000 | AD18: 190 | AE18: =IF(AC18>1000,IF(AD18=0,AC18,AD18)/AB18,((W18*T18*(IF(AD18=0,AC18,AD18)/100))+IF(X18<W18,0,(X18-W18)*T18*IF(AD18=0,AC18,AD18)/100*U18))/AB18) -> 0 | AF18: 2 | AG18: =IF(INDEX(Index,MATCH(Z18,TVM_PortList,0),MATCH("Type",Control!$Q$3:$U$3,0))="BL",INDEX(Index,MATCH(Z18,TVM_PortList,0),MATCH("Payment",Control!$Q$3:$U$3,0))-INDEX(Index,MATCH(V18,TVM_PortList,0),MATCH("Payment",Control!$Q$3:$U$3,0)),BC18+INDEX(Index,MATCH(Z18,TVM_PortList,0),MATCH("Payment",Control!$Q$3:$U$3,0))-INDEX(Index,MATCH(V18,TVM_PortList,0),MATCH("Payment",Control!$Q$3:$U$3,0))) -> 2 | AI18: =AF18*VLOOKUP($Y18,Control!$F$75:$H$79,3,FALSE)/$AB18 -> 0.21333333 | AJ18: =IF(AG18<0,0,$AG18*Control!$D$77) -> 0.026072329 | AL18: =INDEX(Lightering,MATCH($V18,Control!$AB$3:$AB$29,0),MATCH(WTI!$Y18,Control!$AB$3:$AF$3,0))*($AB18/Control!$D$85)*Control!$H$90/$AB18 -> 0 | AM18: =IF(I18="Corpus Christi",Control!$D$76,0) -> 0 | AN18: 0.62666667 | AO18: =Control!$D$78 -> 0 | AP18: =Control!$D$79 -> 0.0673 | AQ18: =IF(INDEX(Control!$Q$3:$S$62,MATCH($Z18,Control!$Q$3:$Q$62,0),MATCH(AQ$9,Control!$Q$3:$S$3,0))=1,Control!$D$81*Control!$E$81,0) -> 0 | AR18: =IF(INDEX(Control!$Q$3:$S$62,MATCH($Z18,Control!$Q$3:$Q$62,0),MATCH(AR$9,Control!$Q$3:$S$3,0))=1,Control!$D$82/$AB18,0) -> 0 | AT18: =IF(AND(L18="Chiriqui Grande",V18="Puerto Armuelles"),Control!$G$93,0) -> 0 | AU18: =SUM(AI18:AT18) -> 0.93337233 | AV18: =+R18+AE18+AU18 -> 0.93337233 | AW18: =IF((MONTH(A18)=MONTH(BH18)),0,IF(((MONTH(BH18))-MONTH(A18))+12*YEAR(BG18)-YEAR(A18)>1,SUMIFS($BD$4:$BG$4,$BD$3:$BG$3,"<="&EOMONTH(BG18,-1),$BD$3:$BG$3,">="&EOMONTH(A18,0)),VLOOKUP("Spreads",$BC$3:$BG$4,MATCH(EOMONTH(A18,0),$BC$3:$BG$3,0)))) -> #N/A | AX18: =+IF($BC$3=1,HLOOKUP(EOMONTH(BE18,0),$BD$3:$BG$6,4,FALSE),IF($BC$3=2,-HLOOKUP(EOMONTH(BE18,0),$BD$3:$BG$6,3,FALSE),0)) -> -1.7 | AZ18: =$Y$3+AV18+AW18+AX18 -> #N/A | BC18: =+INDEX('[1]Transit Time'!$A:$DZ,MATCH(V18,'[1]Transit Time'!$A:$A,0),MATCH(Z18,'[1]Transit Time'!$A$1:$DZ$1,0)) -> 19 | BD18: =IF(ISBLANK(A18),"",A18+$BC18+D18) -> 46353 | BE18: =IFERROR(IF(ISBLANK(B18),"",B18+$BC18),"") -> 46355 | BF18: =HLOOKUP($BC$3,$AV$3:$AX$3,2,FALSE) -> #N/A | BG18: =IF($BC$8=0,IF(BF18="ICE Brent",EOMONTH(BE18,2),EOMONTH(BE18,0)),IF(BF18="ICE Brent",EOMONTH(BE18,1),EOMONTH(BE18,-1))) -> #N/A | BH18: =IF($BC$8=1,EOMONTH(BE18,-1),EOMONTH(BE18,0)) -> 46326
A19: =+$A$10 -> 46334 | B19: =IF(ISBLANK(A19),"",A19+2) -> 46336 | D19: =IF(AL19=0,0,VLOOKUP(Y19,Control!$G$41:$J$44,4,FALSE)) -> 0 | E19: =AVERAGE(A19:B19)+D19 -> 46335 | T19: =INDEX('[2]Flat Rates 2025'!$A:$DZ,MATCH(V19,'[2]Flat Rates 2025'!$A:$A,0),MATCH(Z19,'[2]Flat Rates 2025'!$A$1:$DZ$1,0)) -> 0 | U19: =INDEX(Control!$E$17:$J$21,MATCH(Y19,Control!$E$17:$E$21,0),MATCH(V19,Control!$E$17:$J$17,0)) -> 0.5 | V19: Corpus Christi | W19: =INDEX(Vessel_Minimum_MT,MATCH(Y19,Control!$E$11:$E$15,0),MATCH(V19,Control!$E$11:$J$11,0)) -> 145000 | X19: =AB19/Control!$D$84 -> 109403.46 | Y19: Suezmax | Z19: Sao Sebastiao | AA19: =IF(Z19=V19,"",CONCATENATE(CONCATENATE(VLOOKUP(V19,Zones,2,FALSE),"/",VLOOKUP(Z19,Zones,2,FALSE)))) -> USGC/BAYOVAR+T | AB19: 850000 | AD19: 90 | AE19: =IF(AC19>1000,IF(AD19=0,AC19,AD19)/AB19,((W19*T19*(IF(AD19=0,AC19,AD19)/100))+IF(X19<W19,0,(X19-W19)*T19*IF(AD19=0,AC19,AD19)/100*U19))/AB19) -> 0 | AF19: 2 | AG19: =IF(INDEX(Index,MATCH(Z19,TVM_PortList,0),MATCH("Type",Control!$Q$3:$U$3,0))="BL",INDEX(Index,MATCH(Z19,TVM_PortList,0),MATCH("Payment",Control!$Q$3:$U$3,0))-INDEX(Index,MATCH(V19,TVM_PortList,0),MATCH("Payment",Control!$Q$3:$U$3,0)),BC19+INDEX(Index,MATCH(Z19,TVM_PortList,0),MATCH("Payment",Control!$Q$3:$U$3,0))-INDEX(Index,MATCH(V19,TVM_PortList,0),MATCH("Payment",Control!$Q$3:$U$3,0))) -> 2 | AI19: =ABH364*VLOOKUP($Y19,Control!$F$75:$H$79,3,FALSE)/$AB19 -> 0 | AJ19: =IF(AG19<0,0,$AG19*Control!$D$77) -> 0.026072329 | AM19: =IF(I19="Corpus Christi",Control!$D$76,0) -> 0 | AN19: 0 | AO19: =Control!$D$78 -> 0 | AP19: =Control!$D$79 -> 0.0673 | AQ19: =IF(INDEX(Control!$Q$3:$S$62,MATCH($Z19,Control!$Q$3:$Q$62,0),MATCH(AQ$9,Control!$Q$3:$S$3,0))=1,Control!$D$81*Control!$E$81,0) -> 0 | AR19: =IF(INDEX(Control!$Q$3:$S$62,MATCH($Z19,Control!$Q$3:$Q$62,0),MATCH(AR$9,Control!$Q$3:$S$3,0))=1,Control!$D$82/$AB19,0) -> 0 | AT19: =IF(AND(L19="Chiriqui Grande",V19="Puerto Armuelles"),Control!$G$93,0) -> 0 | AU19: =SUM(AI19:AT19) -> 0.093372329 | AV19: =+R19+AE19+AU19 -> 0.093372329 | AW19: =IF((MONTH(A19)=MONTH(BH19)),0,IF(((MONTH(BH19))-MONTH(A19))+12*YEAR(BG19)-YEAR(A19)>1,SUMIFS($BD$4:$BH$4,$BD$3:$BH$3,"<="&EOMONTH(BG19,-1),$BD$3:$BH$3,">="&EOMONTH(A19,0)),VLOOKUP("Spreads",$BC$3:$BH$4,MATCH(EOMONTH(A19,0),$BC$3:$BH$3,0)))) -> 0 | AZ19: =$Y$3+AV19+AW19+AX19 -> -3.5066277 | BC19: =+INDEX('[1]Transit Time'!$A:$DZ,MATCH(V19,'[1]Transit Time'!$A:$A,0),MATCH(Z19,'[1]Transit Time'!$A$1:$DZ$1,0)) -> 19 | BD19: =IF(ISBLANK(A19),"",A19+$BC19+D19) -> 46353 | BE19: =BD19+2 -> 46355 | BF19: ICE Brent | BG19: =BH19 -> 46356 | BH19: =EOMONTH(BE19,0) -> 46356
A20: =+$A$10 -> 46334 | B20: =IF(ISBLANK(A20),"",A20+2) -> 46336 | D20: =IF(AL20=0,0,VLOOKUP(Y20,Control!$G$41:$J$44,4,FALSE)) -> 0 | E20: =AVERAGE(A20:B20)+D20 -> 46335 | T20: =INDEX('[2]Flat Rates 2025'!$A:$DZ,MATCH(V20,'[2]Flat Rates 2025'!$A:$A,0),MATCH(Z20,'[2]Flat Rates 2025'!$A$1:$DZ$1,0)) -> 0 | U20: =INDEX(Control!$E$17:$J$21,MATCH(Y20,Control!$E$17:$E$21,0),MATCH(V20,Control!$E$17:$J$17,0)) -> 0 | V20: Corpus Christi | W20: =INDEX(Vessel_Minimum_MT,MATCH(Y20,Control!$E$11:$E$15,0),MATCH(V20,Control!$E$11:$J$11,0)) -> 70000 | X20: =AB20/Control!$D$84 -> 90096.968 | Y20: Aframax | Z20: Saint John | AA20: =IF(Z20=V20,"",CONCATENATE(CONCATENATE(VLOOKUP(V20,Zones,2,FALSE),"/",VLOOKUP(Z20,Zones,2,FALSE)))) -> USGC/ECC | AB20: 700000 | AD20: =AD21 -> 927.5 | AE20: =IF(AC20>1000,IF(AD20=0,AC20,AD20)/AB20,((W20*T20*(IF(AD20=0,AC20,AD20)/100))+IF(X20<W20,0,(X20-W20)*T20*IF(AD20=0,AC20,AD20)/100*U20))/AB20) -> 0 | AF20: 1 | AG20: =IF(INDEX(Index,MATCH(Z20,TVM_PortList,0),MATCH("Type",Control!$Q$3:$U$3,0))="BL",INDEX(Index,MATCH(Z20,TVM_PortList,0),MATCH("Payment",Control!$Q$3:$U$3,0))-INDEX(Index,MATCH(V20,TVM_PortList,0),MATCH("Payment",Control!$Q$3:$U$3,0)),BC20+INDEX(Index,MATCH(Z20,TVM_PortList,0),MATCH("Payment",Control!$Q$3:$U$3,0))-INDEX(Index,MATCH(V20,TVM_PortList,0),MATCH("Payment",Control!$Q$3:$U$3,0))) -> 0 | AI20: =ABH365*VLOOKUP($Y20,Control!$F$75:$H$79,3,FALSE)/$AB20 -> 0 | AJ20: =IF(AG20<0,0,$AG20*Control!$D$77) -> 0 | AM20: =IF(I20="Corpus Christi",Control!$D$76,0) -> 0 | AN20: 0 | AO20: =Control!$D$78 -> 0 | AP20: =Control!$D$79 -> 0.0673 | AQ20: =IF(INDEX(Control!$Q$3:$S$62,MATCH($Z20,Control!$Q$3:$Q$62,0),MATCH(AQ$9,Control!$Q$3:$S$3,0))=1,Control!$D$81*Control!$E$81,0) -> 0 | AR20: =IF(INDEX(Control!$Q$3:$S$62,MATCH($Z20,Control!$Q$3:$Q$62,0),MATCH(AR$9,Control!$Q$3:$S$3,0))=1,Control!$D$82/$AB20,0) -> 0 | AT20: =IF(AND(L20="Chiriqui Grande",V20="Puerto Armuelles"),Control!$G$93,0) -> 0 | AU20: =SUM(AI20:AT20) -> 0.0673 | AV20: =+R20+AE20+AU20 -> 0.0673 | AW20: =IF((MONTH(A20)=MONTH(BH20)),0,IF(((MONTH(BH20))-MONTH(A20))+12*YEAR(BG20)-YEAR(A20)>1,SUMIFS($BD$4:$BH$4,$BD$3:$BH$3,"<="&EOMONTH(BG20,-1),$BD$3:$BH$3,">="&EOMONTH(A20,0)),VLOOKUP("Spreads",$BC$3:$BH$4,MATCH(EOMONTH(A20,0),$BC$3:$BH$3,0)))) -> 0 | AZ20: =$Y$3+AV20+AW20+AX20 -> -3.5327 | BC20: =+INDEX('[1]Transit Time'!$A:$DZ,MATCH(V20,'[1]Transit Time'!$A:$A,0),MATCH(Z20,'[1]Transit Time'!$A$1:$DZ$1,0)) -> 8 | BD20: =IF(ISBLANK(A20),"",A20+$BC20+D20) -> 46342 | BE20: =BD20+2 -> 46344 | BF20: ICE Brent | BG20: =BH20 -> 46356 | BH20: =EOMONTH(BE20,0) -> 46356
A21: =A9 -> 46334 | B21: =B9 -> 46336 | D21: =IF(AL21=0,0,VLOOKUP(Y21,Control!$G$41:$J$44,4,FALSE)) -> 0 | E21: =AVERAGE(A21:B21)+D21 -> 46335 | T21: =T22 -> 12.01 | U21: =INDEX(Control!$E$17:$J$21,MATCH(Y21,Control!$E$17:$E$21,0),MATCH(V21,Control!$E$17:$J$17,0)) -> 0 | V21: Corpus Christi | W21: =INDEX(Vessel_Minimum_MT,MATCH(Y21,Control!$E$11:$E$15,0),MATCH(V21,Control!$E$11:$J$11,0)) -> 70000 | X21: =AB21/Control!$D$84 -> 90096.968 | Y21: Aframax | Z21: Saint John | AA21: =IF(Z21=V21,"",CONCATENATE(CONCATENATE(VLOOKUP(V21,Zones,2,FALSE),"/",VLOOKUP(Z21,Zones,2,FALSE)))) -> USGC/ECC | AB21: 700000 | AC21: 70 | AD21: =AD52+7.5 -> 927.5 | AE21: =IF(AC21>1000,IF(AD21=0,AC21,AD21)/AB21,((W21*T21*(IF(AD21=0,AC21,AD21)/100))+IF(X21<W21,0,(X21-W21)*T21*IF(AD21=0,AC21,AD21)/100*U21))/AB21) -> 11.139275 | AF21: 0 | AG21: =AG52 -> -10 | AH21: =AH52 -> 0 | AI21: =AF21*VLOOKUP($Y21,Control!$F$75:$H$87,3,FALSE)/$AB21 -> 0 | AJ21: =IF($AK$3=1,$AG21*Control!$D$77,0) -> 0 | AK21: =IF($AK$4=1,$AH21*Control!$D$77,0) -> 0 | AQ21: =IF(INDEX(Control!$Q$3:$S$62,MATCH($Z21,Control!$Q$3:$Q$62,0),MATCH(AQ$9,Control!$Q$3:$S$3,0))=1,Control!$D$81*Control!$E$81,0) -> 0 | AR21: =IF(INDEX(Control!$Q$3:$S$62,MATCH($Z21,Control!$Q$3:$Q$62,0),MATCH(AR$9,Control!$Q$3:$S$3,0))=1,INDEX(Control!$AK$3:$AO$69,MATCH(WTI!Z21,Control!$AK$3:$AK$29,0),MATCH(WTI!Y21,Control!$AK$3:$AO$3,0))/AB21*1000,0) -> 0 | AS21: =52000/AB21 -> 0.074285714 | AU21: =SUM(AI21:AT21) -> 0.074285714 | AV21: =+R21+AE21+AU21 -> 11.213561 | AW21: =IF((MONTH(A21)=MONTH(BH21)),0,IF(((MONTH(BH21))-MONTH(A21))+12*YEAR(BG21)-YEAR(A21)>1,SUMIFS($BD$4:$BH$4,$BD$3:$BH$3,"<="&EOMONTH(BG21,-1),$BD$3:$BH$3,">="&EOMONTH(A21,0)),VLOOKUP("Spreads",$BC$3:$BH$4,MATCH(EOMONTH(A21,0),$BC$3:$BH$3,0)))) -> 0 | AZ21: =$Y$3+AV21+AW21+AX21 -> 7.6135607 | BC21: =+INDEX('[1]Transit Time'!$A:$DZ,MATCH(V21,'[1]Transit Time'!$A:$A,0),MATCH(Z21,'[1]Transit Time'!$A$1:$DZ$1,0)) -> 8 | BD21: =E21+BC21 -> 46343 | BE21: =BD21+2 -> 46345 | BF21: =BF22 -> ICE Brent | BG21: =EOMONTH(BE21,0) -> 46356 | BH21: =BG21 -> 46356 | BI21: =AE21*AB21 -> 7797492.5 | BK21: =AI21*AB21 -> 0 | BL21: =(AU21-AI21-AJ21)*AB21 -> 52000 | BM21: =AJ21*AB21 -> 0 | BP21: =(AV21-AJ21)*AB21 -> 7849492.5 | BQ21: =BP21-BM21 -> 7849492.5
A22: =+$A$10 -> 46334 | B22: =IF(ISBLANK(A22),"",A22+2) -> 46336 | D22: =IF(AL22=0,0,VLOOKUP(Y22,Control!$G$41:$J$44,4,FALSE)) -> 0 | E22: =AVERAGE(A22:B22)+D22 -> 46335 | T22: 12.01 | U22: =INDEX(Control!$E$17:$J$21,MATCH(Y22,Control!$E$17:$E$21,0),MATCH(V22,Control!$E$17:$J$17,0)) -> 0.5 | V22: Corpus Christi | W22: =INDEX(Vessel_Minimum_MT,MATCH(Y22,Control!$E$11:$E$15,0),MATCH(V22,Control!$E$11:$J$11,0)) -> 145000 | X22: =AB22/Control!$D$84 -> 94601.816 | Y22: Suezmax | Z22: Saint John | AA22: =IF(Z22=V22,"",CONCATENATE(CONCATENATE(VLOOKUP(V22,Zones,2,FALSE),"/",VLOOKUP(Z22,Zones,2,FALSE)))) -> USGC/ECC | AB22: 735000 | AD22: 72 | AE22: =IF(AC22>1000,IF(AD22=0,AC22,AD22)/AB22,((W22*T22*(IF(AD22=0,AC22,AD22)/100))+IF(X22<W22,0,(X22-W22)*T22*IF(AD22=0,AC22,AD22)/100*U22))/AB22) -> 1.7059102 | AF22: 0 | AG22: =AG21 -> -10 | AH22: =AH21 -> 0 | AI22: =ABH367*VLOOKUP($Y22,Control!$F$75:$H$79,3,FALSE)/$AB22 -> 0 | AJ22: =IF(AG22<0,0,$AG22*Control!$D$77) -> 0 | AM22: =IF(I22="Corpus Christi",Control!$D$76,0) -> 0 | AN22: 0 | AO22: =Control!$D$78 -> 0 | AQ22: =IF(INDEX(Control!$Q$3:$S$62,MATCH($Z22,Control!$Q$3:$Q$62,0),MATCH(AQ$9,Control!$Q$3:$S$3,0))=1,Control!$D$81*Control!$E$81,0) -> 0 | AR22: =IF(INDEX(Control!$Q$3:$S$62,MATCH($Z22,Control!$Q$3:$Q$62,0),MATCH(AR$9,Control!$Q$3:$S$3,0))=1,Control!$D$82/$AB22,0) -> 0 | AS22: =52000/AB22 -> 0.070748299 | AT22: =IF(AND(L22="Chiriqui Grande",V22="Puerto Armuelles"),Control!$G$93,0) -> 0 | AU22: =SUM(AI22:AT22) -> 0.070748299 | AV22: =+R22+AE22+AU22 -> 1.7766585 | AW22: =IF((MONTH(A22)=MONTH(BH22)),0,IF(((MONTH(BH22))-MONTH(A22))+12*YEAR(BG22)-YEAR(A22)>1,SUMIFS($BD$4:$BH$4,$BD$3:$BH$3,"<="&EOMONTH(BG22,-1),$BD$3:$BH$3,">="&EOMONTH(A22,0)),VLOOKUP("Spreads",$BC$3:$BH$4,MATCH(EOMONTH(A22,0),$BC$3:$BH$3,0)))) -> 0 | AZ22: =$Y$3+AV22+AW22+AX22 -> -1.8233415 | BC22: =+INDEX('[1]Transit Time'!$A:$DZ,MATCH(V22,'[1]Transit Time'!$A:$A,0),MATCH(Z22,'[1]Transit Time'!$A$1:$DZ$1,0)) -> 8 | BD22: =IF(ISBLANK(A22),"",A22+$BC22+D22) -> 46342 | BE22: =BD22+2 -> 46344 | BF22: ICE Brent | BG22: =BH22 -> 46356 | BH22: =EOMONTH(BE22,0) -> 46356
A23: Load Window | D23: =D9 -> STS Time | E23: =E9 -> Depart | T23: Flat | U23: =INDEX(Control!$E$17:$J$21,MATCH(Y23,Control!$E$17:$E$21,0),MATCH(V23,Control!$E$17:$J$17,0)) -> #N/A | V23: Loadport | W23: =$W$9 -> Vessel MT | X23: Actual MT | Y23: Vessel | Z23: Destination | AA23: Route | AB23: Volume | AC23: Current WS Rate | AD23: WS Rate Call | AE23: Freight | AF23: Demm. | AG23: ATA tvm | AH23: =AH9 -> Ext. TVM | AI23: Demm. $ | AJ23: =AG23 -> ATA tvm | AK23: =AH23 -> Ext. TVM | AL23: =AL9 -> STS | AM23: Wharfage | AN23: Panama Canal | AO23: Insurance | AP23: Inspection | AQ23: Outturn Losses | AR23: ECA costs | AS23: Corpus Dock Fee | AT23: Pipeline Fee | AU23: Total Secondary Costs | AV23: All In Cost | AW23: Structure | AX23: =AX9 -> Basis | AZ23: DES Price | BC23: Transit Time | BD23: Arrival Window | BF23: =BF9 -> Basis | BG23: =BG9 -> Pricing Month | BH23: =BH9 -> Delivery Month | BP23: with | BQ23: without | BS23: BL+30 | BT23: NOR+xx
A24: =A22 -> 46334 | B24: =B9 -> 46336 | E24: =AVERAGE(A24:B24)+D24 -> 46335 | T24: =INDEX('[2]Flat Rates 2025'!$A:$DZ,MATCH(V24,'[2]Flat Rates 2025'!$A:$A,0),MATCH(Z24,'[2]Flat Rates 2025'!$A$1:$DZ$1,0)) -> 0 | U24: =INDEX(Control!$E$17:$J$21,MATCH(Y24,Control!$E$17:$E$21,0),MATCH(V24,Control!$E$17:$J$17,0)) -> 0 | V24: Corpus Christi | W24: =INDEX(Vessel_Minimum_MT,MATCH(Y24,Control!$E$11:$E$15,0),MATCH(V24,Control!$E$11:$J$11,0)) -> 70000 | X24: =AB24/Control!$D$84 -> 96532.466 | Y24: Aframax | Z24: Daesan | AA24: =IF(Z24=V24,"",CONCATENATE(CONCATENATE(VLOOKUP(V24,Zones,2,FALSE),"/",VLOOKUP(Z24,Zones,2,FALSE)))) -> USGC/KOREA | AB24: 750000 | AC24: 1001 | AD24: 6700000 | AE24: =IF(AC24>1000,IF(AD24=0,AC24,AD24)/AB24,((W24*T24*(IF(AD24=0,AC24,AD24)/100))+IF(X24<W24,0,(X24-W24)*T24*IF(AD24=0,AC24,AD24)/100*U24))/AB24) -> 8.9333333 | AF24: 5 | AG24: =IF(INDEX(Index,MATCH(Z24,TVM_PortList,0),MATCH("Type",Control!$Q$3:$U$3,0))="BL",INDEX(Index,MATCH(Z24,TVM_PortList,0),MATCH("Payment",Control!$Q$3:$U$3,0))-INDEX(Index,MATCH(V24,TVM_PortList,0),MATCH("Payment",Control!$Q$3:$U$3,0)),BC24+INDEX(Index,MATCH(Z24,TVM_PortList,0),MATCH("Payment",Control!$Q$3:$U$3,0))-INDEX(Index,MATCH(V24,TVM_PortList,0),MATCH("Payment",Control!$Q$3:$U$3,0))) -> 19 | AI24: =AF24*VLOOKUP($Y24,Control!$F$75:$H$87,3,FALSE)/$AB24 -> 0.53333333 | AJ24: =$AG24*Control!$D$77 -> 0.24768712 | AL24: =IF(((AB24-VLOOKUP(Y24,Control!$J$76:$K$80,2,FALSE))/Control!$D$85)<=0,0,ROUNDUP(((AB24-VLOOKUP(Y24,Control!$J$76:$K$80,2,FALSE))/Control!$D$85),0)*Control!$H$90/AB24) -> 0 | AM24: =IF(I24="Corpus Christi",Control!$D$76,0) -> 0 | AN24: 0 | AO24: =Control!$D$78 -> 0 | AP24: =Control!$D$79 -> 0.0673 | AQ24: =IF(INDEX(Control!$Q$3:$S$62,MATCH($Z24,Control!$Q$3:$Q$62,0),MATCH(AQ$9,Control!$Q$3:$S$3,0))=1,Control!$D$81*Control!$E$81,0) -> 0.2 | AS24: =IF(AND(Y24="VLCC",Control!$K$79=1200000),Control!$D$83/AB24,0) -> 0 | AU24: =SUM(AI24:AT24) -> 1.0483205 | AV24: =+R24+AE24+AU24 -> 9.9816538 | AW24: =IF((MONTH(A24)=MONTH(BH24)),0,IF(((MONTH(BH24))-MONTH(A24))+12*YEAR(BG24)-YEAR(A24)>1,SUMIFS($BD$4:$BG$4,$BD$3:$BG$3,"<="&EOMONTH(BG24,-1),$BD$3:$BG$3,">="&EOMONTH(A24,0)),VLOOKUP("Spreads",$BC$3:$BG$4,MATCH(EOMONTH(A24,0),$BC$3:$BG$3,0)))) -> 0 | AX24: =+IF($BC$3=1,HLOOKUP(EOMONTH(BG24,0),$BD$3:$BH$6,4,FALSE),IF($BC$3=2,-HLOOKUP(EOMONTH(BG24,0),$BC$3:$BH$6,3,FALSE),0)) -> -1.7 | AZ24: =$Y$3+AV24+AW24+AX24 -> 4.6816538 | BC24: 39 | BD24: =IF(ISBLANK(A24),"",A24+$BC24+D24) -> 46373 | BE24: =BD24+2 -> 46375 | BF24: =HLOOKUP($BC$3,$AV$4:$AX$5,2,FALSE) -> Dubai | BG24: =IF($BC$8=0,IF(BF24="ICE Brent",EOMONTH(BE24,2),EOMONTH(BE24,0)),IF(BF24="ICE Brent",EOMONTH(BE24,1),EOMONTH(BE24,-1))) -> 46356 | BH24: =IF($BC$8=1,EOMONTH(BE24,-1),EOMONTH(BE24,0)) -> 46356
